Workbook

Sheet original data 
D1: HEFT | F1: HGA | I1: LWSGA | L1: APRE_EDA | O1: HPSO | R1: R2GA | U1: HEDA
D2: ms | E2: rt | F2: ms | G2: rt | H2: itr | I2: ms | J2: rt | K2: itr | L2: ms | M2: rt | N2: itr | O2: ms | P2: rt | Q2: itr | R2: ms | S2: rt | T2: itr | U2: ms | V2: rt | W2: itr
A3: Montage | B3: 25 | C3: 1 | D3: 28.7148 | E3: 0.00092 | F3: 28.7148 | G3: 5.27815 | H3: 280 | I3: 28.72703 | J3: 5.27456 | K3: 742 | L3: 28.7148 | M3: 5.274 | N3: 821 | O3: 28.65213 | P3: 5.2755 | Q3: 4532 | R3: 28.64701 | S3: 5.27541 | T3: 465 | U3: 28.5041 | V3: 5.28217 | W3: 233
A4: Montage | B4: 25 | C4: 1 | D4: 28.7148 | E4: 0.00067 | F4: 28.7148 | G4: 5.28482 | H4: 353 | I4: 28.87217 | J4: 5.27473 | K4: 735 | L4: 28.7148 | M4: 5.274 | N4: 804 | O4: 28.70029 | P4: 5.276 | Q4: 3390 | R4: 28.59203 | S4: 5.27603 | T4: 456 | U4: 28.54624 | V4: 5.27589 | W4: 249
A5: Montage | B5: 25 | C5: 1 | D5: 28.7148 | E5: 0.00058 | F5: 28.7148 | G5: 5.27442 | H5: 207 | I5: 30.11037 | J5: 5.27508 | K5: 614 | L5: 28.7148 | M5: 5.274 | N5: 774 | O5: 28.77029 | P5: 5.27775 | Q5: 3520 | R5: 28.64701 | S5: 5.28499 | T5: 438 | U5: 28.5041 | V5: 5.29938 | W5: 188
A6: Montage | B6: 25 | C6: 1 | D6: 28.7148 | E6: 0.00065 | F6: 28.7148 | G6: 5.28013 | H6: 350 | I6: 29.87502 | J6: 5.28063 | K6: 718 | L6: 28.7148 | M6: 5.274 | N6: 804 | O6: 28.74417 | P6: 5.27498 | Q6: 4608 | R6: 28.54624 | S6: 5.28065 | T6: 439 | U6: 28.54624 | V6: 5.29772 | W6: 190
A7: Montage | B7: 25 | C7: 1 | D7: 28.7148 | E7: 0.00057 | F7: 28.7148 | G7: 5.29226 | H7: 205 | I7: 28.8863 | J7: 5.2806 | K7: 474 | L7: 28.7148 | M7: 5.274 | N7: 770 | O7: 28.74417 | P7: 5.27622 | Q7: 3054 | R7: 28.58701 | S7: 5.27911 | T7: 446 | U7: 28.54624 | V7: 5.27939 | W7: 224
A8: Montage | B8: 25 | C8: 1 | D8: 28.7148 | E8: 0.00069 | F8: 28.7148 | G8: 5.28088 | H8: 334 | I8: 30.80614 | J8: 5.27628 | K8: 670 | L8: 28.7148 | M8: 5.274 | N8: 813 | O8: 28.74417 | P8: 5.27623 | Q8: 4507 | R8: 28.64701 | S8: 5.28464 | T8: 464 | U8: 28.5041 | V8: 5.29082 | W8: 193
A9: Montage | B9: 25 | C9: 1 | D9: 28.7148 | E9: 0.00065 | F9: 28.7148 | G9: 5.27653 | H9: 355 | I9: 30.82263 | J9: 5.27855 | K9: 722 | L9: 28.7148 | M9: 5.274 | N9: 822 | O9: 28.70029 | P9: 5.27543 | Q9: 4645 | R9: 28.64701 | S9: 5.28203 | T9: 470 | U9: 28.54624 | V9: 5.27436 | W9: 224
A10: Montage | B10: 25 | C10: 1 | D10: 28.7148 | E10: 0.00057 | F10: 28.7148 | G10: 5.28565 | H10: 357 | I10: 28.63568 | J10: 5.27775 | K10: 737 | L10: 28.7148 | M10: 5.274 | N10: 826 | O10: 28.70029 | P10: 5.27582 | Q10: 4595 | R10: 28.64701 | S10: 5.27845 | T10: 472 | U10: 28.54624 | V10: 5.30055 | W10: 195
A11: Montage | B11: 25 | C11: 1 | D11: 28.7148 | E11: 0.00058 | F11: 28.7148 | G11: 5.27433 | H11: 357 | I11: 28.71203 | J11: 5.28124 | K11: 745 | L11: 28.7148 | M11: 5.274 | N11: 826 | O11: 28.74417 | P11: 5.27445 | Q11: 4582 | R11: 28.64701 | S11: 5.27624 | T11: 466 | U11: 28.54624 | V11: 5.27708 | W11: 219
A12: Montage | B12: 25 | C12: 1 | D12: 28.7148 | E12: 0.00064 | F12: 28.7148 | G12: 5.28556 | H12: 361 | I12: 28.90608 | J12: 5.27447 | K12: 690 | L12: 28.7148 | M12: 5.274 | N12: 807 | O12: 28.74417 | P12: 5.27703 | Q12: 2385 | R12: 28.60624 | S12: 5.28053 | T12: 471 | U12: 28.54624 | V12: 5.28508 | W12: 199
A13: Montage | B13: 25 | C13: 1 | D13: 28.7148 | E13: 0.00059 | F13: 28.7148 | G13: 5.27834 | H13: 359 | I13: 28.65703 | J13: 5.27511 | K13: 737 | L13: 28.7148 | M13: 5.274 | N13: 825 | O13: 28.75296 | P13: 5.27408 | Q13: 4669 | R13: 28.54624 | S13: 5.27766 | T13: 477 | U13: 28.54624 | V13: 5.28162 | W13: 201
A14: Montage | B14: 25 | C14: 1 | D14: 28.7148 | E14: 0.00063 | F14: 28.7148 | G14: 5.28769 | H14: 359 | I14: 29.00328 | J14: 5.27783 | K14: 738 | L14: 28.7148 | M14: 5.274 | N14: 828 | O14: 28.74417 | P14: 5.27404 | Q14: 4719 | R14: 28.59203 | S14: 5.27813 | T14: 483 | U14: 28.5041 | V14: 5.28008 | W14: 173
... A1802: fft | B1802: 224 | C1802: 1 | D1802: 72.35609 | E1802: 0.00363 | F1802: 72.35609 | G1802: 255.48402 | H1802: 2231 | I1802: 72.90048 | J1802: 255.42563 | K1802: 10532 | L1802: 71.94765 | M1802: 255.423 | N1802: 2433 | O1802: 72.63722 | P1802: 255.42839 | Q1802: 19781 | R1802: 72.26319 | S1802: 255.47585 | T1802: 2447 | U1802: 71.93967 | V1802: 256.24175 | W1802: 216

Sheet HEFT (Table 5) 
D1: HEFT | L1: HEFT
D2: ms | E2: rt | L2: ms | M2: aver. rt
A3: Montage | B3: 25 | C3: 1 | D3: ='original data '!D3 -> 28.7148 | E3: ='original data '!E3 -> 0.00092 | H3: Montage | I3: 25 | J3: 1 | L3: =AVERAGE(D3:D102) -> 28.7148 | M3: =AVERAGE(E3:E102) -> 0.0006254
A4: Montage | B4: 25 | C4: 1 | D4: ='original data '!D4 -> 28.7148 | E4: ='original data '!E4 -> 0.00067 | H4: Montage | I4: 50 | J4: 1 | L4: =AVERAGE(D103:D202) -> 58.25543 | M4: =AVERAGE(E103:E202) -> 0.0010195
A5: Montage | B5: 25 | C5: 1 | D5: ='original data '!D5 -> 28.7148 | E5: ='original data '!E5 -> 0.00058 | H5: Montage | I5: 100 | J5: 1 | L5: =AVERAGE(D203:D302) -> 105.21427 | M5: =AVERAGE(E203:E302) -> 0.0020251
A6: Montage | B6: 25 | C6: 1 | D6: ='original data '!D6 -> 28.7148 | E6: ='original data '!E6 -> 0.00065 | H6: CyberShake | I6: 30 | J6: 1 | L6: =AVERAGE(D303:D402) -> 171.00667 | M6: =AVERAGE(E303:E402) -> 0.0005637
A7: Montage | B7: 25 | C7: 1 | D7: ='original data '!D7 -> 28.7148 | E7: ='original data '!E7 -> 0.00057 | H7: CyberShake | I7: 50 | J7: 1 | L7: =AVERAGE(D403:D502) -> 196.14333 | M7: =AVERAGE(E403:E502) -> 0.0009093
A8: Montage | B8: 25 | C8: 1 | D8: ='original data '!D8 -> 28.7148 | E8: ='original data '!E8 -> 0.00069 | H8: CyberShake | I8: 100 | J8: 1 | L8: =AVERAGE(D503:D602) -> 250.31558 | M8: =AVERAGE(E503:E602) -> 0.0018852
A9: Montage | B9: 25 | C9: 1 | D9: ='original data '!D9 -> 28.7148 | E9: ='original data '!E9 -> 0.00065 | H9: Epigenomics | I9: 24 | J9: 1 | L9: =AVERAGE(D603:D702) -> 2540.1985 | M9: =AVERAGE(E603:E702) -> 0.0003906
A10: Montage | B10: 25 | C10: 1 | D10: ='original data '!D10 -> 28.7148 | E10: ='original data '!E10 -> 0.00057 | H10: Epigenomics | I10: 47 | J10: 1 | L10: =AVERAGE(D703:D802) -> 4346.2297 | M10: =AVERAGE(E703:E802) -> 0.0006697
A11: Montage | B11: 25 | C11: 1 | D11: ='original data '!D11 -> 28.7148 | E11: ='original data '!E11 -> 0.00058 | H11: Epigenomics | I11: 100 | J11: 1 | L11: =AVERAGE(D803:D902) -> 35669.695 | M11: =AVERAGE(E803:E902) -> 0.0013721
A12: Montage | B12: 25 | C12: 1 | D12: ='original data '!D12 -> 28.7148 | E12: ='original data '!E12 -> 0.00064 | H12: Ligo | I12: 30 | J12: 1 | L12: =AVERAGE(D903:D1002) -> 699.02291 | M12: =AVERAGE(E903:E1002) -> 0.0005664
A13: Montage | B13: 25 | C13: 1 | D13: ='original data '!D13 -> 28.7148 | E13: ='original data '!E13 -> 0.00059 | H13: Ligo | I13: 50 | J13: 1 | L13: =AVERAGE(D1003:D1102) -> 1027.0157 | M13: =AVERAGE(E1003:E1102) -> 0.0009458
A14: Montage | B14: 25 | C14: 1 | D14: ='original data '!D14 -> 28.7148 | E14: ='original data '!E14 -> 0.00063 | H14: Ligo | I14: 100 | J14: 1 | L14: =AVERAGE(D1103:D1202) -> 1774.48 | M14: =AVERAGE(E1103:E1202) -> 0.0017524
A15: Montage | B15: 25 | C15: 1 | D15: ='original data '!D15 -> 28.7148 | E15: ='original data '!E15 -> 0.00069 | H15: gaussian | I15: 9 | J15: 1 | L15: =AVERAGE(D1203:D1302) -> 8.54243 | M15: =AVERAGE(E1203:E1302) -> 0.000264
A16: Montage | B16: 25 | C16: 1 | D16: ='original data '!D16 -> 28.7148 | E16: ='original data '!E16 -> 0.00063 | H16: gaussian | I16: 209 | J16: 1 | L16: =AVERAGE(D1303:D1402) -> 80.12632 | M16: =AVERAGE(E1303:E1402) -> 0.0036063
A17: Montage | B17: 25 | C17: 1 | D17: ='original data '!D17 -> 28.7148 | E17: ='original data '!E17 -> 0.00058 | H17: gaussian | I17: 324 | J17: 1 | L17: =AVERAGE(D1403:D1502) -> 123.43652 | M17: =AVERAGE(E1403:E1502) -> 0.0058087
A18: Montage | B18: 25 | C18: 1 | D18: ='original data '!D18 -> 28.7148 | E18: ='original data '!E18 -> 0.00058 | H18: fft | I18: 40 | J18: 1 | L18: =AVERAGE(D1503:D1602) -> 17.83966 | M18: =AVERAGE(E1503:E1602) -> 0.0007726
A19: Montage | B19: 25 | C19: 1 | D19: ='original data '!D19 -> 28.7148 | E19: ='original data '!E19 -> 0.0006 | H19: fft | I19: 96 | J19: 1 | L19: =AVERAGE(D1603:D1702) -> 35.64892 | M19: =AVERAGE(E1603:E1702) -> 0.001604
A20: Montage | B20: 25 | C20: 1 | D20: ='original data '!D20 -> 28.7148 | E20: ='original data '!E20 -> 0.00058 | H20: fft | I20: 224 | J20: 1 | L20: =AVERAGE(D1703:D1802) -> 72.35609 | M20: =AVERAGE(E1703:E1802) -> 0.003717
A21: Montage | B21: 25 | C21: 1 | D21: ='original data '!D21 -> 28.7148 | E21: ='original data '!E21 -> 0.00058
A22: Montage | B22: 25 | C22: 1 | D22: ='original data '!D22 -> 28.7148 | E22: ='original data '!E22 -> 0.00068
A23: Montage | B23: 25 | C23: 1 | D23: ='original data '!D23 -> 28.7148 | E23: ='original data '!E23 -> 0.00058
A24: Montage | B24: 25 | C24: 1 | D24: ='original data '!D24 -> 28.7148 | E24: ='original data '!E24 -> 0.0006
A25: Montage | B25: 25 | C25: 1 | D25: ='original data '!D25 -> 28.7148 | E25: ='original data '!E25 -> 0.00066
A26: Montage | B26: 25 | C26: 1 | D26: ='original data '!D26 -> 28.7148 | E26: ='original data '!E26 -> 0.00072
A27: Montage | B27: 25 | C27: 1 | D27: ='original data '!D27 -> 28.7148 | E27: ='original data '!E27 -> 0.00059
A28: Montage | B28: 25 | C28: 1 | D28: ='original data '!D28 -> 28.7148 | E28: ='original data '!E28 -> 0.00059
A29: Montage | B29: 25 | C29: 1 | D29: ='original data '!D29 -> 28.7148 | E29: ='original data '!E29 -> 0.00055
A30: Montage | B30: 25 | C30: 1 | D30: ='original data '!D30 -> 28.7148 | E30: ='original data '!E30 -> 0.00051
A31: Montage | B31: 25 | C31: 1 | D31: ='original data '!D31 -> 28.7148 | E31: ='original data '!E31 -> 0.00061
A32: Montage | B32: 25 | C32: 1 | D32: ='original data '!D32 -> 28.7148 | E32: ='original data '!E32 -> 0.00052
... A1802: fft | B1802: 224 | C1802: 1 | D1802: ='original data '!D1802 -> 72.35609 | E1802: ='original data '!E1802 -> 0.00363

Sheet Cmp ms-aver (Table 6) 
D1: ms | E1: ms | F1: ms | G1: ms | H1: ms | I1: ms | J1: ms | L1: ms-aver | M1: ms-aver | N1: ms-aver | O1: ms-aver | P1: ms-aver | Q1: ms-aver | R1: ms-aver | T1: ms-max | U1: ms-max | V1: ms-max | W1: ms-max | X1: ms-max | Y1: ms-max | AA1: ms-min | AB1: ms-min | AC1: ms-min | AD1: ms-min | AE1: ms-min | AF1: ms-min | AH1: AMI | AI1: AMI | AJ1: AMI | AK1: AMI | AL1: AMI | AM1: AMI | AN1: AMI | AP1: nms-aver | AQ1: nms-aver | AR1: nms-aver | AS1: nms-aver | AT1: nms-aver | AU1: nms-aver | AV1: nms-aver
D2: HEFT | E2: HGA | F2: LWSGA | G2: APRE_EDA | H2: HPSO | I2: R2GA | J2: HEDA | L2: HEFT | M2: HGA | N2: LWSGA | O2: APRE_EDA | P2: HPSO | Q2: R2GA | R2: HEDA | T2: =E2 -> HGA | U2: =F2 -> LWSGA | V2: =G2 -> APRE_EDA | W2: =H2 -> HPSO | X2: R2GA | Y2: =J2 -> HEDA | AA2: =E2 -> HGA | AB2: =F2 -> LWSGA | AC2: =G2 -> APRE_EDA | AD2: =H2 -> HPSO | AE2: R2GA | AF2: =J2 -> HEDA | AH2: =L2 -> HEFT | AI2: =M2 -> HGA | AJ2: =N2 -> LWSGA | AK2: =O2 -> APRE_EDA | AL2: =P2 -> HPSO | AM2: R2GA | AN2: =R2 -> HEDA | AP2: =L2 -> HEFT | AQ2: =M2 -> HGA | AR2: =N2 -> LWSGA | AS2: =O2 -> APRE_EDA | AT2: =P2 -> HPSO | AU2: R2GA | AV2: =R2 -> HEDA
A3: Montage | B3: 25 | C3: 1 | D3: ='original data '!D3 -> 28.7148 | E3: ='original data '!F3 -> 28.7148 | F3: ='original data '!I3 -> 28.72703 | G3: ='original data '!L3 -> 28.7148 | H3: ='original data '!O3 -> 28.65213 | I3: ='original data '!R3 -> 28.64701 | J3: ='original data '!U3 -> 28.5041 | K3: M,S | L3: =AVERAGE(D3:D102) -> 28.7148 | M3: =AVERAGE(E3:E102) -> 28.702778 | N3: =AVERAGE(F3:F102) -> 29.518198 | O3: =AVERAGE(G3:G102) -> 28.7148 | P3: =AVERAGE(H3:H102) -> 28.765418 | Q3: =AVERAGE(I3:I102) -> 28.623141 | R3: =AVERAGE(J3:J102) -> 28.531885 | S3: M,S | T3: =MAX(E3:E102) -> 28.7148 | U3: =MAX(F3:F102) -> 31.98679 | V3: =MAX(G3:G102) -> 28.7148 | W3: =MAX(H3:H102) -> 29.98095 | X3: =MAX(I3:I102) -> 28.64701 | Y3: =MAX(J3:J102) -> 28.58701 | Z3: M,S | AA3: =MIN(E3:E102) -> 28.64701 | AB3: =MIN(F3:F102) -> 28.56187 | AC3: =MIN(G3:G102) -> 28.7148 | AD3: =MIN(H3:H102) -> 28.65213 | AE3: =MIN(I3:I102) -> 28.54624 | AF3: =MIN(J3:J102) -> 28.5041 | AG3: M,S | AH3: =(L3-$R3)/$L3 -> 0.00637006 | AI3: =(M3-$R3)/M3 -> 0.0059538802 | AJ3: =(N3-$R3)/N3 -> 0.033413717 | AK3: =(O3-$R3)/O3 -> 0.00637006 | AL3: =(P3-$R3)/P3 -> 0.008118547 | AM3: =(Q3-$R3)/Q3 -> 0.0031882035 | AN3: =(R3-$R3)/R3 -> 0 | AO3: M,S | AP3: =L3/$L3 -> 1 | AQ3: =M3/$L3 -> 0.99958133 | AR3: =N3/$L3 -> 1.0279785 | AS3: =O3/$L3 -> 1 | AT3: =P3/$L3 -> 1.0017628 | AU3: =Q3/$L3 -> 0.99680797 | AV3: =R3/$L3 -> 0.99362994
A4: Montage | B4: 25 | C4: 1 | D4: ='original data '!D4 -> 28.7148 | E4: ='original data '!F4 -> 28.7148 | F4: ='original data '!I4 -> 28.87217 | G4: ='original data '!L4 -> 28.7148 | H4: ='original data '!O4 -> 28.70029 | I4: ='original data '!R4 -> 28.59203 | J4: ='original data '!U4 -> 28.54624 | K4: M,M | L4: =AVERAGE(D103:D202) -> 58.25543 | M4: =AVERAGE(E103:E202) -> 56.581854 | N4: =AVERAGE(F103:F202) -> 55.571276 | O4: =AVERAGE(G103:G202) -> 58.25543 | P4: =AVERAGE(H103:H202) -> 56.27979 | Q4: =AVERAGE(I103:I202) -> 52.995855 | R4: =AVERAGE(J103:J202) -> 53.00429 | S4: M,M | T4: =MAX(E103:E202) -> 56.75636 | U4: =MAX(F103:F202) -> 58.2017 | V4: =MAX(G103:G202) -> 58.25543 | W4: =MAX(H103:H202) -> 57.60586 | X4: =MAX(I103:I202) -> 53.1682 | Y4: =MAX(J103:J202) -> 53.10749 | Z4: M,M | AA4: =MIN(E103:E202) -> 54.62635 | AB4: =MIN(F103:F202) -> 53.5282 | AC4: =MIN(G103:G202) -> 58.25543 | AD4: =MIN(H103:H202) -> 53.7282 | AE4: =MIN(I103:I202) -> 52.92749 | AF4: =MIN(J103:J202) -> 52.92749 | AG4: M,M | AH4: =(L4-$R4)/$L4 -> 0.090139917 | AI4: =(M4-$R4)/M4 -> 0.063228102 | AJ4: =(N4-$R4)/N4 -> 0.046192675 | AK4: =(O4-$R4)/O4 -> 0.090139917 | AL4: =(P4-$R4)/P4 -> 0.058200288 | AM4: =(Q4-$R4)/Q4 -> -0.00015917849 | AN4: =(R4-$R4)/$R4 -> 0 | AO4: M,M | AP4: =L4/$L4 -> 1 | AQ4: =M4/$L4 -> 0.97127175 | AR4: =N4/$L4 -> 0.9539244 | AS4: =O4/$L4 -> 1 | AT4: =P4/$L4 -> 0.9660866 | AU4: =Q4/$L4 -> 0.90971528 | AV4: =R4/$L4 -> 0.90986008
A5: Montage | B5: 25 | C5: 1 | D5: ='original data '!D5 -> 28.7148 | E5: ='original data '!F5 -> 28.7148 | F5: ='original data '!I5 -> 30.11037 | G5: ='original data '!L5 -> 28.7148 | H5: ='original data '!O5 -> 28.77029 | I5: ='original data '!R5 -> 28.64701 | J5: ='original data '!U5 -> 28.5041 | K5: M,L | L5: =AVERAGE(D203:D302) -> 105.21427 | M5: =AVERAGE(E203:E302) -> 104.63795 | N5: =AVERAGE(F203:F302) -> 105.37162 | O5: =AVERAGE(G203:G302) -> 105.21427 | P5: =AVERAGE(H203:H302) -> 104.29605 | Q5: =AVERAGE(I203:I302) -> 103.73932 | R5: =AVERAGE(J203:J302) -> 103.2202 | S5: M,L | T5: =MAX(E203:E302) -> 105.12503 | U5: =MAX(F203:F302) -> 108.56572 | V5: =MAX(G203:G302) -> 105.21427 | W5: =MAX(H203:H302) -> 104.66682 | X5: =MAX(I203:I302) -> 103.93829 | Y5: =MAX(J203:J302) -> 103.61496 | Z5: M,L | AA5: =MIN(E203:E302) -> 104.16663 | AB5: =MIN(F203:F302) -> 103.43627 | AC5: =MIN(G203:G302) -> 105.21427 | AD5: =MIN(H203:H302) -> 103.85553 | AE5: =MIN(I203:I302) -> 103.36586 | AF5: =MIN(J203:J302) -> 102.77198 | AG5: M,L | AH5: =(L5-$R5)/$L5 -> 0.018952485 | AI5: =(M5-$R5)/M5 -> 0.013549081 | AJ5: =(N5-$R5)/N5 -> 0.020417479 | AK5: =(O5-$R5)/O5 -> 0.018952485 | AL5: =(P5-$R5)/P5 -> 0.010315382 | AM5: =(Q5-$R5)/Q5 -> 0.0050040594 | AN5: =(R5-$R5)/$R5 -> 0 | AO5: M,L | AP5: =L5/$L5 -> 1 | AQ5: =M5/$L5 -> 0.99452238 | AR5: =N5/$L5 -> 1.0014955 | AS5: =O5/$L5 -> 1 | AT5: =P5/$L5 -> 0.99127287 | AU5: =Q5/$L5 -> 0.98598142 | AV5: =R5/$L5 -> 0.98104751
A6: Montage | B6: 25 | C6: 1 | D6: ='original data '!D6 -> 28.7148 | E6: ='original data '!F6 -> 28.7148 | F6: ='original data '!I6 -> 29.87502 | G6: ='original data '!L6 -> 28.7148 | H6: ='original data '!O6 -> 28.74417 | I6: ='original data '!R6 -> 28.54624 | J6: ='original data '!U6 -> 28.54624 | K6: C,S | L6: =AVERAGE(D303:D402) -> 171.00667 | M6: =AVERAGE(E303:E402) -> 156.12667 | N6: =AVERAGE(F303:F402) -> 159.12973 | O6: =AVERAGE(G303:G402) -> 156.13162 | P6: =AVERAGE(H303:H402) -> 156.12933 | Q6: =AVERAGE(I303:I402) -> 156.13492 | R6: =AVERAGE(J303:J402) -> 156.12667 | S6: C,S | T6: =MAX(E303:E402) -> 156.12667 | U6: =MAX(F303:F402) -> 234.0814 | V6: =MAX(G303:G402) -> 156.55706 | W6: =MAX(H303:H402) -> 156.14004 | X6: =MAX(I303:I402) -> 156.35333 | Y6: =MAX(J303:J402) -> 156.12667 | Z6: C,S | AA6: =MIN(E303:E402) -> 156.12667 | AB6: =MIN(F303:F402) -> 156.12667 | AC6: =MIN(G303:G402) -> 156.12697 | AD6: =MIN(H303:H402) -> 156.12667 | AE6: =MIN(I303:I402) -> 156.12667 | AF6: =MIN(J303:J402) -> 156.12667 | AG6: C,S | AH6: =(L6-$R6)/$L6 -> 0.08701415 | AI6: =(M6-$R6)/M6 -> 0 | AJ6: =(N6-$R6)/N6 -> 0.018871794 | AK6: =(O6-$R6)/O6 -> 3.1702099e-05 | AL6: =(P6-$R6)/P6 -> 1.7059575e-05 | AM6: =(Q6-$R6)/Q6 -> 5.2822265e-05 | AN6: =(R6-$R6)/$R6 -> 0 | AO6: C,S | AP6: =L6/$L6 -> 1 | AQ6: =M6/$L6 -> 0.91298585 | AR6: =N6/$L6 -> 0.93054694 | AS6: =O6/$L6 -> 0.91301479 | AT6: =P6/$L6 -> 0.91300143 | AU6: =Q6/$L6 -> 0.91303408 | AV6: =R6/$L6 -> 0.91298585
A7: Montage | B7: 25 | C7: 1 | D7: ='original data '!D7 -> 28.7148 | E7: ='original data '!F7 -> 28.7148 | F7: ='original data '!I7 -> 28.8863 | G7: ='original data '!L7 -> 28.7148 | H7: ='original data '!O7 -> 28.74417 | I7: ='original data '!R7 -> 28.58701 | J7: ='original data '!U7 -> 28.54624 | K7: C,M | L7: =AVERAGE(D403:D502) -> 196.14333 | M7: =AVERAGE(E403:E502) -> 186.21287 | N7: =AVERAGE(F403:F502) -> 195.53407 | O7: =AVERAGE(G403:G502) -> 196.0993 | P7: =AVERAGE(H403:H502) -> 187.78164 | Q7: =AVERAGE(I403:I502) -> 185.18744 | R7: =AVERAGE(J403:J502) -> 180.21677 | S7: C,M | T7: =MAX(E403:E502) -> 188.82333 | U7: =MAX(F403:F502) -> 222.77535 | V7: =MAX(G403:G502) -> 196.14333 | W7: =MAX(H403:H502) -> 201.75271 | X7: =MAX(I403:I502) -> 189.05667 | Y7: =MAX(J403:J502) -> 181.89 | Z7: C,M | AA7: =MIN(E403:E502) -> 181.89 | AB7: =MIN(F403:F502) -> 182.50103 | AC7: =MIN(G403:G502) -> 195.46095 | AD7: =MIN(H403:H502) -> 182.34583 | AE7: =MIN(I403:I502) -> 179.93769 | AF7: =MIN(J403:J502) -> 179.67333 | AG7: C,M | AH7: =(L7-$R7)/$L7 -> 0.081198601 | AI7: =(M7-$R7)/M7 -> 0.032200251 | AJ7: =(N7-$R7)/N7 -> 0.078335746 | AK7: =(O7-$R7)/O7 -> 0.080992288 | AL7: =(P7-$R7)/P7 -> 0.040285488 | AM7: =(Q7-$R7)/Q7 -> 0.026841325 | AN7: =(R7-$R7)/$R7 -> 0 | AO7: C,M | AP7: =L7/$L7 -> 1 | AQ7: =M7/$L7 -> 0.9493714 | AR7: =N7/$L7 -> 0.99689382 | AS7: =O7/$L7 -> 0.9997755 | AT7: =P7/$L7 -> 0.9573695 | AU7: =Q7/$L7 -> 0.94414346 | AV7: =R7/$L7 -> 0.9188014
A8: Montage | B8: 25 | C8: 1 | D8: ='original data '!D8 -> 28.7148 | E8: ='original data '!F8 -> 28.7148 | F8: ='original data '!I8 -> 30.80614 | G8: ='original data '!L8 -> 28.7148 | H8: ='original data '!O8 -> 28.74417 | I8: ='original data '!R8 -> 28.64701 | J8: ='original data '!U8 -> 28.5041 | K8: C,L | L8: =AVERAGE(D503:D602) -> 250.31558 | M8: =AVERAGE(E503:E602) -> 246.10143 | N8: =AVERAGE(F503:F602) -> 256.68888 | O8: =AVERAGE(G503:G602) -> 250.31558 | P8: =AVERAGE(H503:H602) -> 252.24953 | Q8: =AVERAGE(I503:I602) -> 247.43182 | R8: =AVERAGE(J503:J602) -> 239.27988 | S8: C,L | T8: =MAX(E503:E602) -> 248.88889 | U8: =MAX(F503:F602) -> 284.60994 | V8: =MAX(G503:G602) -> 250.31558 | W8: =MAX(H503:H602) -> 257.43457 | X8: =MAX(I503:I602) -> 250.31558 | Y8: =MAX(J503:J602) -> 240.81333 | Z8: C,L | AA8: =MIN(E503:E602) -> 244.25558 | AB8: =MIN(F503:F602) -> 242.8148 | AC8: =MIN(G503:G602) -> 250.31558 | AD8: =MIN(H503:H602) -> 246.04792 | AE8: =MIN(I503:I602) -> 245.27333 | AF8: =MIN(J503:J602) -> 238.99004 | AG8: C,L | AH8: =(L8-$R8)/$L8 -> 0.044087144 | AI8: =(M8-$R8)/M8 -> 0.027718455 | AJ8: =(N8-$R8)/N8 -> 0.067821416 | AK8: =(O8-$R8)/O8 -> 0.044087144 | AL8: =(P8-$R8)/P8 -> 0.051415965 | AM8: =(Q8-$R8)/Q8 -> 0.032946219 | AN8: =(R8-$R8)/$R8 -> 0 | AO8: C,L | AP8: =L8/$L8 -> 1 | AQ8: =M8/$L8 -> 0.98316466 | AR8: =N8/$L8 -> 1.0254611 | AS8: =O8/$L8 -> 1 | AT8: =P8/$L8 -> 1.0077261 | AU8: =Q8/$L8 -> 0.98847952 | AV8: =R8/$L8 -> 0.95591286
A9: Montage | B9: 25 | C9: 1 | D9: ='original data '!D9 -> 28.7148 | E9: ='original data '!F9 -> 28.7148 | F9: ='original data '!I9 -> 30.82263 | G9: ='original data '!L9 -> 28.7148 | H9: ='original data '!O9 -> 28.70029 | I9: ='original data '!R9 -> 28.64701 | J9: ='original data '!U9 -> 28.54624 | K9: E,S | L9: =AVERAGE(D603:D702) -> 2540.1985 | M9: =AVERAGE(E603:E702) -> 2444.1437 | N9: =AVERAGE(F603:F702) -> 2378.473 | O9: =AVERAGE(G603:G702) -> 2325.0489 | P9: =AVERAGE(H603:H702) -> 2376.855 | Q9: =AVERAGE(I603:I702) -> 2321.691 | R9: =AVERAGE(J603:J702) -> 2320.9076 | S9: E,S | T9: =MAX(E603:E702) -> 2522.2832 | U9: =MAX(F603:F702) -> 2555.7879 | V9: =MAX(G603:G702) -> 2333.9507 | W9: =MAX(H603:H702) -> 2522.8167 | X9: =MAX(I603:I702) -> 2338.595 | Y9: =MAX(J603:J702) -> 2320.9075 | Z9: E,S | AA9: =MIN(E603:E702) -> 2320.9075 | AB9: =MIN(F603:F702) -> 2320.9075 | AC9: =MIN(G603:G702) -> 2324.4635 | AD9: =MIN(H603:H702) -> 2320.9075 | AE9: =MIN(I603:I702) -> 2320.9075 | AF9: =MIN(J603:J702) -> 2320.9075 | AG9: E,S | AH9: =(L9-$R9)/$L9 -> 0.086328273 | AI9: =(M9-$R9)/M9 -> 0.050420984 | AJ9: =(N9-$R9)/N9 -> 0.024202691 | AK9: =(O9-$R9)/O9 -> 0.0017811695 | AL9: =(P9-$R9)/P9 -> 0.02353845 | AM9: =(Q9-$R9)/Q9 -> 0.00033744555 | AN9: =(R9-$R9)/$R9 -> 0 | AO9: E,S | AP9: =L9/$L9 -> 1 | AQ9: =M9/$L9 -> 0.9621861 | AR9: =N9/$L9 -> 0.93633352 | AS9: =O9/$L9 -> 0.91530203 | AT9: =P9/$L9 -> 0.93569657 | AU9: =Q9/$L9 -> 0.91398015 | AV9: =R9/$L9 -> 0.91367173
A10: Montage | B10: 25 | C10: 1 | D10: ='original data '!D10 -> 28.7148 | E10: ='original data '!F10 -> 28.7148 | F10: ='original data '!I10 -> 28.63568 | G10: ='original data '!L10 -> 28.7148 | H10: ='original data '!O10 -> 28.70029 | I10: ='original data '!R10 -> 28.64701 | J10: ='original data '!U10 -> 28.54624 | K10: E,M | L10: =AVERAGE(D703:D802) -> 4346.2297 | M10: =AVERAGE(E703:E802) -> 4332.5091 | N10: =AVERAGE(F703:F802) -> 4334.0945 | O10: =AVERAGE(G703:G802) -> 4322.3312 | P10: =AVERAGE(H703:H802) -> 4339.2851 | Q10: =AVERAGE(I703:I802) -> 4320.4179 | R10: =AVERAGE(J703:J802) -> 4313.7073 | S10: E,M | T10: =MAX(E703:E802) -> 4346.2297 | U10: =MAX(F703:F802) -> 4371.0441 | V10: =MAX(G703:G802) -> 4332.5487 | W10: =MAX(H703:H802) -> 4343.8772 | X10: =MAX(I703:I802) -> 4337.3997 | Y10: =MAX(J703:J802) -> 4318.4877 | Z10: E,M | AA10: =MIN(E703:E802) -> 4313.6098 | AB10: =MIN(F703:F802) -> 4313.6098 | AC10: =MIN(G703:G802) -> 4314.0251 | AD10: =MIN(H703:H802) -> 4313.6098 | AE10: =MIN(I703:I802) -> 4313.6098 | AF10: =MIN(J703:J802) -> 4313.6098 | AG10: E,M | AH10: =(L10-$R10)/$L10 -> 0.0074828976 | AI10: =(M10-$R10)/M10 -> 0.0043396988 | AJ10: =(N10-$R10)/N10 -> 0.0047038948 | AK10: =(O10-$R10)/O10 -> 0.0019951952 | AL10: =(P10-$R10)/P10 -> 0.0058944579 | AM10: =(Q10-$R10)/Q10 -> 0.0015532143 | AN10: =(R10-$R10)/$R10 -> 0 | AO10: E,M | AP10: =L10/$L10 -> 1 | AQ10: =M10/$L10 -> 0.9968431 | AR10: =N10/$L10 -> 0.99720786 | AS10: =O10/$L10 -> 0.99450133 | AT10: =P10/$L10 -> 0.99840214 | AU10: =Q10/$L10 -> 0.99406109 | AV10: =R10/$L10 -> 0.9925171
A11: Montage | B11: 25 | C11: 1 | D11: ='original data '!D11 -> 28.7148 | E11: ='original data '!F11 -> 28.7148 | F11: ='original data '!I11 -> 28.71203 | G11: ='original data '!L11 -> 28.7148 | H11: ='original data '!O11 -> 28.74417 | I11: ='original data '!R11 -> 28.64701 | J11: ='original data '!U11 -> 28.54624 | K11: E,L | L11: =AVERAGE(D803:D902) -> 35669.695 | M11: =AVERAGE(E803:E902) -> 35668.696 | N11: =AVERAGE(F803:F902) -> 35678.603 | O11: =AVERAGE(G803:G902) -> 35310.961 | P11: =AVERAGE(H803:H902) -> 35652.438 | Q11: =AVERAGE(I803:I902) -> 35460.739 | R11: =AVERAGE(J803:J902) -> 35250.492 | S11: E,L | T11: =MAX(E803:E902) -> 35669.695 | U11: =MAX(F803:F902) -> 36533.064 | V11: =MAX(G803:G902) -> 35484.919 | W11: =MAX(H803:H902) -> 35669.695 | X11: =MAX(I803:I902) -> 35669.695 | Y11: =MAX(J803:J902) -> 35276.828 | Z11: E,L | AA11: =MIN(E803:E902) -> 35635.362 | AB11: =MIN(F803:F902) -> 35296.942 | AC11: =MIN(G803:G902) -> 35222.271 | AD11: =MIN(H803:H902) -> 35532.425 | AE11: =MIN(I803:I902) -> 35272.863 | AF11: =MIN(J803:J902) -> 35215.827 | AG11: E,L | AH11: =(L11-$R11)/$L11 -> 0.011752361 | AI11: =(M11-$R11)/M11 -> 0.011724679 | AJ11: =(N11-$R11)/N11 -> 0.0119991 | AK11: =(O11-$R11)/O11 -> 0.0017124701 | AL11: =(P11-$R11)/P11 -> 0.01127402 | AM11: =(Q11-$R11)/Q11 -> 0.005929032 | AN11: =(R11-$R11)/$R11 -> 0 | AO11: E,L | AP11: =L11/$L11 -> 1 | AQ11: =M11/$L11 -> 0.99997199 | AR11: =N11/$L11 -> 1.0002497 | AS11: =O11/$L11 -> 0.98994289 | AT11: =P11/$L11 -> 0.9995162 | AU11: =Q11/$L11 -> 0.99414194 | AV11: =R11/$L11 -> 0.98824764
A12: Montage | B12: 25 | C12: 1 | D12: ='original data '!D12 -> 28.7148 | E12: ='original data '!F12 -> 28.7148 | F12: ='original data '!I12 -> 28.90608 | G12: ='original data '!L12 -> 28.7148 | H12: ='original data '!O12 -> 28.74417 | I12: ='original data '!R12 -> 28.60624 | J12: ='original data '!U12 -> 28.54624 | K12: L,S | L12: =AVERAGE(D903:D1002) -> 699.02291 | M12: =AVERAGE(E903:E1002) -> 674.36496 | N12: =AVERAGE(F903:F1002) -> 662.12085 | O12: =AVERAGE(G903:G1002) -> 659.94218 | P12: =AVERAGE(H903:H1002) -> 671.9342 | Q12: =AVERAGE(I903:I1002) -> 656.49828 | R12: =AVERAGE(J903:J1002) -> 657.67605 | S12: L,S | T12: =MAX(E903:E1002) -> 699.02291 | U12: =MAX(F903:F1002) -> 676.91654 | V12: =MAX(G903:G1002) -> 663.80215 | W12: =MAX(H903:H1002) -> 681.44507 | X12: =MAX(I903:I1002) -> 661.53393 | Y12: =MAX(J903:J1002) -> 659.84543 | Z12: L,S | AA12: =MIN(E903:E1002) -> 657.32993 | AB12: =MIN(F903:F1002) -> 655.43296 | AC12: =MIN(G903:G1002) -> 658.71364 | AD12: =MIN(H903:H1002) -> 655.43296 | AE12: =MIN(I903:I1002) -> 655.43296 | AF12: =MIN(J903:J1002) -> 657.32381 | AG12: L,S | AH12: =(L12-$R12)/$L12 -> 0.059149504 | AI12: =(M12-$R12)/M12 -> 0.024747587 | AJ12: =(N12-$R12)/N12 -> 0.0067129684 | AK12: =(O12-$R12)/O12 -> 0.0034338364 | AL12: =(P12-$R12)/P12 -> 0.021219567 | AM12: =(Q12-$R12)/Q12 -> -0.0017940228 | AN12: =(R12-$R12)/$R12 -> 0 | AO12: L,S | AP12: =L12/$L12 -> 1 | AQ12: =M12/$L12 -> 0.96472511 | AR12: =N12/$L12 -> 0.94720908 | AS12: =O12/$L12 -> 0.94409235 | AT12: =P12/$L12 -> 0.96124776 | AU12: =Q12/$L12 -> 0.93916561 | AV12: =R12/$L12 -> 0.9408505
A13: Montage | B13: 25 | C13: 1 | D13: ='original data '!D13 -> 28.7148 | E13: ='original data '!F13 -> 28.7148 | F13: ='original data '!I13 -> 28.65703 | G13: ='original data '!L13 -> 28.7148 | H13: ='original data '!O13 -> 28.75296 | I13: ='original data '!R13 -> 28.54624 | J13: ='original data '!U13 -> 28.54624 | K13: L,M | L13: =AVERAGE(D1003:D1102) -> 1027.0157 | M13: =AVERAGE(E1003:E1102) -> 1024.669 | N13: =AVERAGE(F1003:F1102) -> 1051.2164 | O13: =AVERAGE(G1003:G1102) -> 998.53959 | P13: =AVERAGE(H1003:H1102) -> 1064.2816 | Q13: =AVERAGE(I1003:I1102) -> 1002.7198 | R13: =AVERAGE(J1003:J1102) -> 993.5572 | S13: L,M | T13: =MAX(E1003:E1102) -> 1027.0157 | U13: =MAX(F1003:F1102) -> 1103.1415 | V13: =MAX(G1003:G1102) -> 1013.3152 | W13: =MAX(H1003:H1102) -> 1133.7267 | X13: =MAX(I1003:I1102) -> 1010.2888 | Y13: =MAX(J1003:J1102) -> 996.85631 | Z13: L,M | AA13: =MIN(E1003:E1102) -> 1004.936 | AB13: =MIN(F1003:F1102) -> 1013.7805 | AC13: =MIN(G1003:G1102) -> 992.6554 | AD13: =MIN(H1003:H1102) -> 1025.2845 | AE13: =MIN(I1003:I1102) -> 990.8314 | AF13: =MIN(J1003:J1102) -> 990.05487 | AG13: L,M | AH13: =(L13-$R13)/$L13 -> 0.032578412 | AI13: =(M13-$R13)/M13 -> 0.030362775 | AJ13: =(N13-$R13)/N13 -> 0.054850027 | AK13: =(O13-$R13)/O13 -> 0.0049896747 | AL13: =(P13-$R13)/P13 -> 0.066452728 | AM13: =(Q13-$R13)/Q13 -> 0.0091377398 | AN13: =(R13-$R13)/$R13 -> 0 | AO13: L,M | AP13: =L13/$L13 -> 1 | AQ13: =M13/$L13 -> 0.99771498 | AR13: =N13/$L13 -> 1.0235641 | AS13: =O13/$L13 -> 0.97227291 | AT13: =P13/$L13 -> 1.0362856 | AU13: =Q13/$L13 -> 0.97634316 | AV13: =R13/$L13 -> 0.96742159
A14: Montage | B14: 25 | C14: 1 | D14: ='original data '!D14 -> 28.7148 | E14: ='original data '!F14 -> 28.7148 | F14: ='original data '!I14 -> 29.00328 | G14: ='original data '!L14 -> 28.7148 | H14: ='original data '!O14 -> 28.74417 | I14: ='original data '!R14 -> 28.59203 | J14: ='original data '!U14 -> 28.5041 | K14: L,L | L14: =AVERAGE(D1103:D1202) -> 1774.48 | M14: =AVERAGE(E1103:E1202) -> 1774.48 | N14: =AVERAGE(F1103:F1202) -> 1802.9881 | O14: =AVERAGE(G1103:G1202) -> 1757.4768 | P14: =AVERAGE(H1103:H1202) -> 1816.6912 | Q14: =AVERAGE(I1103:I1202) -> 1762.2534 | R14: =AVERAGE(J1103:J1202) -> 1756.9921 | S14: L,L | T14: =MAX(E1103:E1202) -> 1774.48 | U14: =MAX(F1103:F1202) -> 1865.7622 | V14: =MAX(G1103:G1202) -> 1763.3388 | W14: =MAX(H1103:H1202) -> 1862.235 | X14: =MAX(I1103:I1202) -> 1767.24 | Y14: =MAX(J1103:J1202) -> 1763.6464 | Z14: L,L | AA14: =MIN(E1103:E1202) -> 1774.48 | AB14: =MIN(F1103:F1202) -> 1756.1087 | AC14: =MIN(G1103:G1202) -> 1755.0747 | AD14: =MIN(H1103:H1202) -> 1784.2733 | AE14: =MIN(I1103:I1202) -> 1755.9633 | AF14: =MIN(J1103:J1202) -> 1753.8633 | AG14: L,L | AH14: =(L14-$R14)/$L14 -> 0.0098552362 | AI14: =(M14-$R14)/M14 -> 0.0098552362 | AJ14: =(N14-$R14)/N14 -> 0.025511016 | AK14: =(O14-$R14)/O14 -> 0.00027577759 | AL14: =(P14-$R14)/P14 -> 0.032861459 | AM14: =(Q14-$R14)/Q14 -> 0.0029855675 | AN14: =(R14-$R14)/$R14 -> 0 | AO14: L,L | AP14: =L14/$L14 -> 1 | AQ14: =M14/$L14 -> 1 | AR14: =N14/$L14 -> 1.0160656 | AS14: =O14/$L14 -> 0.9904179 | AT14: =P14/$L14 -> 1.0237879 | AU14: =Q14/$L14 -> 0.99310976 | AV14: =R14/$L14 -> 0.99014476
A15: Montage | B15: 25 | C15: 1 | D15: ='original data '!D15 -> 28.7148 | E15: ='original data '!F15 -> 28.64701 | F15: ='original data '!I15 -> 29.08495 | G15: ='original data '!L15 -> 28.7148 | H15: ='original data '!O15 -> 28.74417 | I15: ='original data '!R15 -> 28.64701 | J15: ='original data '!U15 -> 28.54624 | K15: G,S | L15: =AVERAGE(D1203:D1302) -> 8.54243 | M15: =AVERAGE(E1203:E1302) -> 8.54243 | N15: =AVERAGE(F1203:F1302) -> 8.5424369 | O15: =AVERAGE(G1203:G1302) -> 8.54243 | P15: =AVERAGE(H1203:H1302) -> 8.54243 | Q15: =AVERAGE(I1203:I1302) -> 8.54243 | R15: =AVERAGE(J1203:J1302) -> 8.54243 | S15: G,S | T15: =MAX(E1203:E1302) -> 8.54243 | U15: =MAX(F1203:F1302) -> 8.54256 | V15: =MAX(G1203:G1302) -> 8.54243 | W15: =MAX(H1203:H1302) -> 8.54243 | X15: =MAX(I1203:I1302) -> 8.54243 | Y15: =MAX(J1203:J1302) -> 8.54243 | Z15: G,S | AA15: =MIN(E1203:E1302) -> 8.54243 | AB15: =MIN(F1203:F1302) -> 8.54243 | AC15: =MIN(G1203:G1302) -> 8.54243 | AD15: =MIN(H1203:H1302) -> 8.54243 | AE15: =MIN(I1203:I1302) -> 8.54243 | AF15: =MIN(J1203:J1302) -> 8.54243 | AG15: G,S | AH15: =(L15-$R15)/$L15 -> 0 | AI15: =(M15-$R15)/M15 -> 0 | AJ15: =(N15-$R15)/N15 -> 8.0773204e-07 | AK15: =(O15-$R15)/O15 -> 0 | AL15: =(P15-$R15)/P15 -> 0 | AM15: =(Q15-$R15)/Q15 -> 0 | AN15: =(R15-$R15)/$R15 -> 0 | AO15: G,S | AP15: =L15/$L15 -> 1 | AQ15: =M15/$L15 -> 1 | AR15: =N15/$L15 -> 1.0000008 | AS15: =O15/$L15 -> 1 | AT15: =P15/$L15 -> 1 | AU15: =Q15/$L15 -> 1 | AV15: =R15/$L15 -> 1
A16: Montage | B16: 25 | C16: 1 | D16: ='original data '!D16 -> 28.7148 | E16: ='original data '!F16 -> 28.7148 | F16: ='original data '!I16 -> 31.3647 | G16: ='original data '!L16 -> 28.7148 | H16: ='original data '!O16 -> 28.70029 | I16: ='original data '!R16 -> 28.54624 | J16: ='original data '!U16 -> 28.54624 | K16: G,M | L16: =AVERAGE(D1303:D1402) -> 80.12632 | M16: =AVERAGE(E1303:E1402) -> 80.120593 | N16: =AVERAGE(F1303:F1402) -> 82.756825 | O16: =AVERAGE(G1303:G1402) -> 76.85111 | P16: =AVERAGE(H1303:H1402) -> 83.49283 | Q16: =AVERAGE(I1303:I1402) -> 77.903966 | R16: =AVERAGE(J1303:J1402) -> 76.572331 | S16: G,M | T16: =MAX(E1303:E1402) -> 80.12632 | U16: =MAX(F1303:F1402) -> 90.54956 | V16: =MAX(G1303:G1402) -> 78.23853 | W16: =MAX(H1303:H1402) -> 84.99252 | X16: =MAX(I1303:I1402) -> 78.91921 | Y16: =MAX(J1303:J1402) -> 77.18472 | Z16: G,M | AA16: =MIN(E1303:E1402) -> 79.6552 | AB16: =MIN(F1303:F1402) -> 79.60329 | AC16: =MIN(G1303:G1402) -> 76.33402 | AD16: =MIN(H1303:H1402) -> 82.02048 | AE16: =MIN(I1303:I1402) -> 77.28067 | AF16: =MIN(J1303:J1402) -> 76.00356 | AG16: G,M | AH16: =(L16-$R16)/$L16 -> 0.044354829 | AI16: =(M16-$R16)/M16 -> 0.044286521 | AJ16: =(N16-$R16)/N16 -> 0.074730926 | AK16: =(O16-$R16)/O16 -> 0.0036275234 | AL16: =(P16-$R16)/P16 -> 0.082887351 | AM16: =(Q16-$R16)/Q16 -> 0.017093286 | AN16: =(R16-$R16)/$R16 -> 0 | AO16: G,M | AP16: =L16/$L16 -> 1 | AQ16: =M16/$L16 -> 0.99992853 | AR16: =N16/$L16 -> 1.0328295 | AS16: =O16/$L16 -> 0.95912442 | AT16: =P16/$L16 -> 1.042015 | AU16: =Q16/$L16 -> 0.97226436 | AV16: =R16/$L16 -> 0.95564517
A17: Montage | B17: 25 | C17: 1 | D17: ='original data '!D17 -> 28.7148 | E17: ='original data '!F17 -> 28.7148 | F17: ='original data '!I17 -> 31.11252 | G17: ='original data '!L17 -> 28.7148 | H17: ='original data '!O17 -> 28.70029 | I17: ='original data '!R17 -> 28.54624 | J17: ='original data '!U17 -> 28.54624 | K17: G,L | L17: =AVERAGE(D1403:D1502) -> 123.43652 | M17: =AVERAGE(E1403:E1502) -> 123.43652 | N17: =AVERAGE(F1403:F1502) -> 127.84316 | O17: =AVERAGE(G1403:G1502) -> 119.34135 | P17: =AVERAGE(H1403:H1502) -> 129.57431 | Q17: =AVERAGE(I1403:I1502) -> 120.58811 | R17: =AVERAGE(J1403:J1502) -> 119.19083 | S17: G,L | T17: =MAX(E1403:E1502) -> 123.43652 | U17: =MAX(F1403:F1502) -> 133.21538 | V17: =MAX(G1403:G1502) -> 120.75932 | W17: =MAX(H1403:H1502) -> 131.45597 | X17: =MAX(I1403:I1502) -> 121.29885 | Y17: =MAX(J1403:J1502) -> 119.78082 | Z17: G,L | AA17: =MIN(E1403:E1502) -> 123.43652 | AB17: =MIN(F1403:F1502) -> 122.73202 | AC17: =MIN(G1403:G1502) -> 118.61685 | AD17: =MIN(H1403:H1502) -> 127.07185 | AE17: =MIN(I1403:I1502) -> 120.02656 | AF17: =MIN(J1403:J1502) -> 118.44476 | AG17: G,L | AH17: =(L17-$R17)/$L17 -> 0.034395757 | AI17: =(M17-$R17)/M17 -> 0.034395757 | AJ17: =(N17-$R17)/N17 -> 0.067679274 | AK17: =(O17-$R17)/O17 -> 0.0012612921 | AL17: =(P17-$R17)/P17 -> 0.080135326 | AM17: =(Q17-$R17)/Q17 -> 0.011587246 | AN17: =(R17-$R17)/$R17 -> 0 | AO17: G,L | AP17: =L17/$L17 -> 1 | AQ17: =M17/$L17 -> 1 | AR17: =N17/$L17 -> 1.0356996 | AS17: =O17/$L17 -> 0.96682369 | AT17: =P17/$L17 -> 1.0497242 | AU17: =Q17/$L17 -> 0.9769241 | AV17: =R17/$L17 -> 0.96560424
A18: Montage | B18: 25 | C18: 1 | D18: ='original data '!D18 -> 28.7148 | E18: ='original data '!F18 -> 28.7148 | F18: ='original data '!I18 -> 28.72933 | G18: ='original data '!L18 -> 28.7148 | H18: ='original data '!O18 -> 28.82529 | I18: ='original data '!R18 -> 28.54624 | J18: ='original data '!U18 -> 28.54624 | K18: F,S | L18: =AVERAGE(D1503:D1602) -> 17.83966 | M18: =AVERAGE(E1503:E1602) -> 17.723946 | N18: =AVERAGE(F1503:F1602) -> 18.05353 | O18: =AVERAGE(G1503:G1602) -> 16.86576 | P18: =AVERAGE(H1503:H1602) -> 18.741277 | Q18: =AVERAGE(I1503:I1602) -> 17.080234 | R18: =AVERAGE(J1503:J1602) -> 16.662235 | S18: F,S | T18: =MAX(E1503:E1602) -> 17.83966 | U18: =MAX(F1503:F1602) -> 19.07941 | V18: =MAX(G1503:G1602) -> 17.22705 | W18: =MAX(H1503:H1602) -> 19.25513 | X18: =MAX(I1503:I1602) -> 17.4204 | Y18: =MAX(J1503:J1602) -> 16.81385 | Z18: F,S | AA18: =MIN(E1503:E1602) -> 16.94709 | AB18: =MIN(F1503:F1602) -> 17.08916 | AC18: =MIN(G1503:G1602) -> 16.54063 | AD18: =MIN(H1503:H1602) -> 17.65302 | AE18: =MIN(I1503:I1602) -> 16.743 | AF18: =MIN(J1503:J1602) -> 16.48228 | AG18: F,S | AH18: =(L18-$R18)/$L18 -> 0.066000428 | AI18: =(M18-$R18)/M18 -> 0.059902648 | AJ18: =(N18-$R18)/N18 -> 0.07706501 | AK18: =(O18-$R18)/O18 -> 0.012067354 | AL18: =(P18-$R18)/P18 -> 0.11093384 | AM18: =(Q18-$R18)/Q18 -> 0.024472669 | AN18: =(R18-$R18)/$R18 -> 0 | AO18: F,S | AP18: =L18/$L18 -> 1 | AQ18: =M18/$L18 -> 0.99351367 | AR18: =N18/$L18 -> 1.0119885 | AS18: =O18/$L18 -> 0.94540815 | AT18: =P18/$L18 -> 1.05054 | AU18: =Q18/$L18 -> 0.95743045 | AV18: =R18/$L18 -> 0.93399957
A19: Montage | B19: 25 | C19: 1 | D19: ='original data '!D19 -> 28.7148 | E19: ='original data '!F19 -> 28.7148 | F19: ='original data '!I19 -> 29.864 | G19: ='original data '!L19 -> 28.7148 | H19: ='original data '!O19 -> 28.70029 | I19: ='original data '!R19 -> 28.60624 | J19: ='original data '!U19 -> 28.5041 | K19: F,M | L19: =AVERAGE(D1603:D1702) -> 35.64892 | M19: =AVERAGE(E1603:E1702) -> 35.644938 | N19: =AVERAGE(F1603:F1702) -> 36.687374 | O19: =AVERAGE(G1603:G1702) -> 35.216209 | P19: =AVERAGE(H1603:H1702) -> 35.737806 | Q19: =AVERAGE(I1603:I1702) -> 35.455768 | R19: =AVERAGE(J1603:J1702) -> 35.154573 | S19: F,M | T19: =MAX(E1603:E1702) -> 35.64892 | U19: =MAX(F1603:F1702) -> 39.01631 | V19: =MAX(G1603:G1702) -> 35.43092 | W19: =MAX(H1603:H1702) -> 35.89243 | X19: =MAX(I1603:I1702) -> 35.52495 | Y19: =MAX(J1603:J1702) -> 35.2471 | Z19: F,M | AA19: =MIN(E1603:E1702) -> 35.53135 | AB19: =MIN(F1603:F1702) -> 35.59427 | AC19: =MIN(G1603:G1702) -> 35.09442 | AD19: =MIN(H1603:H1702) -> 35.37443 | AE19: =MIN(I1603:I1702) -> 35.28103 | AF19: =MIN(J1603:J1702) -> 35.07041 | AG19: F,M | AH19: =(L19-$R19)/$L19 -> 0.013867107 | AI19: =(M19-$R19)/M19 -> 0.01375693 | AJ19: =(N19-$R19)/N19 -> 0.041780066 | AK19: =(O19-$R19)/O19 -> 0.001750231 | AL19: =(P19-$R19)/P19 -> 0.016319788 | AM19: =(Q19-$R19)/Q19 -> 0.0084949759 | AN19: =(R19-$R19)/$R19 -> 0 | AO19: F,M | AP19: =L19/$L19 -> 1 | AQ19: =M19/$L19 -> 0.99988829 | AR19: =N19/$L19 -> 1.02913 | AS19: =O19/$L19 -> 0.98786188 | AT19: =P19/$L19 -> 1.0024934 | AU19: =Q19/$L19 -> 0.99458184 | AV19: =R19/$L19 -> 0.98613289
A20: Montage | B20: 25 | C20: 1 | D20: ='original data '!D20 -> 28.7148 | E20: ='original data '!F20 -> 28.70478 | F20: ='original data '!I20 -> 30.81114 | G20: ='original data '!L20 -> 28.7148 | H20: ='original data '!O20 -> 28.82924 | I20: ='original data '!R20 -> 28.64701 | J20: ='original data '!U20 -> 28.54624 | K20: F,L | L20: =AVERAGE(D1703:D1802) -> 72.35609 | M20: =AVERAGE(E1703:E1802) -> 72.35609 | N20: =AVERAGE(F1703:F1802) -> 73.493517 | O20: =AVERAGE(G1703:G1802) -> 71.971538 | P20: =AVERAGE(H1703:H1802) -> 72.690419 | Q20: =AVERAGE(I1703:I1802) -> 72.268356 | R20: =AVERAGE(J1703:J1802) -> 71.943583 | S20: F,L | T20: =MAX(E1703:E1802) -> 72.35609 | U20: =MAX(F1703:F1802) -> 76.54496 | V20: =MAX(G1703:G1802) -> 72.14702 | W20: =MAX(H1703:H1802) -> 73.13597 | X20: =MAX(I1703:I1802) -> 72.27935 | Y20: =MAX(J1703:J1802) -> 72.02416 | Z20: F,L | AA20: =MIN(E1703:E1802) -> 72.35609 | AB20: =MIN(F1703:F1802) -> 72.42843 | AC20: =MIN(G1703:G1802) -> 71.91369 | AD20: =MIN(H1703:H1802) -> 72.27255 | AE20: =MIN(I1703:I1802) -> 72.20657 | AF20: =MIN(J1703:J1802) -> 71.91113 | AG20: F,L | AH20: =(L20-$R20)/$L20 -> 0.0057010709 | AI20: =(M20-$R20)/M20 -> 0.0057010709 | AJ20: =(N20-$R20)/N20 -> 0.021089404 | AK20: =(O20-$R20)/O20 -> 0.00038842577 | AL20: =(P20-$R20)/P20 -> 0.0102742 | AM20: =(Q20-$R20)/Q20 -> 0.0044939932 | AN20: =(R20-$R20)/$R20 -> 0 | AO20: F,L | AP20: =L20/$L20 -> 1 | AQ20: =M20/$L20 -> 1 | AR20: =N20/$L20 -> 1.0157199 | AS20: =O20/$L20 -> 0.99468529 | AT20: =P20/$L20 -> 1.0046206 | AU20: =Q20/$L20 -> 0.99878747 | AV20: =R20/$L20 -> 0.99429893
A21: Montage | B21: 25 | C21: 1 | D21: ='original data '!D21 -> 28.7148 | E21: ='original data '!F21 -> 28.7148 | F21: ='original data '!I21 -> 28.79363 | G21: ='original data '!L21 -> 28.7148 | H21: ='original data '!O21 -> 29.98095 | I21: ='original data '!R21 -> 28.64701 | J21: ='original data '!U21 -> 28.54624 | AH21: =AVERAGE(AH3:AH20) -> 0.038846013 | AI21: =AVERAGE(AI3:AI20) -> 0.024007981 | AJ21: =AVERAGE(AJ3:AJ20) -> 0.037521001 | AK21: =AVERAGE(AK3:AK20) -> 0.015214253 | AL21: =AVERAGE(AL3:AL20) -> 0.035007995 | AM21: =AVERAGE(AM3:AM20) -> 0.0084535887 | AN21: =AVERAGE(AN3:AN20) -> 0 | AP21: =AVERAGE(AP3:AP20) -> 1 | AQ21: =AVERAGE(AQ3:AQ20) -> 0.9847594 | AR21: =AVERAGE(AR3:AR20) -> 0.99901658 | AS21: =AVERAGE(AS3:AS20) -> 0.97629017 | AT21: =AVERAGE(AT3:AT20) -> 0.99675271 | AU21: =AVERAGE(AU3:AU20) -> 0.9693862 | AV21: =AVERAGE(AV3:AV20) -> 0.96115399
A22: Montage | B22: 25 | C22: 1 | D22: ='original data '!D22 -> 28.7148 | E22: ='original data '!F22 -> 28.7148 | F22: ='original data '!I22 -> 30.73727 | G22: ='original data '!L22 -> 28.7148 | H22: ='original data '!O22 -> 28.74417 | I22: ='original data '!R22 -> 28.64203 | J22: ='original data '!U22 -> 28.58701
A23: Montage | B23: 25 | C23: 1 | D23: ='original data '!D23 -> 28.7148 | E23: ='original data '!F23 -> 28.7148 | F23: ='original data '!I23 -> 29.747 | G23: ='original data '!L23 -> 28.7148 | H23: ='original data '!O23 -> 28.74417 | I23: ='original data '!R23 -> 28.64701 | J23: ='original data '!U23 -> 28.5041
A24: Montage | B24: 25 | C24: 1 | D24: ='original data '!D24 -> 28.7148 | E24: ='original data '!F24 -> 28.7148 | F24: ='original data '!I24 -> 30.72959 | G24: ='original data '!L24 -> 28.7148 | H24: ='original data '!O24 -> 28.70029 | I24: ='original data '!R24 -> 28.60624 | J24: ='original data '!U24 -> 28.54624
A25: Montage | B25: 25 | C25: 1 | D25: ='original data '!D25 -> 28.7148 | E25: ='original data '!F25 -> 28.7148 | F25: ='original data '!I25 -> 28.8651 | G25: ='original data '!L25 -> 28.7148 | H25: ='original data '!O25 -> 28.82924 | I25: ='original data '!R25 -> 28.64701 | J25: ='original data '!U25 -> 28.54624
A26: Montage | B26: 25 | C26: 1 | D26: ='original data '!D26 -> 28.7148 | E26: ='original data '!F26 -> 28.7148 | F26: ='original data '!I26 -> 31.96014 | G26: ='original data '!L26 -> 28.7148 | H26: ='original data '!O26 -> 28.70029 | I26: ='original data '!R26 -> 28.54624 | J26: ='original data '!U26 -> 28.5041
A27: Montage | B27: 25 | C27: 1 | D27: ='original data '!D27 -> 28.7148 | E27: ='original data '!F27 -> 28.70478 | F27: ='original data '!I27 -> 31.98679 | G27: ='original data '!L27 -> 28.7148 | H27: ='original data '!O27 -> 28.65245 | I27: ='original data '!R27 -> 28.64701 | J27: ='original data '!U27 -> 28.5041
A28: Montage | B28: 25 | C28: 1 | D28: ='original data '!D28 -> 28.7148 | E28: ='original data '!F28 -> 28.70478 | F28: ='original data '!I28 -> 29.864 | G28: ='original data '!L28 -> 28.7148 | H28: ='original data '!O28 -> 28.70029 | I28: ='original data '!R28 -> 28.64701 | J28: ='original data '!U28 -> 28.54624
A29: Montage | B29: 25 | C29: 1 | D29: ='original data '!D29 -> 28.7148 | E29: ='original data '!F29 -> 28.7148 | F29: ='original data '!I29 -> 31.16258 | G29: ='original data '!L29 -> 28.7148 | H29: ='original data '!O29 -> 28.74417 | I29: ='original data '!R29 -> 28.64701 | J29: ='original data '!U29 -> 28.54624
A30: Montage | B30: 25 | C30: 1 | D30: ='original data '!D30 -> 28.7148 | E30: ='original data '!F30 -> 28.65703 | F30: ='original data '!I30 -> 28.79512 | G30: ='original data '!L30 -> 28.7148 | H30: ='original data '!O30 -> 28.74417 | I30: ='original data '!R30 -> 28.64701 | J30: ='original data '!U30 -> 28.54624
A31: Montage | B31: 25 | C31: 1 | D31: ='original data '!D31 -> 28.7148 | E31: ='original data '!F31 -> 28.70478 | F31: ='original data '!I31 -> 28.86235 | G31: ='original data '!L31 -> 28.7148 | H31: ='original data '!O31 -> 28.82924 | I31: ='original data '!R31 -> 28.54624 | J31: ='original data '!U31 -> 28.5041
A32: Montage | B32: 25 | C32: 1 | D32: ='original data '!D32 -> 28.7148 | E32: ='original data '!F32 -> 28.7148 | F32: ='original data '!I32 -> 29.66986 | G32: ='original data '!L32 -> 28.7148 | H32: ='original data '!O32 -> 28.70029 | I32: ='original data '!R32 -> 28.64701 | J32: ='original data '!U32 -> 28.54624
A33: Montage | B33: 25 | C33: 1 | D33: ='original data '!D33 -> 28.7148 | E33: ='original data '!F33 -> 28.7148 | F33: ='original data '!I33 -> 31.78771 | G33: ='original data '!L33 -> 28.7148 | H33: ='original data '!O33 -> 28.82924 | I33: ='original data '!R33 -> 28.60624 | J33: ='original data '!U33 -> 28.54624
... A1802: fft | B1802: 224 | C1802: 1 | D1802: ='original data '!D1802 -> 72.35609 | E1802: ='original data '!F1802 -> 72.35609 | F1802: ='original data '!I1802 -> 72.90048 | G1802: ='original data '!L1802 -> 71.94765 | H1802: ='original data '!O1802 -> 72.63722 | I1802: ='original data '!R1802 -> 72.26319 | J1802: ='original data '!U1802 -> 71.93967

Sheet boxplot（Fig.1） 
D1: ms | E1: ms | F1: ms | G1: ms | H1: ms | I1: ms | J1: ms
D2: HEFT | E2: HGA | F2: LWSGA | G2: APRE_EDA | H2: HPSO | I2: R2GA | J2: HEDA | M2: =D2 -> HEFT | N2: =E2 -> HGA | O2: =F2 -> LWSGA | P2: APRE_EDA | Q2: HPSO | R2: R²GA | S2: =J2 -> HEDA
A3: Montage | B3: 25 | C3: 1 | D3: ='original data '!D3 -> 28.7148 | E3: ='original data '!F3 -> 28.7148 | F3: ='original data '!I3 -> 28.72703 | G3: ='original data '!L3 -> 28.7148 | H3: ='original data '!O3 -> 28.65213 | I3: ='original data '!R3 -> 28.64701 | J3: ='original data '!U3 -> 28.5041 | L3: M,S | M3: =D3/D3 -> 1 | N3: =E3/D3 -> 1 | O3: =F3/D3 -> 1.0004259 | P3: =G3/D3 -> 1 | Q3: =H3/D3 -> 0.9978175 | R3: =I3/D3 -> 0.9976392 | S3: =J3/D3 -> 0.99266232
A4: Montage | B4: 25 | C4: 1 | D4: ='original data '!D4 -> 28.7148 | E4: ='original data '!F4 -> 28.7148 | F4: ='original data '!I4 -> 28.87217 | G4: ='original data '!L4 -> 28.7148 | H4: ='original data '!O4 -> 28.70029 | I4: ='original data '!R4 -> 28.59203 | J4: ='original data '!U4 -> 28.54624 | L4: M,S | M4: =D4/D4 -> 1 | N4: =E4/D4 -> 1 | O4: =F4/D4 -> 1.0054804 | P4: =G4/D4 -> 1 | Q4: =H4/D4 -> 0.99949469 | R4: =I4/D4 -> 0.9957245 | S4: =J4/D4 -> 0.99412986
A5: Montage | B5: 25 | C5: 1 | D5: ='original data '!D5 -> 28.7148 | E5: ='original data '!F5 -> 28.7148 | F5: ='original data '!I5 -> 30.11037 | G5: ='original data '!L5 -> 28.7148 | H5: ='original data '!O5 -> 28.77029 | I5: ='original data '!R5 -> 28.64701 | J5: ='original data '!U5 -> 28.5041 | L5: M,S | M5: =D5/D5 -> 1 | N5: =E5/D5 -> 1 | O5: =F5/D5 -> 1.0486011 | P5: =G5/D5 -> 1 | Q5: =H5/D5 -> 1.0019325 | R5: =I5/D5 -> 0.9976392 | S5: =J5/D5 -> 0.99266232
A6: Montage | B6: 25 | C6: 1 | D6: ='original data '!D6 -> 28.7148 | E6: ='original data '!F6 -> 28.7148 | F6: ='original data '!I6 -> 29.87502 | G6: ='original data '!L6 -> 28.7148 | H6: ='original data '!O6 -> 28.74417 | I6: ='original data '!R6 -> 28.54624 | J6: ='original data '!U6 -> 28.54624 | L6: M,S | M6: =D6/D6 -> 1 | N6: =E6/D6 -> 1 | O6: =F6/D6 -> 1.0404049 | P6: =G6/D6 -> 1 | Q6: =H6/D6 -> 1.0010228 | R6: =I6/D6 -> 0.99412986 | S6: =J6/D6 -> 0.99412986
A7: Montage | B7: 25 | C7: 1 | D7: ='original data '!D7 -> 28.7148 | E7: ='original data '!F7 -> 28.7148 | F7: ='original data '!I7 -> 28.8863 | G7: ='original data '!L7 -> 28.7148 | H7: ='original data '!O7 -> 28.74417 | I7: ='original data '!R7 -> 28.58701 | J7: ='original data '!U7 -> 28.54624 | L7: M,S | M7: =D7/D7 -> 1 | N7: =E7/D7 -> 1 | O7: =F7/D7 -> 1.0059725 | P7: =G7/D7 -> 1 | Q7: =H7/D7 -> 1.0010228 | R7: =I7/D7 -> 0.99554968 | S7: =J7/D7 -> 0.99412986
A8: Montage | B8: 25 | C8: 1 | D8: ='original data '!D8 -> 28.7148 | E8: ='original data '!F8 -> 28.7148 | F8: ='original data '!I8 -> 30.80614 | G8: ='original data '!L8 -> 28.7148 | H8: ='original data '!O8 -> 28.74417 | I8: ='original data '!R8 -> 28.64701 | J8: ='original data '!U8 -> 28.5041 | L8: M,S | M8: =D8/D8 -> 1 | N8: =E8/D8 -> 1 | O8: =F8/D8 -> 1.0728314 | P8: =G8/D8 -> 1 | Q8: =H8/D8 -> 1.0010228 | R8: =I8/D8 -> 0.9976392 | S8: =J8/D8 -> 0.99266232
A9: Montage | B9: 25 | C9: 1 | D9: ='original data '!D9 -> 28.7148 | E9: ='original data '!F9 -> 28.7148 | F9: ='original data '!I9 -> 30.82263 | G9: ='original data '!L9 -> 28.7148 | H9: ='original data '!O9 -> 28.70029 | I9: ='original data '!R9 -> 28.64701 | J9: ='original data '!U9 -> 28.54624 | L9: M,S | M9: =D9/D9 -> 1 | N9: =E9/D9 -> 1 | O9: =F9/D9 -> 1.0734057 | P9: =G9/D9 -> 1 | Q9: =H9/D9 -> 0.99949469 | R9: =I9/D9 -> 0.9976392 | S9: =J9/D9 -> 0.99412986
A10: Montage | B10: 25 | C10: 1 | D10: ='original data '!D10 -> 28.7148 | E10: ='original data '!F10 -> 28.7148 | F10: ='original data '!I10 -> 28.63568 | G10: ='original data '!L10 -> 28.7148 | H10: ='original data '!O10 -> 28.70029 | I10: ='original data '!R10 -> 28.64701 | J10: ='original data '!U10 -> 28.54624 | L10: M,S | M10: =D10/D10 -> 1 | N10: =E10/D10 -> 1 | O10: =F10/D10 -> 0.99724463 | P10: =G10/D10 -> 1 | Q10: =H10/D10 -> 0.99949469 | R10: =I10/D10 -> 0.9976392 | S10: =J10/D10 -> 0.99412986
A11: Montage | B11: 25 | C11: 1 | D11: ='original data '!D11 -> 28.7148 | E11: ='original data '!F11 -> 28.7148 | F11: ='original data '!I11 -> 28.71203 | G11: ='original data '!L11 -> 28.7148 | H11: ='original data '!O11 -> 28.74417 | I11: ='original data '!R11 -> 28.64701 | J11: ='original data '!U11 -> 28.54624 | L11: M,S | M11: =D11/D11 -> 1 | N11: =E11/D11 -> 1 | O11: =F11/D11 -> 0.99990353 | P11: =G11/D11 -> 1 | Q11: =H11/D11 -> 1.0010228 | R11: =I11/D11 -> 0.9976392 | S11: =J11/D11 -> 0.99412986
A12: Montage | B12: 25 | C12: 1 | D12: ='original data '!D12 -> 28.7148 | E12: ='original data '!F12 -> 28.7148 | F12: ='original data '!I12 -> 28.90608 | G12: ='original data '!L12 -> 28.7148 | H12: ='original data '!O12 -> 28.74417 | I12: ='original data '!R12 -> 28.60624 | J12: ='original data '!U12 -> 28.54624 | L12: M,S | M12: =D12/D12 -> 1 | N12: =E12/D12 -> 1 | O12: =F12/D12 -> 1.0066614 | P12: =G12/D12 -> 1 | Q12: =H12/D12 -> 1.0010228 | R12: =I12/D12 -> 0.99621937 | S12: =J12/D12 -> 0.99412986
A13: Montage | B13: 25 | C13: 1 | D13: ='original data '!D13 -> 28.7148 | E13: ='original data '!F13 -> 28.7148 | F13: ='original data '!I13 -> 28.65703 | G13: ='original data '!L13 -> 28.7148 | H13: ='original data '!O13 -> 28.75296 | I13: ='original data '!R13 -> 28.54624 | J13: ='original data '!U13 -> 28.54624 | L13: M,S | M13: =D13/D13 -> 1 | N13: =E13/D13 -> 1 | O13: =F13/D13 -> 0.99798815 | P13: =G13/D13 -> 1 | Q13: =H13/D13 -> 1.0013289 | R13: =I13/D13 -> 0.99412986 | S13: =J13/D13 -> 0.99412986
A14: Montage | B14: 25 | C14: 1 | D14: ='original data '!D14 -> 28.7148 | E14: ='original data '!F14 -> 28.7148 | F14: ='original data '!I14 -> 29.00328 | G14: ='original data '!L14 -> 28.7148 | H14: ='original data '!O14 -> 28.74417 | I14: ='original data '!R14 -> 28.59203 | J14: ='original data '!U14 -> 28.5041 | L14: M,S | M14: =D14/D14 -> 1 | N14: =E14/D14 -> 1 | O14: =F14/D14 -> 1.0100464 | P14: =G14/D14 -> 1 | Q14: =H14/D14 -> 1.0010228 | R14: =I14/D14 -> 0.9957245 | S14: =J14/D14 -> 0.99266232
... A16: Montage | B16: 25 | C16: 1 | D16: ='original data '!D16 -> 28.7148 | E16: ='original data '!F16 -> 28.7148 | F16: ='original data '!I16 -> 31.3647 | G16: ='original data '!L16 -> 28.7148 | H16: ='original data '!O16 -> 28.70029 | I16: ='original data '!R16 -> 28.54624 | J16: ='original data '!U16 -> 28.54624 | L16: M,S | M16: =D16/D16 -> 1 | N16: =E16/D16 -> 1 | O16: =F16/D16 -> 1.0922834 | P16: =G16/D16 -> 1 | Q16: =H16/D16 -> 0.99949469 | R16: =I16/D16 -> 0.99412986 | S16: =J16/D16 -> 0.99412986
A17: Montage | B17: 25 | C17: 1 | D17: ='original data '!D17 -> 28.7148 | E17: ='original data '!F17 -> 28.7148 | F17: ='original data '!I17 -> 31.11252 | G17: ='original data '!L17 -> 28.7148 | H17: ='original data '!O17 -> 28.70029 | I17: ='original data '!R17 -> 28.54624 | J17: ='original data '!U17 -> 28.54624 | L17: M,S | M17: =D17/D17 -> 1 | N17: =E17/D17 -> 1 | O17: =F17/D17 -> 1.0835012 | P17: =G17/D17 -> 1 | Q17: =H17/D17 -> 0.99949469 | R17: =I17/D17 -> 0.99412986 | S17: =J17/D17 -> 0.99412986 | U17: HEFT | V17: HGA | W17: LWSGA | X17: APRE_EDA | Y17: HPSO | Z17: R2GA | AA17: HEDA | AC17: HEFT | AD17: HGA | AE17: LWSGA | AF17: APRE_EDA | AG17: HPSO | AH17: R2GA | AI17: HEDA
A18: Montage | B18: 25 | C18: 1 | D18: ='original data '!D18 -> 28.7148 | E18: ='original data '!F18 -> 28.7148 | F18: ='original data '!I18 -> 28.72933 | G18: ='original data '!L18 -> 28.7148 | H18: ='original data '!O18 -> 28.82529 | I18: ='original data '!R18 -> 28.54624 | J18: ='original data '!U18 -> 28.54624 | L18: M,S | M18: =D18/D18 -> 1 | N18: =E18/D18 -> 1 | O18: =F18/D18 -> 1.000506 | P18: =G18/D18 -> 1 | Q18: =H18/D18 -> 1.0038478 | R18: =I18/D18 -> 0.99412986 | S18: =J18/D18 -> 0.99412986 | U18: =STDEV(D3:D102)/AVERAGE(D3:D102) -> 1.3678217e-15 | V18: =STDEV(E3:E102)/AVERAGE(E3:E102) -> 0.00077577006 | W18: =STDEV(F3:F102)/AVERAGE(F3:F102) -> 0.032921704 | X18: =STDEV(G3:G102)/AVERAGE(G3:G102) -> 1.3678217e-15 | Y18: =STDEV(H3:H102)/AVERAGE(H3:H102) -> 0.0063295767 | Z18: =STDEV(I3:I102)/AVERAGE(I3:I102) -> 0.001296722 | AA18: =STDEV(J3:J102)/AVERAGE(J3:J102) -> 0.00076077886 | AC18: =STDEV(M3:M102) -> 0 | AD18: =STDEV(N3:N102) -> 0.00077544526 | AE18: =STDEV(O3:O102) -> 0.033842804 | AF18: =STDEV(P3:P102) -> 0 | AG18: =STDEV(Q3:Q102) -> 0.0063407345 | AH18: =STDEV(R3:R102) -> 0.0012925828 | AI18: =STDEV(S3:S102) -> 0.00075593266
A19: Montage | B19: 25 | C19: 1 | D19: ='original data '!D19 -> 28.7148 | E19: ='original data '!F19 -> 28.7148 | F19: ='original data '!I19 -> 29.864 | G19: ='original data '!L19 -> 28.7148 | H19: ='original data '!O19 -> 28.70029 | I19: ='original data '!R19 -> 28.60624 | J19: ='original data '!U19 -> 28.5041 | L19: M,S | M19: =D19/D19 -> 1 | N19: =E19/D19 -> 1 | O19: =F19/D19 -> 1.0400212 | P19: =G19/D19 -> 1 | Q19: =H19/D19 -> 0.99949469 | R19: =I19/D19 -> 0.99621937 | S19: =J19/D19 -> 0.99266232 | U19: =STDEV(D103:D202)/AVERAGE(D103:D202) -> 1.7161855e-15 | V19: =STDEV(E103:E202)/AVERAGE(E103:E202) -> 0.0041536982 | W19: =STDEV(F103:F202)/AVERAGE(F103:F202) -> 0.022353811 | X19: =STDEV(G103:G202)/AVERAGE(G103:G202) -> 1.7161855e-15 | Y19: =STDEV(H103:H202)/AVERAGE(H103:H202) -> 0.019508773 | Z19: =STDEV(I103:I202)/AVERAGE(I103:I202) -> 0.0011265002 | AA19: =STDEV(J103:J202)/AVERAGE(J103:J202) -> 0.0010067759 | AC19: =STDEV(M103:M202) -> 0 | AD19: =STDEV(N103:N202) -> 0.0040343698 | AE19: =STDEV(O103:O202) -> 0.021323846 | AF19: =STDEV(P103:P202) -> 0 | AG19: =STDEV(Q103:Q202) -> 0.018847164 | AH19: =STDEV(R103:R202) -> 0.0010247944 | AI19: =STDEV(S103:S202) -> 0.00091602517
A20: Montage | B20: 25 | C20: 1 | D20: ='original data '!D20 -> 28.7148 | E20: ='original data '!F20 -> 28.70478 | F20: ='original data '!I20 -> 30.81114 | G20: ='original data '!L20 -> 28.7148 | H20: ='original data '!O20 -> 28.82924 | I20: ='original data '!R20 -> 28.64701 | J20: ='original data '!U20 -> 28.54624 | L20: M,S | M20: =D20/D20 -> 1 | N20: =E20/D20 -> 0.99965105 | O20: =F20/D20 -> 1.0730056 | P20: =G20/D20 -> 1 | Q20: =H20/D20 -> 1.0039854 | R20: =I20/D20 -> 0.9976392 | S20: =J20/D20 -> 0.99412986 | U20: =STDEV(D203:D302)/AVERAGE(D203:D302) -> 2.0361943e-15 | V20: =STDEV(E203:E302)/AVERAGE(E203:E302) -> 0.0024429655 | W20: =STDEV(F203:F302)/AVERAGE(F203:F302) -> 0.011963018 | X20: =STDEV(G203:G302)/AVERAGE(G203:G302) -> 2.0361943e-15 | Y20: =STDEV(H203:H302)/AVERAGE(H203:H302) -> 0.0014203443 | Z20: =STDEV(I203:I302)/AVERAGE(I203:I302) -> 0.00088392674 | AA20: =STDEV(J203:J302)/AVERAGE(J203:J302) -> 0.0012076807 | AC20: =STDEV(M203:M302) -> 0 | AD20: =STDEV(N203:N302) -> 0.0024295838 | AE20: =STDEV(O203:O302) -> 0.011980909 | AF20: =STDEV(P203:P302) -> 0 | AG20: =STDEV(Q203:Q302) -> 0.0014079488 | AH20: =STDEV(R203:R302) -> 0.00087153534 | AI20: =STDEV(S203:S302) -> 0.0011847921
A21: Montage | B21: 25 | C21: 1 | D21: ='original data '!D21 -> 28.7148 | E21: ='original data '!F21 -> 28.7148 | F21: ='original data '!I21 -> 28.79363 | G21: ='original data '!L21 -> 28.7148 | H21: ='original data '!O21 -> 29.98095 | I21: ='original data '!R21 -> 28.64701 | J21: ='original data '!U21 -> 28.54624 | L21: M,S | M21: =D21/D21 -> 1 | N21: =E21/D21 -> 1 | O21: =F21/D21 -> 1.0027453 | P21: =G21/D21 -> 1 | Q21: =H21/D21 -> 1.044094 | R21: =I21/D21 -> 0.9976392 | S21: =J21/D21 -> 0.99412986 | U21: =STDEV(D303:D402)/AVERAGE(D303:D402) -> 1.3363171e-15 | V21: =STDEV(E303:E402)/AVERAGE(E303:E402) -> 1.4636778e-15 | W21: =STDEV(F303:F402)/AVERAGE(F303:F402) -> 0.07243102 | X21: =STDEV(G303:G402)/AVERAGE(G303:G402) -> 0.00027550147 | Y21: =STDEV(H303:H402)/AVERAGE(H303:H402) -> 1.9412811e-05 | Z21: =STDEV(I303:I402)/AVERAGE(I303:I402) -> 0.00022131537 | AA21: =STDEV(J303:J402)/AVERAGE(J303:J402) -> 1.4636778e-15 | AC21: =STDEV(M303:M402) -> 0 | AD21: =STDEV(N303:N402) -> 1.2273977e-15 | AE21: =STDEV(O303:O402) -> 0.067400464 | AF21: =STDEV(P303:P402) -> 0.00025153692 | AG21: =STDEV(Q303:Q402) -> 1.7723924e-05 | AH21: =STDEV(R303:R402) -> 0.00020206848 | AI21: =STDEV(S303:S402) -> 1.2273977e-15
A22: Montage | B22: 25 | C22: 1 | D22: ='original data '!D22 -> 28.7148 | E22: ='original data '!F22 -> 28.7148 | F22: ='original data '!I22 -> 30.73727 | G22: ='original data '!L22 -> 28.7148 | H22: ='original data '!O22 -> 28.74417 | I22: ='original data '!R22 -> 28.64203 | J22: ='original data '!U22 -> 28.58701 | L22: M,S | M22: =D22/D22 -> 1 | N22: =E22/D22 -> 1 | O22: =F22/D22 -> 1.070433 | P22: =G22/D22 -> 1 | Q22: =H22/D22 -> 1.0010228 | R22: =I22/D22 -> 0.99746577 | S22: =J22/D22 -> 0.99554968 | U22: =STDEV(D403:D502)/AVERAGE(D403:D502) -> 7.2816376e-16 | V22: =STDEV(E403:E502)/AVERAGE(E403:E502) -> 0.0082440821 | W22: =STDEV(F403:F502)/AVERAGE(F403:F502) -> 0.055564294 | X22: =STDEV(G403:G502)/AVERAGE(G403:G502) -> 0.00082385637 | Y22: =STDEV(H403:H502)/AVERAGE(H403:H502) -> 0.015581453 | Z22: =STDEV(I403:I502)/AVERAGE(I403:I502) -> 0.0086971285 | AA22: =STDEV(J403:J502)/AVERAGE(J403:J502) -> 0.0029982899 | AC22: =STDEV(M403:M502) -> 0 | AD22: =STDEV(N403:N502) -> 0.0078266957 | AE22: =STDEV(O403:O502) -> 0.055391701 | AF22: =STDEV(P403:P502) -> 0.00082367142 | AG22: =STDEV(Q403:Q502) -> 0.014917208 | AH22: =STDEV(R403:R502) -> 0.008211337 | AI22: =STDEV(S403:S502) -> 0.002754833
A23: Montage | B23: 25 | C23: 1 | D23: ='original data '!D23 -> 28.7148 | E23: ='original data '!F23 -> 28.7148 | F23: ='original data '!I23 -> 29.747 | G23: ='original data '!L23 -> 28.7148 | H23: ='original data '!O23 -> 28.74417 | I23: ='original data '!R23 -> 28.64701 | J23: ='original data '!U23 -> 28.5041 | L23: M,S | M23: =D23/D23 -> 1 | N23: =E23/D23 -> 1 | O23: =F23/D23 -> 1.0359466 | P23: =G23/D23 -> 1 | Q23: =H23/D23 -> 1.0010228 | R23: =I23/D23 -> 0.9976392 | S23: =J23/D23 -> 0.99266232 | U23: =STDEV(D503:D602)/AVERAGE(D503:D602) -> 1.1411552e-15 | V23: =STDEV(E503:E602)/AVERAGE(E503:E602) -> 0.002637196 | W23: =STDEV(F503:F602)/AVERAGE(F503:F602) -> 0.034105744 | X23: =STDEV(G503:G602)/AVERAGE(G503:G602) -> 1.1411552e-15 | Y23: =STDEV(H503:H602)/AVERAGE(H503:H602) -> 0.010599931 | Z23: =STDEV(I503:I602)/AVERAGE(I503:I602) -> 0.0049665497 | AA23: =STDEV(J503:J602)/AVERAGE(J503:J602) -> 0.0011436078 | AC23: =STDEV(M503:M602) -> 0 | AD23: =STDEV(N503:N602) -> 0.0025927979 | AE23: =STDEV(O503:O602) -> 0.034974113 | AF23: =STDEV(P503:P602) -> 0 | AG23: =STDEV(Q503:Q602) -> 0.010681827 | AH23: =STDEV(R503:R602) -> 0.0049093326 | AI23: =STDEV(S503:S602) -> 0.0010931894
A24: Montage | B24: 25 | C24: 1 | D24: ='original data '!D24 -> 28.7148 | E24: ='original data '!F24 -> 28.7148 | F24: ='original data '!I24 -> 30.72959 | G24: ='original data '!L24 -> 28.7148 | H24: ='original data '!O24 -> 28.70029 | I24: ='original data '!R24 -> 28.60624 | J24: ='original data '!U24 -> 28.54624 | L24: M,S | M24: =D24/D24 -> 1 | N24: =E24/D24 -> 1 | O24: =F24/D24 -> 1.0701656 | P24: =G24/D24 -> 1 | Q24: =H24/D24 -> 0.99949469 | R24: =I24/D24 -> 0.99621937 | S24: =J24/D24 -> 0.99412986 | U24: =STDEV(D603:D702)/AVERAGE(D603:D702) -> 3.5984454e-16 | V24: =STDEV(E603:E702)/AVERAGE(E603:E702) -> 0.035006607 | W24: =STDEV(F603:F702)/AVERAGE(F603:F702) -> 0.033278023 | X24: =STDEV(G603:G702)/AVERAGE(G603:G702) -> 0.00073797383 | Y24: =STDEV(H603:H702)/AVERAGE(H603:H702) -> 0.037256873 | Z24: =STDEV(I603:I702)/AVERAGE(I603:I702) -> 0.0012067788 | AA24: =STDEV(J603:J702)/AVERAGE(J603:J702) -> 1.3784556e-15 | AC24: =STDEV(M603:M702) -> 0 | AD24: =STDEV(N603:N702) -> 0.03368287 | AE24: =STDEV(O603:O702) -> 0.031159328 | AF24: =STDEV(P603:P702) -> 0.00067546894 | AG24: =STDEV(Q603:Q702) -> 0.034861129 | AH24: =STDEV(R603:R702) -> 0.0011029719 | AI24: =STDEV(S603:S702) -> 0
