Workbook

Sheet Para.
B1: 1 | C1: 2 | D1: 3 | E1: 4 | F1: 5 | G1: Orthogonal Array | N1: run | O1: ε | P1: θ | Q1: η | R1: Рe | S1: Pi | T1: φ | V1: ARV | W1: Sum
A2: the population size factor：ε | B2: 3 | C2: 3.5 | D2: 4 | E2: 4.5 | F2: 5 | G2: 1 | H2: 1 | I2: 1 | J2: 1 | K2: 1 | L2: 1 | N2: 1 | O2: =HLOOKUP(G2,$B$1:$F$7,2) -> 3 | P2: =HLOOKUP(H2,$B$1:$F$7,3) -> 0.01 | Q2: =HLOOKUP(I2,$B$1:$F$7,4) -> 0.01 | R2: =HLOOKUP(J2,$B$1:$F$7,5) -> 1.5 | S2: =HLOOKUP(K2,$B$1:$F$7,6) -> 0.45 | T2: =HLOOKUP(L2,$B$1:$F$7,7) -> 0.7 | V2: =W2/180 -> 0.0037706684 | W2: =Total!H23 -> 0.67872032
A3: the update rate：θ1 | B3: 0.01 | C3: 0.02 | D3: 0.03 | E3: 0.04 | F3: 0.05 | G3: 1 | H3: 2 | I3: 3 | J3: 4 | K3: 5 | L3: 2 | N3: 2 | O3: =HLOOKUP(G3,$B$1:$F$7,2) -> 3 | P3: =HLOOKUP(H3,$B$1:$F$7,3) -> 0.02 | Q3: =HLOOKUP(I3,$B$1:$F$7,4) -> 0.03 | R3: =HLOOKUP(J3,$B$1:$F$7,5) -> 3 | S3: =HLOOKUP(K3,$B$1:$F$7,6) -> 0.65 | T3: =HLOOKUP(L3,$B$1:$F$7,7) -> 0.75 | V3: =W3/180 -> 0.0036123757 | W3: =Total!I23 -> 0.65022762
A4: the update rate：θ2 | B4: 0.01 | C4: 0.02 | D4: 0.03 | E4: 0.04 | F4: 0.05 | G4: 1 | H4: 3 | I4: 5 | J4: 2 | K4: 4 | L4: 3 | N4: 3 | O4: =HLOOKUP(G4,$B$1:$F$7,2) -> 3 | P4: =HLOOKUP(H4,$B$1:$F$7,3) -> 0.03 | Q4: =HLOOKUP(I4,$B$1:$F$7,4) -> 0.05 | R4: =HLOOKUP(J4,$B$1:$F$7,5) -> 2 | S4: =HLOOKUP(K4,$B$1:$F$7,6) -> 0.6 | T4: =HLOOKUP(L4,$B$1:$F$7,7) -> 0.8 | V4: =W4/180 -> 0.0033720723 | W4: =Total!J23 -> 0.60697301
A5: the factor of heuristic information：ηφ | B5: 1.5 | C5: 2 | D5: 2.5 | E5: 3 | F5: 3.5 | G5: 1 | H5: 4 | I5: 2 | J5: 5 | K5: 3 | L5: 4 | N5: 4 | O5: =HLOOKUP(G5,$B$1:$F$7,2) -> 3 | P5: =HLOOKUP(H5,$B$1:$F$7,3) -> 0.04 | Q5: =HLOOKUP(I5,$B$1:$F$7,4) -> 0.02 | R5: =HLOOKUP(J5,$B$1:$F$7,5) -> 3.5 | S5: =HLOOKUP(K5,$B$1:$F$7,6) -> 0.55 | T5: =HLOOKUP(L5,$B$1:$F$7,7) -> 0.85 | V5: =W5/180 -> 0.0032690683 | W5: =Total!K23 -> 0.58843229
A6: the factor of PRPR: ρ | B6: 0.45 | C6: 0.5 | D6: 0.55 | E6: 0.6 | F6: 0.65 | G6: 1 | H6: 5 | I6: 4 | J6: 3 | K6: 2 | L6: 5 | N6: 5 | O6: =HLOOKUP(G6,$B$1:$F$7,2) -> 3 | P6: =HLOOKUP(H6,$B$1:$F$7,3) -> 0.05 | Q6: =HLOOKUP(I6,$B$1:$F$7,4) -> 0.04 | R6: =HLOOKUP(J6,$B$1:$F$7,5) -> 2.5 | S6: =HLOOKUP(K6,$B$1:$F$7,6) -> 0.5 | T6: =HLOOKUP(L6,$B$1:$F$7,7) -> 0.9 | V6: =W6/180 -> 0.0033873181 | W6: =Total!L23 -> 0.60971727
A7: the ratio of runtime in stage 1：σ | B7: 0.7 | C7: 0.75 | D7: 0.8 | E7: 0.85 | F7: 0.9 | G7: 2 | H7: 1 | I7: 5 | J7: 4 | K7: 3 | L7: 5 | N7: 6 | O7: =HLOOKUP(G7,$B$1:$F$7,2) -> 3.5 | P7: =HLOOKUP(H7,$B$1:$F$7,3) -> 0.01 | Q7: =HLOOKUP(I7,$B$1:$F$7,4) -> 0.05 | R7: =HLOOKUP(J7,$B$1:$F$7,5) -> 3 | S7: =HLOOKUP(K7,$B$1:$F$7,6) -> 0.55 | T7: =HLOOKUP(L7,$B$1:$F$7,7) -> 0.9 | V7: =W7/180 -> 0.0031634294 | W7: =Total!M23 -> 0.56941728
G8: 2 | H8: 2 | I8: 2 | J8: 2 | K8: 2 | L8: 1 | N8: 7 | O8: =HLOOKUP(G8,$B$1:$F$7,2) -> 3.5 | P8: =HLOOKUP(H8,$B$1:$F$7,3) -> 0.02 | Q8: =HLOOKUP(I8,$B$1:$F$7,4) -> 0.02 | R8: =HLOOKUP(J8,$B$1:$F$7,5) -> 2 | S8: =HLOOKUP(K8,$B$1:$F$7,6) -> 0.5 | T8: =HLOOKUP(L8,$B$1:$F$7,7) -> 0.7 | V8: =W8/180 -> 0.0032830558 | W8: =Total!N23 -> 0.59095004
G9: 2 | H9: 3 | I9: 4 | J9: 5 | K9: 1 | L9: 2 | N9: 8 | O9: =HLOOKUP(G9,$B$1:$F$7,2) -> 3.5 | P9: =HLOOKUP(H9,$B$1:$F$7,3) -> 0.03 | Q9: =HLOOKUP(I9,$B$1:$F$7,4) -> 0.04 | R9: =HLOOKUP(J9,$B$1:$F$7,5) -> 3.5 | S9: =HLOOKUP(K9,$B$1:$F$7,6) -> 0.45 | T9: =HLOOKUP(L9,$B$1:$F$7,7) -> 0.75 | V9: =W9/180 -> 0.0029902023 | W9: =Total!O23 -> 0.53823642
G10: 2 | H10: 4 | I10: 1 | J10: 3 | K10: 5 | L10: 3 | N10: 9 | O10: =HLOOKUP(G10,$B$1:$F$7,2) -> 3.5 | P10: =HLOOKUP(H10,$B$1:$F$7,3) -> 0.04 | Q10: =HLOOKUP(I10,$B$1:$F$7,4) -> 0.01 | R10: =HLOOKUP(J10,$B$1:$F$7,5) -> 2.5 | S10: =HLOOKUP(K10,$B$1:$F$7,6) -> 0.65 | T10: =HLOOKUP(L10,$B$1:$F$7,7) -> 0.8 | V10: =W10/180 -> 0.0032496968 | W10: =Total!P23 -> 0.58494543
G11: 2 | H11: 5 | I11: 3 | J11: 1 | K11: 4 | L11: 4 | N11: 10 | O11: =HLOOKUP(G11,$B$1:$F$7,2) -> 3.5 | P11: =HLOOKUP(H11,$B$1:$F$7,3) -> 0.05 | Q11: =HLOOKUP(I11,$B$1:$F$7,4) -> 0.03 | R11: =HLOOKUP(J11,$B$1:$F$7,5) -> 1.5 | S11: =HLOOKUP(K11,$B$1:$F$7,6) -> 0.6 | T11: =HLOOKUP(L11,$B$1:$F$7,7) -> 0.85 | V11: =W11/180 -> 0.0029076746 | W11: =Total!Q23 -> 0.52338142
G12: 3 | H12: 1 | I12: 4 | J12: 2 | K12: 5 | L12: 4 | N12: 11 | O12: =HLOOKUP(G12,$B$1:$F$7,2) -> 4 | P12: =HLOOKUP(H12,$B$1:$F$7,3) -> 0.01 | Q12: =HLOOKUP(I12,$B$1:$F$7,4) -> 0.04 | R12: =HLOOKUP(J12,$B$1:$F$7,5) -> 2 | S12: =HLOOKUP(K12,$B$1:$F$7,6) -> 0.65 | T12: =HLOOKUP(L12,$B$1:$F$7,7) -> 0.85 | V12: =W12/180 -> 0.0031385162 | W12: =Total!R23 -> 0.56493292
G13: 3 | H13: 2 | I13: 1 | J13: 5 | K13: 4 | L13: 5 | N13: 12 | O13: =HLOOKUP(G13,$B$1:$F$7,2) -> 4 | P13: =HLOOKUP(H13,$B$1:$F$7,3) -> 0.02 | Q13: =HLOOKUP(I13,$B$1:$F$7,4) -> 0.01 | R13: =HLOOKUP(J13,$B$1:$F$7,5) -> 3.5 | S13: =HLOOKUP(K13,$B$1:$F$7,6) -> 0.6 | T13: =HLOOKUP(L13,$B$1:$F$7,7) -> 0.9 | V13: =W13/180 -> 0.003032841 | W13: =Total!S23 -> 0.54591138
G14: 3 | H14: 3 | I14: 3 | J14: 3 | K14: 3 | L14: 1 | N14: 13 | O14: =HLOOKUP(G14,$B$1:$F$7,2) -> 4 | P14: =HLOOKUP(H14,$B$1:$F$7,3) -> 0.03 | Q14: =HLOOKUP(I14,$B$1:$F$7,4) -> 0.03 | R14: =HLOOKUP(J14,$B$1:$F$7,5) -> 2.5 | S14: =HLOOKUP(K14,$B$1:$F$7,6) -> 0.55 | T14: =HLOOKUP(L14,$B$1:$F$7,7) -> 0.7 | V14: =W14/180 -> 0.0030140716 | W14: =Total!T23 -> 0.54253288
G15: 3 | H15: 4 | I15: 5 | J15: 1 | K15: 2 | L15: 2 | N15: 14 | O15: =HLOOKUP(G15,$B$1:$F$7,2) -> 4 | P15: =HLOOKUP(H15,$B$1:$F$7,3) -> 0.04 | Q15: =HLOOKUP(I15,$B$1:$F$7,4) -> 0.05 | R15: =HLOOKUP(J15,$B$1:$F$7,5) -> 1.5 | S15: =HLOOKUP(K15,$B$1:$F$7,6) -> 0.5 | T15: =HLOOKUP(L15,$B$1:$F$7,7) -> 0.75 | V15: =W15/180 -> 0.0032663884 | W15: =Total!U23 -> 0.58794991
G16: 3 | H16: 5 | I16: 2 | J16: 4 | K16: 1 | L16: 3 | N16: 15 | O16: =HLOOKUP(G16,$B$1:$F$7,2) -> 4 | P16: =HLOOKUP(H16,$B$1:$F$7,3) -> 0.05 | Q16: =HLOOKUP(I16,$B$1:$F$7,4) -> 0.02 | R16: =HLOOKUP(J16,$B$1:$F$7,5) -> 3 | S16: =HLOOKUP(K16,$B$1:$F$7,6) -> 0.45 | T16: =HLOOKUP(L16,$B$1:$F$7,7) -> 0.8 | V16: =W16/180 -> 0.0030775415 | W16: =Total!V23 -> 0.55395746
G17: 4 | H17: 1 | I17: 3 | J17: 5 | K17: 2 | L17: 3 | N17: 16 | O17: =HLOOKUP(G17,$B$1:$F$7,2) -> 4.5 | P17: =HLOOKUP(H17,$B$1:$F$7,3) -> 0.01 | Q17: =HLOOKUP(I17,$B$1:$F$7,4) -> 0.03 | R17: =HLOOKUP(J17,$B$1:$F$7,5) -> 3.5 | S17: =HLOOKUP(K17,$B$1:$F$7,6) -> 0.5 | T17: =HLOOKUP(L17,$B$1:$F$7,7) -> 0.8 | V17: =W17/180 -> 0.0029136211 | W17: =Total!W23 -> 0.52445181
D18: .. | G18: 4 | H18: 2 | I18: 5 | J18: 3 | K18: 1 | L18: 4 | N18: 17 | O18: =HLOOKUP(G18,$B$1:$F$7,2) -> 4.5 | P18: =HLOOKUP(H18,$B$1:$F$7,3) -> 0.02 | Q18: =HLOOKUP(I18,$B$1:$F$7,4) -> 0.05 | R18: =HLOOKUP(J18,$B$1:$F$7,5) -> 2.5 | S18: =HLOOKUP(K18,$B$1:$F$7,6) -> 0.45 | T18: =HLOOKUP(L18,$B$1:$F$7,7) -> 0.85 | V18: =W18/180 -> 0.0027763739 | W18: =Total!X23 -> 0.4997473
G19: 4 | H19: 3 | I19: 2 | J19: 1 | K19: 5 | L19: 5 | N19: 18 | O19: =HLOOKUP(G19,$B$1:$F$7,2) -> 4.5 | P19: =HLOOKUP(H19,$B$1:$F$7,3) -> 0.03 | Q19: =HLOOKUP(I19,$B$1:$F$7,4) -> 0.02 | R19: =HLOOKUP(J19,$B$1:$F$7,5) -> 1.5 | S19: =HLOOKUP(K19,$B$1:$F$7,6) -> 0.65 | T19: =HLOOKUP(L19,$B$1:$F$7,7) -> 0.9 | V19: =W19/180 -> 0.0028006292 | W19: =Total!Y23 -> 0.50411326
G20: 4 | H20: 4 | I20: 4 | J20: 4 | K20: 4 | L20: 1 | N20: 19 | O20: =HLOOKUP(G20,$B$1:$F$7,2) -> 4.5 | P20: =HLOOKUP(H20,$B$1:$F$7,3) -> 0.04 | Q20: =HLOOKUP(I20,$B$1:$F$7,4) -> 0.04 | R20: =HLOOKUP(J20,$B$1:$F$7,5) -> 3 | S20: =HLOOKUP(K20,$B$1:$F$7,6) -> 0.6 | T20: =HLOOKUP(L20,$B$1:$F$7,7) -> 0.7 | V20: =W20/180 -> 0.0034461667 | W20: =Total!Z23 -> 0.62031
G21: 4 | H21: 5 | I21: 1 | J21: 2 | K21: 3 | L21: 2 | N21: 20 | O21: =HLOOKUP(G21,$B$1:$F$7,2) -> 4.5 | P21: =HLOOKUP(H21,$B$1:$F$7,3) -> 0.05 | Q21: =HLOOKUP(I21,$B$1:$F$7,4) -> 0.01 | R21: =HLOOKUP(J21,$B$1:$F$7,5) -> 2 | S21: =HLOOKUP(K21,$B$1:$F$7,6) -> 0.55 | T21: =HLOOKUP(L21,$B$1:$F$7,7) -> 0.75 | V21: =W21/180 -> 0.0034192474 | W21: =Total!AA23 -> 0.61546454
G22: 5 | H22: 1 | I22: 2 | J22: 3 | K22: 4 | L22: 2 | N22: 21 | O22: =HLOOKUP(G22,$B$1:$F$7,2) -> 5 | P22: =HLOOKUP(H22,$B$1:$F$7,3) -> 0.01 | Q22: =HLOOKUP(I22,$B$1:$F$7,4) -> 0.02 | R22: =HLOOKUP(J22,$B$1:$F$7,5) -> 2.5 | S22: =HLOOKUP(K22,$B$1:$F$7,6) -> 0.6 | T22: =HLOOKUP(L22,$B$1:$F$7,7) -> 0.75 | V22: =W22/180 -> 0.0030051381 | W22: =Total!AB23 -> 0.54092485
G23: 5 | H23: 2 | I23: 4 | J23: 1 | K23: 3 | L23: 3 | N23: 22 | O23: =HLOOKUP(G23,$B$1:$F$7,2) -> 5 | P23: =HLOOKUP(H23,$B$1:$F$7,3) -> 0.02 | Q23: =HLOOKUP(I23,$B$1:$F$7,4) -> 0.04 | R23: =HLOOKUP(J23,$B$1:$F$7,5) -> 1.5 | S23: =HLOOKUP(K23,$B$1:$F$7,6) -> 0.55 | T23: =HLOOKUP(L23,$B$1:$F$7,7) -> 0.8 | V23: =W23/180 -> 0.0027181068 | W23: =Total!AC23 -> 0.48925923
G24: 5 | H24: 3 | I24: 1 | J24: 4 | K24: 2 | L24: 4 | N24: 23 | O24: =HLOOKUP(G24,$B$1:$F$7,2) -> 5 | P24: =HLOOKUP(H24,$B$1:$F$7,3) -> 0.03 | Q24: =HLOOKUP(I24,$B$1:$F$7,4) -> 0.01 | R24: =HLOOKUP(J24,$B$1:$F$7,5) -> 3 | S24: =HLOOKUP(K24,$B$1:$F$7,6) -> 0.5 | T24: =HLOOKUP(L24,$B$1:$F$7,7) -> 0.85 | V24: =W24/180 -> 0.0033634543 | W24: =Total!AD23 -> 0.60542178
G25: 5 | H25: 4 | I25: 3 | J25: 2 | K25: 1 | L25: 5 | N25: 24 | O25: =HLOOKUP(G25,$B$1:$F$7,2) -> 5 | P25: =HLOOKUP(H25,$B$1:$F$7,3) -> 0.04 | Q25: =HLOOKUP(I25,$B$1:$F$7,4) -> 0.03 | R25: =HLOOKUP(J25,$B$1:$F$7,5) -> 2 | S25: =HLOOKUP(K25,$B$1:$F$7,6) -> 0.45 | T25: =HLOOKUP(L25,$B$1:$F$7,7) -> 0.9 | V25: =W25/180 -> 0.003143468 | W25: =Total!AE23 -> 0.56582424
G26: 5 | H26: 5 | I26: 5 | J26: 5 | K26: 5 | L26: 1 | N26: 25 | O26: =HLOOKUP(G26,$B$1:$F$7,2) -> 5 | P26: =HLOOKUP(H26,$B$1:$F$7,3) -> 0.05 | Q26: =HLOOKUP(I26,$B$1:$F$7,4) -> 0.05 | R26: =HLOOKUP(J26,$B$1:$F$7,5) -> 3.5 | S26: =HLOOKUP(K26,$B$1:$F$7,6) -> 0.65 | T26: =HLOOKUP(L26,$B$1:$F$7,7) -> 0.7 | V26: =W26/180 -> 0.0036422554 | W26: =Total!AF23 -> 0.65560597
F27: Level | G27: ε | H27: θ1 | I27: θ2 | J27: η | K27: prp | L27: φ
F28: 1 | G28: =AVERAGEIF(G2:G26,1,$V$2:$V$26) -> 0.0034823006 | H28: =AVERAGEIF(H2:H26,1,$V$2:$V$26) -> 0.0031982746 | I28: =AVERAGEIF(I2:I26,1,$V$2:$V$26) -> 0.0033671816 | J28: =AVERAGEIF(J2:J26,1,$V$2:$V$26) -> 0.0030926935 | K28: =AVERAGEIF(K2:K26,1,$V$2:$V$26) -> 0.0031516508 | L28: =AVERAGEIF(L2:L26,1,$V$2:$V$26) -> 0.0034312436
F29: 2 | G29: =AVERAGEIF(G2:G26,2,$V$2:$V$26) -> 0.0031188118 | H29: =AVERAGEIF(H2:H26,2,$V$2:$V$26) -> 0.0030845506 | I29: =AVERAGEIF(I2:I26,2,$V$2:$V$26) -> 0.0030870866 | J29: =AVERAGEIF(J2:J26,2,$V$2:$V$26) -> 0.0032712719 | K29: =AVERAGEIF(K2:K26,2,$V$2:$V$26) -> 0.0032427675 | L29: =AVERAGEIF(L2:L26,2,$V$2:$V$26) -> 0.0032586704
F30: 3 | G30: =AVERAGEIF(G2:G26,3,$V$2:$V$26) -> 0.0031058717 | H30: =AVERAGEIF(H2:H26,3,$V$2:$V$26) -> 0.0031080859 | I30: =AVERAGEIF(I2:I26,3,$V$2:$V$26) -> 0.0031182422 | J30: =AVERAGEIF(J2:J26,3,$V$2:$V$26) -> 0.0030865197 | K30: =AVERAGEIF(K2:K26,3,$V$2:$V$26) -> 0.0031167847 | L30: =AVERAGEIF(L2:L26,3,$V$2:$V$26) -> 0.0030662077
F31: 4 | G31: =AVERAGEIF(G2:G26,4,$V$2:$V$26) -> 0.0030712077 | H31: =AVERAGEIF(H2:H26,4,$V$2:$V$26) -> 0.0032749576 | I31: =AVERAGEIF(I2:I26,4,$V$2:$V$26) -> 0.003136062 | J31: =AVERAGEIF(J2:J26,4,$V$2:$V$26) -> 0.0033325935 | K31: =AVERAGEIF(K2:K26,4,$V$2:$V$26) -> 0.0031527785 | L31: =AVERAGEIF(L2:L26,4,$V$2:$V$26) -> 0.0030910174
F32: 5 | G32: =AVERAGEIF(G2:G26,5,$V$2:$V$26) -> 0.0031744845 | H32: =AVERAGEIF(H2:H26,5,$V$2:$V$26) -> 0.0032868074 | I32: =AVERAGEIF(I2:I26,5,$V$2:$V$26) -> 0.0032441038 | J32: =AVERAGEIF(J2:J26,5,$V$2:$V$26) -> 0.0031695976 | K32: =AVERAGEIF(K2:K26,5,$V$2:$V$26) -> 0.0032886947 | L32: =AVERAGEIF(L2:L26,5,$V$2:$V$26) -> 0.0031055371
G33: =SUM(G28:G32) -> 0.015952676 | H33: =SUM(H28:H32) -> 0.015952676 | I33: =SUM(I28:I32) -> 0.015952676 | J33: =SUM(J28:J32) -> 0.015952676 | K33: =SUM(K28:K32) -> 0.015952676 | L33: =SUM(L28:L32) -> 0.015952676
G34: =C2 -> 3.5 | H34: =$B3+2*($F3-$B3)/4 -> 0.03 | I34: =$B4+2*($F4-$B4)/4 -> 0.03 | J34: =$B5+2*($F5-$B5)/4 -> 2.5 | K34: =$B6+2*($F6-$B6)/4 -> 0.55 | L34: =E7 -> 0.85
E36: Range(Delta) | G36: =(MAX(G28:G32)-MIN(G28:G32)) -> 0.00041109288 | H36: =(MAX(H28:H32)-MIN(H28:H32)) -> 0.00020225677 | I36: =(MAX(I28:I32)-MIN(I28:I32)) -> 0.00028009504 | J36: =(MAX(J28:J32)-MIN(J28:J32)) -> 0.00024607381 | K36: =(MAX(K28:K32)-MIN(K28:K32)) -> 0.00017190997 | L36: =(MAX(L28:L32)-MIN(L28:L32)) -> 0.00036503585

Sheet Total
A1: ty | B1: sz | C1: ra | E1: Min | F1: Aver | H1: 1 | I1: 2 | J1: 3 | K1: 4 | L1: 5 | M1: 6 | N1: 7 | O1: 8 | P1: 9 | Q1: 10 | R1: 11 | S1: 12 | T1: 13 | U1: 14 | V1: 15 | W1: 16 | X1: 17 | Y1: 18 | Z1: 19 | AA1: 20 | AB1: 21 | AC1: 22 | AD1: 23 | AE1: 24 | AF1: 25
A2: Montage | B2: 25 | C2: 1 | E2: =MIN('1:25'!L2:U2) -> 28.504 | F2: =AVERAGE('1:25'!W2) -> 28.536016 | H2: =INDIRECT(COLUMN(A1)&"!AM"&ROW(A1)+1) -> 0.010103845 | I2: =INDIRECT(COLUMN(B1)&"!AM"&ROW(B1)+1) -> 0.016559079 | J2: =INDIRECT(COLUMN(C1)&"!AM"&ROW(C1)+1) -> 0.0089811956 | K2: =INDIRECT(COLUMN(D1)&"!AM"&ROW(D1)+1) -> 0.0073323042 | L2: =INDIRECT(COLUMN(E1)&"!AM"&ROW(E1)+1) -> 0.010314342 | M2: =INDIRECT(COLUMN(F1)&"!AM"&ROW(F1)+1) -> 0.01192815 | N2: =INDIRECT(COLUMN(G1)&"!AM"&ROW(G1)+1) -> 0.014699691 | O2: =INDIRECT(COLUMN(H1)&"!AM"&ROW(H1)+1) -> 0.013401628 | ... AF2: =INDIRECT(COLUMN(Y1)&"!AM"&ROW(Y1)+1) -> 0.014840022
A3: Montage | B3: 50 | C3: 1 | E3: =MIN('1:25'!L3:U3) -> 52.927 | F3: =AVERAGE('1:25'!W3) -> 53.035568 | H3: =INDIRECT(COLUMN(A2)&"!AM"&ROW(A2)+1) -> 0.021935874 | I3: =INDIRECT(COLUMN(B2)&"!AM"&ROW(B2)+1) -> 0.025846921 | J3: =INDIRECT(COLUMN(C2)&"!AM"&ROW(C2)+1) -> 0.025525724 | K3: =INDIRECT(COLUMN(D2)&"!AM"&ROW(D2)+1) -> 0.02407089 | L3: =INDIRECT(COLUMN(E2)&"!AM"&ROW(E2)+1) -> 0.03143953 | M3: =INDIRECT(COLUMN(F2)&"!AM"&ROW(F2)+1) -> 0.025204527 | N3: =INDIRECT(COLUMN(G2)&"!AM"&ROW(G2)+1) -> 0.019895328 | O3: =INDIRECT(COLUMN(H2)&"!AM"&ROW(H2)+1) -> 0.024203148 | ... AF3: =INDIRECT(COLUMN(Y2)&"!AM"&ROW(Y2)+1) -> 0.022238177
A4: Montage | B4: 100 | C4: 1 | E4: =MIN('1:25'!L4:U4) -> 102.802 | F4: =AVERAGE('1:25'!W4) -> 103.25301 | H4: =INDIRECT(COLUMN(A3)&"!AM"&ROW(A3)+1) -> 0.048267543 | I4: =INDIRECT(COLUMN(B3)&"!AM"&ROW(B3)+1) -> 0.044678119 | J4: =INDIRECT(COLUMN(C3)&"!AM"&ROW(C3)+1) -> 0.053053443 | K4: =INDIRECT(COLUMN(D3)&"!AM"&ROW(D3)+1) -> 0.044036108 | L4: =INDIRECT(COLUMN(E3)&"!AM"&ROW(E3)+1) -> 0.046730608 | M4: =INDIRECT(COLUMN(F3)&"!AM"&ROW(F3)+1) -> 0.048578821 | N4: =INDIRECT(COLUMN(G3)&"!AM"&ROW(G3)+1) -> 0.042392171 | O4: =INDIRECT(COLUMN(H3)&"!AM"&ROW(H3)+1) -> 0.040543958 | ... AF4: =INDIRECT(COLUMN(Y3)&"!AM"&ROW(Y3)+1) -> 0.048763643
A5: CyberShake | B5: 30 | C5: 1 | E5: =MIN('1:25'!L5:U5) -> 156.127 | F5: =AVERAGE('1:25'!W5) -> 156.127 | H5: =INDIRECT(COLUMN(A4)&"!AM"&ROW(A4)+1) -> 0 | I5: =INDIRECT(COLUMN(B4)&"!AM"&ROW(B4)+1) -> 0 | J5: =INDIRECT(COLUMN(C4)&"!AM"&ROW(C4)+1) -> 0 | K5: =INDIRECT(COLUMN(D4)&"!AM"&ROW(D4)+1) -> 0 | L5: =INDIRECT(COLUMN(E4)&"!AM"&ROW(E4)+1) -> 0 | M5: =INDIRECT(COLUMN(F4)&"!AM"&ROW(F4)+1) -> 0 | N5: =INDIRECT(COLUMN(G4)&"!AM"&ROW(G4)+1) -> 0 | O5: =INDIRECT(COLUMN(H4)&"!AM"&ROW(H4)+1) -> 0 | ... AF5: =INDIRECT(COLUMN(Y4)&"!AM"&ROW(Y4)+1) -> 0
A6: CyberShake | B6: 50 | C6: 1 | E6: =MIN('1:25'!L6:U6) -> 179.673 | F6: =AVERAGE('1:25'!W6) -> 180.38015 | H6: =INDIRECT(COLUMN(A5)&"!AM"&ROW(A5)+1) -> 0.010324311 | I6: =INDIRECT(COLUMN(B5)&"!AM"&ROW(B5)+1) -> 0.075626277 | J6: =INDIRECT(COLUMN(C5)&"!AM"&ROW(C5)+1) -> 0.04075181 | K6: =INDIRECT(COLUMN(D5)&"!AM"&ROW(D5)+1) -> 0.071919543 | L6: =INDIRECT(COLUMN(E5)&"!AM"&ROW(E5)+1) -> 0.078698525 | M6: =INDIRECT(COLUMN(F5)&"!AM"&ROW(F5)+1) -> 0.048755239 | N6: =INDIRECT(COLUMN(G5)&"!AM"&ROW(G5)+1) -> 0.043273057 | O6: =INDIRECT(COLUMN(H5)&"!AM"&ROW(H5)+1) -> 0.02446667 | ... AF6: =INDIRECT(COLUMN(Y5)&"!AM"&ROW(Y5)+1) -> 0.07761322
A7: CyberShake | B7: 100 | C7: 1 | E7: =MIN('1:25'!L7:U7) -> 238.867 | F7: =AVERAGE('1:25'!W7) -> 239.35028 | H7: =INDIRECT(COLUMN(A6)&"!AM"&ROW(A6)+1) -> 0.02258579 | I7: =INDIRECT(COLUMN(B6)&"!AM"&ROW(B6)+1) -> 0.023707754 | J7: =INDIRECT(COLUMN(C6)&"!AM"&ROW(C6)+1) -> 0.023222128 | K7: =INDIRECT(COLUMN(D6)&"!AM"&ROW(D6)+1) -> 0.016586636 | L7: =INDIRECT(COLUMN(E6)&"!AM"&ROW(E6)+1) -> 0.027232728 | M7: =INDIRECT(COLUMN(F6)&"!AM"&ROW(F6)+1) -> 0.019860424 | N7: =INDIRECT(COLUMN(G6)&"!AM"&ROW(G6)+1) -> 0.018956156 | O7: =INDIRECT(COLUMN(H6)&"!AM"&ROW(H6)+1) -> 0.030284635 | ... AF7: =INDIRECT(COLUMN(Y6)&"!AM"&ROW(Y6)+1) -> 0.029685976
A8: Epigenomics | B8: 24 | C8: 1 | E8: =MIN('1:25'!L8:U8) -> 2320.908 | F8: =AVERAGE('1:25'!W8) -> 2320.9667 | H8: =INDIRECT(COLUMN(A7)&"!AM"&ROW(A7)+1) -> 0 | I8: =INDIRECT(COLUMN(B7)&"!AM"&ROW(B7)+1) -> 0.0063251107 | J8: =INDIRECT(COLUMN(C7)&"!AM"&ROW(C7)+1) -> 0 | K8: =INDIRECT(COLUMN(D7)&"!AM"&ROW(D7)+1) -> 0 | L8: =INDIRECT(COLUMN(E7)&"!AM"&ROW(E7)+1) -> 0 | M8: =INDIRECT(COLUMN(F7)&"!AM"&ROW(F7)+1) -> 0 | N8: =INDIRECT(COLUMN(G7)&"!AM"&ROW(G7)+1) -> 0 | O8: =INDIRECT(COLUMN(H7)&"!AM"&ROW(H7)+1) -> 0 | ... AF8: =INDIRECT(COLUMN(Y7)&"!AM"&ROW(Y7)+1) -> 0
A9: Epigenomics | B9: 47 | C9: 1 | E9: =MIN('1:25'!L9:U9) -> 4313.61 | F9: =AVERAGE('1:25'!W9) -> 4314.0002 | H9: =INDIRECT(COLUMN(A8)&"!AM"&ROW(A8)+1) -> 0 | I9: =INDIRECT(COLUMN(B8)&"!AM"&ROW(B8)+1) -> 0.0022616787 | J9: =INDIRECT(COLUMN(C8)&"!AM"&ROW(C8)+1) -> 0.0011308394 | K9: =INDIRECT(COLUMN(D8)&"!AM"&ROW(D8)+1) -> 0 | L9: =INDIRECT(COLUMN(E8)&"!AM"&ROW(E8)+1) -> 0.0033925181 | M9: =INDIRECT(COLUMN(F8)&"!AM"&ROW(F8)+1) -> 0.0033925181 | N9: =INDIRECT(COLUMN(G8)&"!AM"&ROW(G8)+1) -> 0 | O9: =INDIRECT(COLUMN(H8)&"!AM"&ROW(H8)+1) -> 0.0011308394 | ... AF9: =INDIRECT(COLUMN(Y8)&"!AM"&ROW(Y8)+1) -> 0.0022616787
A10: Epigenomics | B10: 100 | C10: 1 | E10: =MIN('1:25'!L10:U10) -> 35210.383 | F10: =AVERAGE('1:25'!W10) -> 35256.139 | H10: =INDIRECT(COLUMN(A9)&"!AM"&ROW(A9)+1) -> 0.018925469 | I10: =INDIRECT(COLUMN(B9)&"!AM"&ROW(B9)+1) -> 0.011232028 | J10: =INDIRECT(COLUMN(C9)&"!AM"&ROW(C9)+1) -> 0.012600232 | K10: =INDIRECT(COLUMN(D9)&"!AM"&ROW(D9)+1) -> 0.011537449 | L10: =INDIRECT(COLUMN(E9)&"!AM"&ROW(E9)+1) -> 0.01725954 | M10: =INDIRECT(COLUMN(F9)&"!AM"&ROW(F9)+1) -> 0.012751949 | N10: =INDIRECT(COLUMN(G9)&"!AM"&ROW(G9)+1) -> 0.014917958 | O10: =INDIRECT(COLUMN(H9)&"!AM"&ROW(H9)+1) -> 0.012145821 | ... AF10: =INDIRECT(COLUMN(Y9)&"!AM"&ROW(Y9)+1) -> 0.010222439
A11: Ligo | B11: 30 | C11: 1 | E11: =MIN('1:25'!L11:U11) -> 655.465 | F11: =AVERAGE('1:25'!W11) -> 657.77815 | H11: =INDIRECT(COLUMN(A10)&"!AM"&ROW(A10)+1) -> 0.030099243 | I11: =INDIRECT(COLUMN(B10)&"!AM"&ROW(B10)+1) -> 0.039553599 | J11: =INDIRECT(COLUMN(C10)&"!AM"&ROW(C10)+1) -> 0.038950974 | K11: =INDIRECT(COLUMN(D10)&"!AM"&ROW(D10)+1) -> 0.036779996 | L11: =INDIRECT(COLUMN(E10)&"!AM"&ROW(E10)+1) -> 0.040273699 | M11: =INDIRECT(COLUMN(F10)&"!AM"&ROW(F10)+1) -> 0.036853226 | N11: =INDIRECT(COLUMN(G10)&"!AM"&ROW(G10)+1) -> 0.030050422 | O11: =INDIRECT(COLUMN(H10)&"!AM"&ROW(H10)+1) -> 0.035539655 | ... AF11: =INDIRECT(COLUMN(Y10)&"!AM"&ROW(Y10)+1) -> 0.045761406
A12: Ligo | B12: 50 | C12: 1 | E12: =MIN('1:25'!L12:U12) -> 990.096 | F12: =AVERAGE('1:25'!W12) -> 994.43757 | H12: =INDIRECT(COLUMN(A11)&"!AM"&ROW(A11)+1) -> 0.057851966 | I12: =INDIRECT(COLUMN(B11)&"!AM"&ROW(B11)+1) -> 0.043342262 | J12: =INDIRECT(COLUMN(C11)&"!AM"&ROW(C11)+1) -> 0.050662764 | K12: =INDIRECT(COLUMN(D11)&"!AM"&ROW(D11)+1) -> 0.043894733 | L12: =INDIRECT(COLUMN(E11)&"!AM"&ROW(E11)+1) -> 0.056415742 | M12: =INDIRECT(COLUMN(F11)&"!AM"&ROW(F11)+1) -> 0.046408631 | N12: =INDIRECT(COLUMN(G11)&"!AM"&ROW(G11)+1) -> 0.030365742 | O12: =INDIRECT(COLUMN(H11)&"!AM"&ROW(H11)+1) -> 0.044311865 | ... AF12: =INDIRECT(COLUMN(Y11)&"!AM"&ROW(Y11)+1) -> 0.05265651
A13: Ligo | B13: 100 | C13: 1 | E13: =MIN('1:25'!L13:U13) -> 1753.79 | F13: =AVERAGE('1:25'!W13) -> 1757.2709 | H13: =INDIRECT(COLUMN(A12)&"!AM"&ROW(A12)+1) -> 0.040416469 | I13: =INDIRECT(COLUMN(B12)&"!AM"&ROW(B12)+1) -> 0.014019352 | J13: =INDIRECT(COLUMN(C12)&"!AM"&ROW(C12)+1) -> 0.015353035 | K13: =INDIRECT(COLUMN(D12)&"!AM"&ROW(D12)+1) -> 0.015345623 | L13: =INDIRECT(COLUMN(E12)&"!AM"&ROW(E12)+1) -> 0.016630269 | M13: =INDIRECT(COLUMN(F12)&"!AM"&ROW(F12)+1) -> 0.016461492 | N13: =INDIRECT(COLUMN(G12)&"!AM"&ROW(G12)+1) -> 0.026365756 | O13: =INDIRECT(COLUMN(H12)&"!AM"&ROW(H12)+1) -> 0.014902582 | ... AF13: =INDIRECT(COLUMN(Y12)&"!AM"&ROW(Y12)+1) -> 0.011653619
... A19: fft | B19: 224 | C19: 1 | E19: =MIN('1:25'!L19:U19) -> 71.908 | F19: =AVERAGE('1:25'!W19) -> 71.948252 | H19: =INDIRECT(COLUMN(A18)&"!AM"&ROW(A18)+1) -> 0.019469322 | I19: =INDIRECT(COLUMN(B18)&"!AM"&ROW(B18)+1) -> 0.0056043834 | J19: =INDIRECT(COLUMN(C18)&"!AM"&ROW(C18)+1) -> 0.0059937698 | K19: =INDIRECT(COLUMN(D18)&"!AM"&ROW(D18)+1) -> 0.003421038 | L19: =INDIRECT(COLUMN(E18)&"!AM"&ROW(E18)+1) -> 0.0040746509 | M19: =INDIRECT(COLUMN(F18)&"!AM"&ROW(F18)+1) -> 0.004519664 | N19: =INDIRECT(COLUMN(G18)&"!AM"&ROW(G18)+1) -> 0.0067864494 | O19: =INDIRECT(COLUMN(H18)&"!AM"&ROW(H18)+1) -> 0.0059103299 | ... AF19: =INDIRECT(COLUMN(Y18)&"!AM"&ROW(Y18)+1) -> 0.0018217723
A23: Montage | B23: 25 | C23: 1 | E23: 28.7148 | F23: =F2/E23 -> 0.9937738 | G23: SUM | H23: =SUM(H2:H19) -> 0.67872032 | I23: =SUM(I2:I19) -> 0.65022762 | J23: =SUM(J2:J19) -> 0.60697301 | K23: =SUM(K2:K19) -> 0.58843229 | L23: =SUM(L2:L19) -> 0.60971727 | M23: =SUM(M2:M19) -> 0.56941728 | N23: =SUM(N2:N19) -> 0.59095004 | O23: =SUM(O2:O19) -> 0.53823642 | ... AF23: =SUM(AF2:AF19) -> 0.65560597
A24: Montage | B24: 50 | C24: 1 | E24: 58.25543 | F24: =F3/E24 -> 0.91039699
A25: Montage | B25: 100 | C25: 1 | E25: 105.21427 | F25: =F4/E25 -> 0.98135935 | H25: ='1'!$W2 -> 28.5328 | I25: ='2'!$W2 -> 28.5512 | J25: ='3'!$W2 -> 28.5296 | K25: ='4'!$W2 -> 28.5249 | L25: ='5'!$W2 -> 28.5334 | M25: ='6'!$W2 -> 28.538 | N25: ='7'!$W2 -> 28.5459 | O25: ='8'!$W2 -> 28.5422 | P25: ='9'!$W2 -> 28.5459 | Q25: ='10'!$W2 -> 28.5436 | R25: ='11'!$W2 -> 28.525 | S25: ='12'!$W2 -> 28.5292 | T25: ='13'!$W2 -> 28.5422 | U25: ='14'!$W2 -> 28.551 | V25: ='15'!$W2 -> 28.5338 | W25: ='16'!$W2 -> 28.5334 | X25: ='17'!$W2 -> 28.5417 | Y25: ='18'!$W2 -> 28.5376 | Z25: ='19'!$W2 -> 28.5478 | AA25: ='20'!$W2 -> 28.5166 | AB25: ='21'!$W2 -> 28.525 | AC25: ='22'!$W2 -> 28.5375 | AD25: ='23'!$W2 -> 28.5292 | AE25: ='24'!$W2 -> 28.5166 | AF25: ='25'!$W2 -> 28.5463
A26: CyberShake | B26: 30 | C26: 1 | E26: 171.00667 | F26: =F5/E26 -> 0.91298778
A27: CyberShake | B27: 50 | C27: 1 | E27: 196.14333 | F27: =F6/E27 -> 0.91963437
A28: CyberShake | B28: 100 | C28: 1 | E28: 250.31558 | F28: =F7/E28 -> 0.95619411
A29: Epigenomics | B29: 24 | C29: 1 | E29: 2540.1985 | F29: =F8/E29 -> 0.91369502
A30: Epigenomics | B30: 47 | C30: 1 | E30: 4346.2297 | F30: =F9/E30 -> 0.9925845
A31: Epigenomics | B31: 100 | C31: 1 | E31: 35669.695 | F31: =F10/E31 -> 0.98840597
A32: Ligo | B32: 30 | C32: 1 | E32: 699.02291 | F32: =F11/E32 -> 0.94099656
A33: Ligo | B33: 50 | C33: 1 | E33: 1027.0157 | F33: =F12/E33 -> 0.9682788
A34: Ligo | B34: 100 | C34: 1 | E34: 1774.48 | F34: =F13/E34 -> 0.99030189
A35: gaussian | B35: 9 | C35: 1 | E35: 8.54243 | F35: =F14/E35 -> 0.99994966
A36: gaussian | B36: 209 | C36: 1 | E36: 80.12583 | F36: =F15/E36 -> 0.95568428
A37: gaussian | B37: 324 | C37: 1 | E37: 122.97587 | F37: =F16/E37 -> 0.96806068
... A40: fft | B40: 224 | C40: 1 | E40: 72.35577 | F40: =F19/E40 -> 0.99436786
F41: =AVERAGE(F23:F40) -> 0.96160812

Sheet 1
A1: Montage | B1: 25 | C1: 1 | D1: 28.582 | E1: 5.292 | F1: 218 | H1: ty | I1: sz | J1: ra | L1: 1 | M1: 2 | N1: 3 | O1: 4 | P1: 5 | Q1: 6 | R1: 7 | S1: 8 | T1: 9 | U1: 10 | W1: average | Y1: Min | AM1: sum
A2: Montage | B2: 25 | C2: 1 | D2: 28.504 | E2: 5.293 | F2: 273 | H2: Montage | I2: 25 | J2: 1 | L2: =INDIRECT("D"&1+(ROW(D1)-1)*10+COLUMN(A1)-1) -> 28.582 | M2: =INDIRECT("D"&1+(ROW(E1)-1)*10+COLUMN(B1)-1) -> 28.504 | N2: =INDIRECT("D"&1+(ROW(F1)-1)*10+COLUMN(C1)-1) -> 28.546 | O2: =INDIRECT("D"&1+(ROW(G1)-1)*10+COLUMN(D1)-1) -> 28.504 | P2: =INDIRECT("D"&1+(ROW(H1)-1)*10+COLUMN(E1)-1) -> 28.504 | Q2: =INDIRECT("D"&1+(ROW(I1)-1)*10+COLUMN(F1)-1) -> 28.504 | R2: =INDIRECT("D"&1+(ROW(J1)-1)*10+COLUMN(G1)-1) -> 28.546 | S2: =INDIRECT("D"&1+(ROW(K1)-1)*10+COLUMN(H1)-1) -> 28.546 | ... U2: =INDIRECT("D"&1+(ROW(M1)-1)*10+COLUMN(J1)-1) -> 28.546 | W2: =AVERAGE(L2:U2) -> 28.5328 | Y2: =Total!E2 -> 28.504 | AB2: =(L2-$Y2)/$Y2 -> 0.002736458 | AC2: =(M2-$Y2)/$Y2 -> 0 | AD2: =(N2-$Y2)/$Y2 -> 0.0014734774 | AE2: =(O2-$Y2)/$Y2 -> 0 | AF2: =(P2-$Y2)/$Y2 -> 0 | AG2: =(Q2-$Y2)/$Y2 -> 0 | AH2: =(R2-$Y2)/$Y2 -> 0.0014734774 | AI2: =(S2-$Y2)/$Y2 -> 0.0014734774 | ... AK2: =(U2-$Y2)/$Y2 -> 0.0014734774 | AM2: =SUM(AB2:AK2) -> 0.010103845
A3: Montage | B3: 25 | C3: 1 | D3: 28.546 | E3: 5.279 | F3: 236 | H3: Montage | I3: 50 | J3: 1 | L3: =INDIRECT("D"&1+(ROW(D2)-1)*10+COLUMN(A2)-1) -> 53.077 | M3: =INDIRECT("D"&1+(ROW(E2)-1)*10+COLUMN(B2)-1) -> 53.127 | N3: =INDIRECT("D"&1+(ROW(F2)-1)*10+COLUMN(C2)-1) -> 52.927 | O3: =INDIRECT("D"&1+(ROW(G2)-1)*10+COLUMN(D2)-1) -> 53.048 | P3: =INDIRECT("D"&1+(ROW(H2)-1)*10+COLUMN(E2)-1) -> 53.067 | Q3: =INDIRECT("D"&1+(ROW(I2)-1)*10+COLUMN(F2)-1) -> 53.077 | R3: =INDIRECT("D"&1+(ROW(J2)-1)*10+COLUMN(G2)-1) -> 53.077 | S3: =INDIRECT("D"&1+(ROW(K2)-1)*10+COLUMN(H2)-1) -> 53.037 | ... U3: =INDIRECT("D"&1+(ROW(M2)-1)*10+COLUMN(J2)-1) -> 52.927 | W3: =AVERAGE(L3:U3) -> 53.0431 | Y3: =Total!E3 -> 52.927 | AB3: =(L3-$Y3)/$Y3 -> 0.0028340922 | AC3: =(M3-$Y3)/$Y3 -> 0.0037787897 | AD3: =(N3-$Y3)/$Y3 -> 0 | AE3: =(O3-$Y3)/$Y3 -> 0.0022861677 | AF3: =(P3-$Y3)/$Y3 -> 0.0026451528 | AG3: =(Q3-$Y3)/$Y3 -> 0.0028340922 | AH3: =(R3-$Y3)/$Y3 -> 0.0028340922 | AI3: =(S3-$Y3)/$Y3 -> 0.0020783343 | ... AK3: =(U3-$Y3)/$Y3 -> 0 | AM3: =SUM(AB3:AK3) -> 0.021935874
A4: Montage | B4: 25 | C4: 1 | D4: 28.504 | E4: 5.279 | F4: 273 | H4: Montage | I4: 100 | J4: 1 | L4: =INDIRECT("D"&1+(ROW(D3)-1)*10+COLUMN(A3)-1) -> 103.314 | M4: =INDIRECT("D"&1+(ROW(E3)-1)*10+COLUMN(B3)-1) -> 103.259 | N4: =INDIRECT("D"&1+(ROW(F3)-1)*10+COLUMN(C3)-1) -> 103.322 | O4: =INDIRECT("D"&1+(ROW(G3)-1)*10+COLUMN(D3)-1) -> 103.422 | P4: =INDIRECT("D"&1+(ROW(H3)-1)*10+COLUMN(E3)-1) -> 103.324 | Q4: =INDIRECT("D"&1+(ROW(I3)-1)*10+COLUMN(F3)-1) -> 103.26 | R4: =INDIRECT("D"&1+(ROW(J3)-1)*10+COLUMN(G3)-1) -> 103.203 | S4: =INDIRECT("D"&1+(ROW(K3)-1)*10+COLUMN(H3)-1) -> 103.282 | ... U4: =INDIRECT("D"&1+(ROW(M3)-1)*10+COLUMN(J3)-1) -> 103.325 | W4: =AVERAGE(L4:U4) -> 103.2982 | Y4: =Total!E4 -> 102.802 | AB4: =(L4-$Y4)/$Y4 -> 0.0049804479 | AC4: =(M4-$Y4)/$Y4 -> 0.0044454388 | AD4: =(N4-$Y4)/$Y4 -> 0.0050582673 | AE4: =(O4-$Y4)/$Y4 -> 0.0060310111 | AF4: =(P4-$Y4)/$Y4 -> 0.0050777222 | AG4: =(Q4-$Y4)/$Y4 -> 0.0044551662 | AH4: =(R4-$Y4)/$Y4 -> 0.0039007023 | AI4: =(S4-$Y4)/$Y4 -> 0.0046691699 | ... AK4: =(U4-$Y4)/$Y4 -> 0.0050874497 | AM4: =SUM(AB4:AK4) -> 0.048267543
A5: Montage | B5: 25 | C5: 1 | D5: 28.504 | E5: 5.278 | F5: 365 | H5: CyberShake | I5: 30 | J5: 1 | L5: =INDIRECT("D"&1+(ROW(D4)-1)*10+COLUMN(A4)-1) -> 156.127 | M5: =INDIRECT("D"&1+(ROW(E4)-1)*10+COLUMN(B4)-1) -> 156.127 | N5: =INDIRECT("D"&1+(ROW(F4)-1)*10+COLUMN(C4)-1) -> 156.127 | O5: =INDIRECT("D"&1+(ROW(G4)-1)*10+COLUMN(D4)-1) -> 156.127 | P5: =INDIRECT("D"&1+(ROW(H4)-1)*10+COLUMN(E4)-1) -> 156.127 | Q5: =INDIRECT("D"&1+(ROW(I4)-1)*10+COLUMN(F4)-1) -> 156.127 | R5: =INDIRECT("D"&1+(ROW(J4)-1)*10+COLUMN(G4)-1) -> 156.127 | S5: =INDIRECT("D"&1+(ROW(K4)-1)*10+COLUMN(H4)-1) -> 156.127 | ... U5: =INDIRECT("D"&1+(ROW(M4)-1)*10+COLUMN(J4)-1) -> 156.127 | W5: =AVERAGE(L5:U5) -> 156.127 | Y5: =Total!E5 -> 156.127 | AB5: =(L5-$Y5)/$Y5 -> 0 | AC5: =(M5-$Y5)/$Y5 -> 0 | AD5: =(N5-$Y5)/$Y5 -> 0 | AE5: =(O5-$Y5)/$Y5 -> 0 | AF5: =(P5-$Y5)/$Y5 -> 0 | AG5: =(Q5-$Y5)/$Y5 -> 0 | AH5: =(R5-$Y5)/$Y5 -> 0 | AI5: =(S5-$Y5)/$Y5 -> 0 | ... AK5: =(U5-$Y5)/$Y5 -> 0 | AM5: =SUM(AB5:AK5) -> 0
A6: Montage | B6: 25 | C6: 1 | D6: 28.504 | E6: 5.297 | F6: 272 | H6: CyberShake | I6: 50 | J6: 1 | L6: =INDIRECT("D"&1+(ROW(D5)-1)*10+COLUMN(A5)-1) -> 179.938 | M6: =INDIRECT("D"&1+(ROW(E5)-1)*10+COLUMN(B5)-1) -> 179.673 | N6: =INDIRECT("D"&1+(ROW(F5)-1)*10+COLUMN(C5)-1) -> 179.938 | O6: =INDIRECT("D"&1+(ROW(G5)-1)*10+COLUMN(D5)-1) -> 179.938 | P6: =INDIRECT("D"&1+(ROW(H5)-1)*10+COLUMN(E5)-1) -> 179.938 | Q6: =INDIRECT("D"&1+(ROW(I5)-1)*10+COLUMN(F5)-1) -> 179.938 | R6: =INDIRECT("D"&1+(ROW(J5)-1)*10+COLUMN(G5)-1) -> 179.938 | S6: =INDIRECT("D"&1+(ROW(K5)-1)*10+COLUMN(H5)-1) -> 179.938 | ... U6: =INDIRECT("D"&1+(ROW(M5)-1)*10+COLUMN(J5)-1) -> 179.673 | W6: =AVERAGE(L6:U6) -> 179.8585 | Y6: =Total!E6 -> 179.673 | AB6: =(L6-$Y6)/$Y6 -> 0.0014749016 | AC6: =(M6-$Y6)/$Y6 -> 0 | AD6: =(N6-$Y6)/$Y6 -> 0.0014749016 | AE6: =(O6-$Y6)/$Y6 -> 0.0014749016 | AF6: =(P6-$Y6)/$Y6 -> 0.0014749016 | AG6: =(Q6-$Y6)/$Y6 -> 0.0014749016 | AH6: =(R6-$Y6)/$Y6 -> 0.0014749016 | AI6: =(S6-$Y6)/$Y6 -> 0.0014749016 | ... AK6: =(U6-$Y6)/$Y6 -> 0 | AM6: =SUM(AB6:AK6) -> 0.010324311
A7: Montage | B7: 25 | C7: 1 | D7: 28.546 | E7: 5.278 | F7: 260 | H7: CyberShake | I7: 100 | J7: 1 | L7: =INDIRECT("D"&1+(ROW(D6)-1)*10+COLUMN(A6)-1) -> 239.183 | M7: =INDIRECT("D"&1+(ROW(E6)-1)*10+COLUMN(B6)-1) -> 239.145 | N7: =INDIRECT("D"&1+(ROW(F6)-1)*10+COLUMN(C6)-1) -> 239.417 | O7: =INDIRECT("D"&1+(ROW(G6)-1)*10+COLUMN(D6)-1) -> 239.62 | P7: =INDIRECT("D"&1+(ROW(H6)-1)*10+COLUMN(E6)-1) -> 239.316 | Q7: =INDIRECT("D"&1+(ROW(I6)-1)*10+COLUMN(F6)-1) -> 238.9 | R7: =INDIRECT("D"&1+(ROW(J6)-1)*10+COLUMN(G6)-1) -> 239.375 | S7: =INDIRECT("D"&1+(ROW(K6)-1)*10+COLUMN(H6)-1) -> 239.559 | ... U7: =INDIRECT("D"&1+(ROW(M6)-1)*10+COLUMN(J6)-1) -> 240.41 | W7: =AVERAGE(L7:U7) -> 239.4065 | Y7: =Total!E7 -> 238.867 | AB7: =(L7-$Y7)/$Y7 -> 0.0013229119 | AC7: =(M7-$Y7)/$Y7 -> 0.0011638276 | AD7: =(N7-$Y7)/$Y7 -> 0.0023025366 | AE7: =(O7-$Y7)/$Y7 -> 0.0031523819 | AF7: =(P7-$Y7)/$Y7 -> 0.0018797071 | AG7: =(Q7-$Y7)/$Y7 -> 0.00013815219 | AH7: =(R7-$Y7)/$Y7 -> 0.0021267065 | AI7: =(S7-$Y7)/$Y7 -> 0.0028970096 | ... AK7: =(U7-$Y7)/$Y7 -> 0.0064596617 | AM7: =SUM(AB7:AK7) -> 0.02258579
A8: Montage | B8: 25 | C8: 1 | D8: 28.546 | E8: 5.279 | F8: 243 | H8: Epigenomics | I8: 24 | J8: 1 | L8: =INDIRECT("D"&1+(ROW(D7)-1)*10+COLUMN(A7)-1) -> 2320.908 | M8: =INDIRECT("D"&1+(ROW(E7)-1)*10+COLUMN(B7)-1) -> 2320.908 | N8: =INDIRECT("D"&1+(ROW(F7)-1)*10+COLUMN(C7)-1) -> 2320.908 | O8: =INDIRECT("D"&1+(ROW(G7)-1)*10+COLUMN(D7)-1) -> 2320.908 | P8: =INDIRECT("D"&1+(ROW(H7)-1)*10+COLUMN(E7)-1) -> 2320.908 | Q8: =INDIRECT("D"&1+(ROW(I7)-1)*10+COLUMN(F7)-1) -> 2320.908 | R8: =INDIRECT("D"&1+(ROW(J7)-1)*10+COLUMN(G7)-1) -> 2320.908 | S8: =INDIRECT("D"&1+(ROW(K7)-1)*10+COLUMN(H7)-1) -> 2320.908 | ... U8: =INDIRECT("D"&1+(ROW(M7)-1)*10+COLUMN(J7)-1) -> 2320.908 | W8: =AVERAGE(L8:U8) -> 2320.908 | Y8: =Total!E8 -> 2320.908 | AB8: =(L8-$Y8)/$Y8 -> 0 | AC8: =(M8-$Y8)/$Y8 -> 0 | AD8: =(N8-$Y8)/$Y8 -> 0 | AE8: =(O8-$Y8)/$Y8 -> 0 | AF8: =(P8-$Y8)/$Y8 -> 0 | AG8: =(Q8-$Y8)/$Y8 -> 0 | AH8: =(R8-$Y8)/$Y8 -> 0 | AI8: =(S8-$Y8)/$Y8 -> 0 | ... AK8: =(U8-$Y8)/$Y8 -> 0 | AM8: =SUM(AB8:AK8) -> 0
A9: Montage | B9: 25 | C9: 1 | D9: 28.546 | E9: 5.278 | F9: 308 | H9: Epigenomics | I9: 47 | J9: 1 | L9: =INDIRECT("D"&1+(ROW(D8)-1)*10+COLUMN(A8)-1) -> 4313.61 | M9: =INDIRECT("D"&1+(ROW(E8)-1)*10+COLUMN(B8)-1) -> 4313.61 | N9: =INDIRECT("D"&1+(ROW(F8)-1)*10+COLUMN(C8)-1) -> 4313.61 | O9: =INDIRECT("D"&1+(ROW(G8)-1)*10+COLUMN(D8)-1) -> 4313.61 | P9: =INDIRECT("D"&1+(ROW(H8)-1)*10+COLUMN(E8)-1) -> 4313.61 | Q9: =INDIRECT("D"&1+(ROW(I8)-1)*10+COLUMN(F8)-1) -> 4313.61 | R9: =INDIRECT("D"&1+(ROW(J8)-1)*10+COLUMN(G8)-1) -> 4313.61 | S9: =INDIRECT("D"&1+(ROW(K8)-1)*10+COLUMN(H8)-1) -> 4313.61 | ... U9: =INDIRECT("D"&1+(ROW(M8)-1)*10+COLUMN(J8)-1) -> 4313.61 | W9: =AVERAGE(L9:U9) -> 4313.61 | Y9: =Total!E9 -> 4313.61 | AB9: =(L9-$Y9)/$Y9 -> 0 | AC9: =(M9-$Y9)/$Y9 -> 0 | AD9: =(N9-$Y9)/$Y9 -> 0 | AE9: =(O9-$Y9)/$Y9 -> 0 | AF9: =(P9-$Y9)/$Y9 -> 0 | AG9: =(Q9-$Y9)/$Y9 -> 0 | AH9: =(R9-$Y9)/$Y9 -> 0 | AI9: =(S9-$Y9)/$Y9 -> 0 | ... AK9: =(U9-$Y9)/$Y9 -> 0 | AM9: =SUM(AB9:AK9) -> 0
A10: Montage | B10: 25 | C10: 1 | D10: 28.546 | E10: 5.274 | F10: 284 | H10: Epigenomics | I10: 100 | J10: 1 | L10: =INDIRECT("D"&1+(ROW(D9)-1)*10+COLUMN(A9)-1) -> 35273.672 | M10: =INDIRECT("D"&1+(ROW(E9)-1)*10+COLUMN(B9)-1) -> 35276.642 | N10: =INDIRECT("D"&1+(ROW(F9)-1)*10+COLUMN(C9)-1) -> 35342.047 | O10: =INDIRECT("D"&1+(ROW(G9)-1)*10+COLUMN(D9)-1) -> 35298.271 | P10: =INDIRECT("D"&1+(ROW(H9)-1)*10+COLUMN(E9)-1) -> 35312.064 | Q10: =INDIRECT("D"&1+(ROW(I9)-1)*10+COLUMN(F9)-1) -> 35269.238 | R10: =INDIRECT("D"&1+(ROW(J9)-1)*10+COLUMN(G9)-1) -> 35246.097 | S10: =INDIRECT("D"&1+(ROW(K9)-1)*10+COLUMN(H9)-1) -> 35244.377 | ... U10: =INDIRECT("D"&1+(ROW(M9)-1)*10+COLUMN(J9)-1) -> 35234.638 | W10: =AVERAGE(L10:U10) -> 35277.02 | Y10: =Total!E10 -> 35210.383 | AB10: =(L10-$Y10)/$Y10 -> 0.0017974528 | AC10: =(M10-$Y10)/$Y10 -> 0.0018818029 | AD10: =(N10-$Y10)/$Y10 -> 0.0037393515 | AE10: =(O10-$Y10)/$Y10 -> 0.0024960819 | AF10: =(P10-$Y10)/$Y10 -> 0.0028878129 | AG10: =(Q10-$Y10)/$Y10 -> 0.001671524 | AH10: =(R10-$Y10)/$Y10 -> 0.0010143031 | AI10: =(S10-$Y10)/$Y10 -> 0.00096545385 | ... AK10: =(U10-$Y10)/$Y10 -> 0.00068885931 | AM10: =SUM(AB10:AK10) -> 0.018925469
A11: Montage | B11: 50 | C11: 1 | D11: 53.077 | E11: 19.581 | F11: 367 | H11: Ligo | I11: 30 | J11: 1 | L11: =INDIRECT("D"&1+(ROW(D10)-1)*10+COLUMN(A10)-1) -> 657.356 | M11: =INDIRECT("D"&1+(ROW(E10)-1)*10+COLUMN(B10)-1) -> 657.33 | N11: =INDIRECT("D"&1+(ROW(F10)-1)*10+COLUMN(C10)-1) -> 657.356 | O11: =INDIRECT("D"&1+(ROW(G10)-1)*10+COLUMN(D10)-1) -> 658.233 | P11: =INDIRECT("D"&1+(ROW(H10)-1)*10+COLUMN(E10)-1) -> 657.356 | Q11: =INDIRECT("D"&1+(ROW(I10)-1)*10+COLUMN(F10)-1) -> 657.324 | R11: =INDIRECT("D"&1+(ROW(J10)-1)*10+COLUMN(G10)-1) -> 657.356 | S11: =INDIRECT("D"&1+(ROW(K10)-1)*10+COLUMN(H10)-1) -> 657.356 | ... U11: =INDIRECT("D"&1+(ROW(M10)-1)*10+COLUMN(J10)-1) -> 657.356 | W11: =AVERAGE(L11:U11) -> 657.4379 | Y11: =Total!E11 -> 655.465 | AB11: =(L11-$Y11)/$Y11 -> 0.0028849748 | AC11: =(M11-$Y11)/$Y11 -> 0.0028453083 | AD11: =(N11-$Y11)/$Y11 -> 0.0028849748 | AE11: =(O11-$Y11)/$Y11 -> 0.0042229562 | AF11: =(P11-$Y11)/$Y11 -> 0.0028849748 | AG11: =(Q11-$Y11)/$Y11 -> 0.0028361545 | AH11: =(R11-$Y11)/$Y11 -> 0.0028849748 | AI11: =(S11-$Y11)/$Y11 -> 0.0028849748 | ... AK11: =(U11-$Y11)/$Y11 -> 0.0028849748 | AM11: =SUM(AB11:AK11) -> 0.030099243
A12: Montage | B12: 50 | C12: 1 | D12: 53.127 | E12: 19.57 | F12: 366 | H12: Ligo | I12: 50 | J12: 1 | L12: =INDIRECT("D"&1+(ROW(D11)-1)*10+COLUMN(A11)-1) -> 995.476 | M12: =INDIRECT("D"&1+(ROW(E11)-1)*10+COLUMN(B11)-1) -> 995.75 | N12: =INDIRECT("D"&1+(ROW(F11)-1)*10+COLUMN(C11)-1) -> 996.458 | O12: =INDIRECT("D"&1+(ROW(G11)-1)*10+COLUMN(D11)-1) -> 993.677 | P12: =INDIRECT("D"&1+(ROW(H11)-1)*10+COLUMN(E11)-1) -> 999.255 | Q12: =INDIRECT("D"&1+(ROW(I11)-1)*10+COLUMN(F11)-1) -> 995.883 | R12: =INDIRECT("D"&1+(ROW(J11)-1)*10+COLUMN(G11)-1) -> 994.349 | S12: =INDIRECT("D"&1+(ROW(K11)-1)*10+COLUMN(H11)-1) -> 996.3 | ... U12: =INDIRECT("D"&1+(ROW(M11)-1)*10+COLUMN(J11)-1) -> 996.248 | W12: =AVERAGE(L12:U12) -> 995.8239 | Y12: =Total!E12 -> 990.096 | AB12: =(L12-$Y12)/$Y12 -> 0.0054338165 | AC12: =(M12-$Y12)/$Y12 -> 0.0057105574 | AD12: =(N12-$Y12)/$Y12 -> 0.0064256395 | AE12: =(O12-$Y12)/$Y12 -> 0.003616821 | AF12: =(P12-$Y12)/$Y12 -> 0.0092506181 | AG12: =(Q12-$Y12)/$Y12 -> 0.0058448878 | AH12: =(R12-$Y12)/$Y12 -> 0.0042955431 | AI12: =(S12-$Y12)/$Y12 -> 0.006266059 | ... AK12: =(U12-$Y12)/$Y12 -> 0.0062135389 | AM12: =SUM(AB12:AK12) -> 0.057851966
A13: Montage | B13: 50 | C13: 1 | D13: 52.927 | E13: 19.572 | F13: 391 | H13: Ligo | I13: 100 | J13: 1 | L13: =INDIRECT("D"&1+(ROW(D12)-1)*10+COLUMN(A12)-1) -> 1763.951 | M13: =INDIRECT("D"&1+(ROW(E12)-1)*10+COLUMN(B12)-1) -> 1765.662 | N13: =INDIRECT("D"&1+(ROW(F12)-1)*10+COLUMN(C12)-1) -> 1762.365 | O13: =INDIRECT("D"&1+(ROW(G12)-1)*10+COLUMN(D12)-1) -> 1758.605 | P13: =INDIRECT("D"&1+(ROW(H12)-1)*10+COLUMN(E12)-1) -> 1757.977 | Q13: =INDIRECT("D"&1+(ROW(I12)-1)*10+COLUMN(F12)-1) -> 1760.407 | R13: =INDIRECT("D"&1+(ROW(J12)-1)*10+COLUMN(G12)-1) -> 1758.583 | S13: =INDIRECT("D"&1+(ROW(K12)-1)*10+COLUMN(H12)-1) -> 1759.213 | ... U13: =INDIRECT("D"&1+(ROW(M12)-1)*10+COLUMN(J12)-1) -> 1757.567 | W13: =AVERAGE(L13:U13) -> 1760.8782 | Y13: =Total!E13 -> 1753.79 | AB13: =(L13-$Y13)/$Y13 -> 0.0057937381 | AC13: =(M13-$Y13)/$Y13 -> 0.0067693395 | AD13: =(N13-$Y13)/$Y13 -> 0.0048894109 | AE13: =(O13-$Y13)/$Y13 -> 0.0027454826 | AF13: =(P13-$Y13)/$Y13 -> 0.002387401 | AG13: =(Q13-$Y13)/$Y13 -> 0.0037729717 | AH13: =(R13-$Y13)/$Y13 -> 0.0027329384 | AI13: =(S13-$Y13)/$Y13 -> 0.0030921604 | ... AK13: =(U13-$Y13)/$Y13 -> 0.0021536216 | AM13: =SUM(AB13:AK13) -> 0.040416469
... A19: Montage | B19: 50 | C19: 1 | D19: 53.067 | E19: 19.564 | F19: 366 | H19: fft | I19: 224 | J19: 1 | L19: =INDIRECT("D"&1+(ROW(D18)-1)*10+COLUMN(A18)-1) -> 72.064 | M19: =INDIRECT("D"&1+(ROW(E18)-1)*10+COLUMN(B18)-1) -> 72.088 | N19: =INDIRECT("D"&1+(ROW(F18)-1)*10+COLUMN(C18)-1) -> 72.08 | O19: =INDIRECT("D"&1+(ROW(G18)-1)*10+COLUMN(D18)-1) -> 71.996 | P19: =INDIRECT("D"&1+(ROW(H18)-1)*10+COLUMN(E18)-1) -> 72.037 | Q19: =INDIRECT("D"&1+(ROW(I18)-1)*10+COLUMN(F18)-1) -> 72.07 | R19: =INDIRECT("D"&1+(ROW(J18)-1)*10+COLUMN(G18)-1) -> 71.998 | S19: =INDIRECT("D"&1+(ROW(K18)-1)*10+COLUMN(H18)-1) -> 71.972 | ... U19: =INDIRECT("D"&1+(ROW(M18)-1)*10+COLUMN(J18)-1) -> 72.124 | W19: =AVERAGE(L19:U19) -> 72.048 | Y19: =Total!E19 -> 71.908 | AB19: =(L19-$Y19)/$Y19 -> 0.0021694387 | AC19: =(M19-$Y19)/$Y19 -> 0.0025031985 | AD19: =(N19-$Y19)/$Y19 -> 0.0023919453 | AE19: =(O19-$Y19)/$Y19 -> 0.0012237859 | AF19: =(P19-$Y19)/$Y19 -> 0.0017939589 | AG19: =(Q19-$Y19)/$Y19 -> 0.0022528787 | AH19: =(R19-$Y19)/$Y19 -> 0.0012515993 | AI19: =(S19-$Y19)/$Y19 -> 0.00089002614 | ... AK19: =(U19-$Y19)/$Y19 -> 0.0030038382 | AM19: =SUM(AB19:AK19) -> 0.019469322
A20: Montage | B20: 50 | C20: 1 | D20: 52.927 | E20: 19.586 | F20: 378
A21: Montage | B21: 100 | C21: 1 | D21: 103.314 | E21: 101.997 | F21: 630
A22: Montage | B22: 100 | C22: 1 | D22: 103.259 | E22: 102.09 | F22: 578
A23: Montage | B23: 100 | C23: 1 | D23: 103.322 | E23: 102.059 | F23: 635
A24: Montage | B24: 100 | C24: 1 | D24: 103.422 | E24: 102.062 | F24: 600
A25: Montage | B25: 100 | C25: 1 | D25: 103.324 | E25: 102.072 | F25: 622
A26: Montage | B26: 100 | C26: 1 | D26: 103.26 | E26: 102.088 | F26: 622
A27: Montage | B27: 100 | C27: 1 | D27: 103.203 | E27: 102.156 | F27: 586
A28: Montage | B28: 100 | C28: 1 | D28: 103.282 | E28: 102.054 | F28: 642
A29: Montage | B29: 100 | C29: 1 | D29: 103.271 | E29: 102.029 | F29: 598
A30: Montage | B30: 100 | C30: 1 | D30: 103.325 | E30: 102.032 | F30: 629
A31: CyberShake | B31: 30 | C31: 1 | D31: 156.127 | E31: 8.008 | F31: 280
... A180: fft | B180: 224 | C180: 1 | D180: 72.124 | E180: 255.822 | F180: 321

Sheet 2
A1: Montage | B1: 25 | C1: 1 | D1: 28.587 | E1: 5.294 | F1: 226 | H1: ty | I1: sz | J1: ra | L1: 1 | M1: 2 | N1: 3 | O1: 4 | P1: 5 | Q1: 6 | R1: 7 | S1: 8 | T1: 9 | U1: 10 | W1: average | Y1: Min | AM1: sum
A2: Montage | B2: 25 | C2: 1 | D2: 28.546 | E2: 5.283 | F2: 256 | H2: Montage | I2: 25 | J2: 1 | L2: =INDIRECT("D"&1+(ROW(D1)-1)*10+COLUMN(A1)-1) -> 28.587 | M2: =INDIRECT("D"&1+(ROW(E1)-1)*10+COLUMN(B1)-1) -> 28.546 | N2: =INDIRECT("D"&1+(ROW(F1)-1)*10+COLUMN(C1)-1) -> 28.504 | O2: =INDIRECT("D"&1+(ROW(G1)-1)*10+COLUMN(D1)-1) -> 28.596 | P2: =INDIRECT("D"&1+(ROW(H1)-1)*10+COLUMN(E1)-1) -> 28.504 | Q2: =INDIRECT("D"&1+(ROW(I1)-1)*10+COLUMN(F1)-1) -> 28.546 | R2: =INDIRECT("D"&1+(ROW(J1)-1)*10+COLUMN(G1)-1) -> 28.587 | S2: =INDIRECT("D"&1+(ROW(K1)-1)*10+COLUMN(H1)-1) -> 28.504 | ... U2: =INDIRECT("D"&1+(ROW(M1)-1)*10+COLUMN(J1)-1) -> 28.592 | W2: =AVERAGE(L2:U2) -> 28.5512 | Y2: =Total!E2 -> 28.504 | AB2: =(L2-$Y2)/$Y2 -> 0.002911872 | AC2: =(M2-$Y2)/$Y2 -> 0.0014734774 | AD2: =(N2-$Y2)/$Y2 -> 0 | AE2: =(O2-$Y2)/$Y2 -> 0.0032276172 | AF2: =(P2-$Y2)/$Y2 -> 0 | AG2: =(Q2-$Y2)/$Y2 -> 0.0014734774 | AH2: =(R2-$Y2)/$Y2 -> 0.002911872 | AI2: =(S2-$Y2)/$Y2 -> 0 | ... AK2: =(U2-$Y2)/$Y2 -> 0.003087286 | AM2: =SUM(AB2:AK2) -> 0.016559079
A3: Montage | B3: 25 | C3: 1 | D3: 28.504 | E3: 5.293 | F3: 241 | H3: Montage | I3: 50 | J3: 1 | L3: =INDIRECT("D"&1+(ROW(D2)-1)*10+COLUMN(A2)-1) -> 53.367 | M3: =INDIRECT("D"&1+(ROW(E2)-1)*10+COLUMN(B2)-1) -> 52.958 | N3: =INDIRECT("D"&1+(ROW(F2)-1)*10+COLUMN(C2)-1) -> 53.037 | O3: =INDIRECT("D"&1+(ROW(G2)-1)*10+COLUMN(D2)-1) -> 53.092 | P3: =INDIRECT("D"&1+(ROW(H2)-1)*10+COLUMN(E2)-1) -> 53.037 | Q3: =INDIRECT("D"&1+(ROW(I2)-1)*10+COLUMN(F2)-1) -> 53.038 | R3: =INDIRECT("D"&1+(ROW(J2)-1)*10+COLUMN(G2)-1) -> 52.988 | S3: =INDIRECT("D"&1+(ROW(K2)-1)*10+COLUMN(H2)-1) -> 52.987 | ... U3: =INDIRECT("D"&1+(ROW(M2)-1)*10+COLUMN(J2)-1) -> 53.017 | W3: =AVERAGE(L3:U3) -> 53.0638 | Y3: =Total!E3 -> 52.927 | AB3: =(L3-$Y3)/$Y3 -> 0.0083133372 | AC3: =(M3-$Y3)/$Y3 -> 0.0005857124 | AD3: =(N3-$Y3)/$Y3 -> 0.0020783343 | AE3: =(O3-$Y3)/$Y3 -> 0.0031175015 | AF3: =(P3-$Y3)/$Y3 -> 0.0020783343 | AG3: =(Q3-$Y3)/$Y3 -> 0.0020972283 | AH3: =(R3-$Y3)/$Y3 -> 0.0011525308 | AI3: =(S3-$Y3)/$Y3 -> 0.0011336369 | ... AK3: =(U3-$Y3)/$Y3 -> 0.0017004553 | AM3: =SUM(AB3:AK3) -> 0.025846921
A4: Montage | B4: 25 | C4: 1 | D4: 28.596 | E4: 5.289 | F4: 279 | H4: Montage | I4: 100 | J4: 1 | L4: =INDIRECT("D"&1+(ROW(D3)-1)*10+COLUMN(A3)-1) -> 103.302 | M4: =INDIRECT("D"&1+(ROW(E3)-1)*10+COLUMN(B3)-1) -> 103.291 | N4: =INDIRECT("D"&1+(ROW(F3)-1)*10+COLUMN(C3)-1) -> 103.266 | O4: =INDIRECT("D"&1+(ROW(G3)-1)*10+COLUMN(D3)-1) -> 103.272 | P4: =INDIRECT("D"&1+(ROW(H3)-1)*10+COLUMN(E3)-1) -> 103.259 | Q4: =INDIRECT("D"&1+(ROW(I3)-1)*10+COLUMN(F3)-1) -> 103.237 | R4: =INDIRECT("D"&1+(ROW(J3)-1)*10+COLUMN(G3)-1) -> 103.285 | S4: =INDIRECT("D"&1+(ROW(K3)-1)*10+COLUMN(H3)-1) -> 103.154 | ... U4: =INDIRECT("D"&1+(ROW(M3)-1)*10+COLUMN(J3)-1) -> 103.299 | W4: =AVERAGE(L4:U4) -> 103.2613 | Y4: =Total!E4 -> 102.802 | AB4: =(L4-$Y4)/$Y4 -> 0.0048637186 | AC4: =(M4-$Y4)/$Y4 -> 0.0047567168 | AD4: =(N4-$Y4)/$Y4 -> 0.0045135309 | AE4: =(O4-$Y4)/$Y4 -> 0.0045718955 | AF4: =(P4-$Y4)/$Y4 -> 0.0044454388 | AG4: =(Q4-$Y4)/$Y4 -> 0.0042314352 | AH4: =(R4-$Y4)/$Y4 -> 0.0046983522 | AI4: =(S4-$Y4)/$Y4 -> 0.0034240579 | ... AK4: =(U4-$Y4)/$Y4 -> 0.0048345363 | AM4: =SUM(AB4:AK4) -> 0.044678119
A5: Montage | B5: 25 | C5: 1 | D5: 28.504 | E5: 5.29 | F5: 240 | H5: CyberShake | I5: 30 | J5: 1 | L5: =INDIRECT("D"&1+(ROW(D4)-1)*10+COLUMN(A4)-1) -> 156.127 | M5: =INDIRECT("D"&1+(ROW(E4)-1)*10+COLUMN(B4)-1) -> 156.127 | N5: =INDIRECT("D"&1+(ROW(F4)-1)*10+COLUMN(C4)-1) -> 156.127 | O5: =INDIRECT("D"&1+(ROW(G4)-1)*10+COLUMN(D4)-1) -> 156.127 | P5: =INDIRECT("D"&1+(ROW(H4)-1)*10+COLUMN(E4)-1) -> 156.127 | Q5: =INDIRECT("D"&1+(ROW(I4)-1)*10+COLUMN(F4)-1) -> 156.127 | R5: =INDIRECT("D"&1+(ROW(J4)-1)*10+COLUMN(G4)-1) -> 156.127 | S5: =INDIRECT("D"&1+(ROW(K4)-1)*10+COLUMN(H4)-1) -> 156.127 | ... U5: =INDIRECT("D"&1+(ROW(M4)-1)*10+COLUMN(J4)-1) -> 156.127 | W5: =AVERAGE(L5:U5) -> 156.127 | Y5: =Total!E5 -> 156.127 | AB5: =(L5-$Y5)/$Y5 -> 0 | AC5: =(M5-$Y5)/$Y5 -> 0 | AD5: =(N5-$Y5)/$Y5 -> 0 | AE5: =(O5-$Y5)/$Y5 -> 0 | AF5: =(P5-$Y5)/$Y5 -> 0 | AG5: =(Q5-$Y5)/$Y5 -> 0 | AH5: =(R5-$Y5)/$Y5 -> 0 | AI5: =(S5-$Y5)/$Y5 -> 0 | ... AK5: =(U5-$Y5)/$Y5 -> 0 | AM5: =SUM(AB5:AK5) -> 0
A6: Montage | B6: 25 | C6: 1 | D6: 28.546 | E6: 5.281 | F6: 245 | H6: CyberShake | I6: 50 | J6: 1 | L6: =INDIRECT("D"&1+(ROW(D5)-1)*10+COLUMN(A5)-1) -> 180.25 | M6: =INDIRECT("D"&1+(ROW(E5)-1)*10+COLUMN(B5)-1) -> 181.89 | N6: =INDIRECT("D"&1+(ROW(F5)-1)*10+COLUMN(C5)-1) -> 180.871 | O6: =INDIRECT("D"&1+(ROW(G5)-1)*10+COLUMN(D5)-1) -> 181.351 | P6: =INDIRECT("D"&1+(ROW(H5)-1)*10+COLUMN(E5)-1) -> 181.597 | Q6: =INDIRECT("D"&1+(ROW(I5)-1)*10+COLUMN(F5)-1) -> 181.89 | R6: =INDIRECT("D"&1+(ROW(J5)-1)*10+COLUMN(G5)-1) -> 181.717 | S6: =INDIRECT("D"&1+(ROW(K5)-1)*10+COLUMN(H5)-1) -> 179.943 | ... U6: =INDIRECT("D"&1+(ROW(M5)-1)*10+COLUMN(J5)-1) -> 179.938 | W6: =AVERAGE(L6:U6) -> 181.0318 | Y6: =Total!E6 -> 179.673 | AB6: =(L6-$Y6)/$Y6 -> 0.0032113896 | AC6: =(M6-$Y6)/$Y6 -> 0.012339083 | AD6: =(N6-$Y6)/$Y6 -> 0.0066676685 | AE6: =(O6-$Y6)/$Y6 -> 0.0093391884 | AF6: =(P6-$Y6)/$Y6 -> 0.010708342 | AG6: =(Q6-$Y6)/$Y6 -> 0.012339083 | AH6: =(R6-$Y6)/$Y6 -> 0.011376222 | AI6: =(S6-$Y6)/$Y6 -> 0.00150273 | ... AK6: =(U6-$Y6)/$Y6 -> 0.0014749016 | AM6: =SUM(AB6:AK6) -> 0.075626277
A7: Montage | B7: 25 | C7: 1 | D7: 28.587 | E7: 5.284 | F7: 216 | H7: CyberShake | I7: 100 | J7: 1 | L7: =INDIRECT("D"&1+(ROW(D6)-1)*10+COLUMN(A6)-1) -> 239.674 | M7: =INDIRECT("D"&1+(ROW(E6)-1)*10+COLUMN(B6)-1) -> 239.259 | N7: =INDIRECT("D"&1+(ROW(F6)-1)*10+COLUMN(C6)-1) -> 239.253 | O7: =INDIRECT("D"&1+(ROW(G6)-1)*10+COLUMN(D6)-1) -> 239.653 | P7: =INDIRECT("D"&1+(ROW(H6)-1)*10+COLUMN(E6)-1) -> 239.613 | Q7: =INDIRECT("D"&1+(ROW(I6)-1)*10+COLUMN(F6)-1) -> 239.48 | R7: =INDIRECT("D"&1+(ROW(J6)-1)*10+COLUMN(G6)-1) -> 239.23 | S7: =INDIRECT("D"&1+(ROW(K6)-1)*10+COLUMN(H6)-1) -> 239.397 | ... U7: =INDIRECT("D"&1+(ROW(M6)-1)*10+COLUMN(J6)-1) -> 239.218 | W7: =AVERAGE(L7:U7) -> 239.4333 | Y7: =Total!E7 -> 238.867 | AB7: =(L7-$Y7)/$Y7 -> 0.0033784491 | AC7: =(M7-$Y7)/$Y7 -> 0.0016410806 | AD7: =(N7-$Y7)/$Y7 -> 0.001615962 | AE7: =(O7-$Y7)/$Y7 -> 0.0032905341 | AF7: =(P7-$Y7)/$Y7 -> 0.0031230769 | AG7: =(Q7-$Y7)/$Y7 -> 0.0025662817 | AH7: =(R7-$Y7)/$Y7 -> 0.0015196741 | AI7: =(S7-$Y7)/$Y7 -> 0.002218808 | ... AK7: =(U7-$Y7)/$Y7 -> 0.001469437 | AM7: =SUM(AB7:AK7) -> 0.023707754
A8: Montage | B8: 25 | C8: 1 | D8: 28.504 | E8: 5.299 | F8: 248 | H8: Epigenomics | I8: 24 | J8: 1 | L8: =INDIRECT("D"&1+(ROW(D7)-1)*10+COLUMN(A7)-1) -> 2328.248 | M8: =INDIRECT("D"&1+(ROW(E7)-1)*10+COLUMN(B7)-1) -> 2320.908 | N8: =INDIRECT("D"&1+(ROW(F7)-1)*10+COLUMN(C7)-1) -> 2320.908 | O8: =INDIRECT("D"&1+(ROW(G7)-1)*10+COLUMN(D7)-1) -> 2320.908 | P8: =INDIRECT("D"&1+(ROW(H7)-1)*10+COLUMN(E7)-1) -> 2320.908 | Q8: =INDIRECT("D"&1+(ROW(I7)-1)*10+COLUMN(F7)-1) -> 2320.908 | R8: =INDIRECT("D"&1+(ROW(J7)-1)*10+COLUMN(G7)-1) -> 2320.908 | S8: =INDIRECT("D"&1+(ROW(K7)-1)*10+COLUMN(H7)-1) -> 2320.908 | ... U8: =INDIRECT("D"&1+(ROW(M7)-1)*10+COLUMN(J7)-1) -> 2328.248 | W8: =AVERAGE(L8:U8) -> 2322.376 | Y8: =Total!E8 -> 2320.908 | AB8: =(L8-$Y8)/$Y8 -> 0.0031625553 | AC8: =(M8-$Y8)/$Y8 -> 0 | AD8: =(N8-$Y8)/$Y8 -> 0 | AE8: =(O8-$Y8)/$Y8 -> 0 | AF8: =(P8-$Y8)/$Y8 -> 0 | AG8: =(Q8-$Y8)/$Y8 -> 0 | AH8: =(R8-$Y8)/$Y8 -> 0 | AI8: =(S8-$Y8)/$Y8 -> 0 | ... AK8: =(U8-$Y8)/$Y8 -> 0.0031625553 | AM8: =SUM(AB8:AK8) -> 0.0063251107
A9: Montage | B9: 25 | C9: 1 | D9: 28.546 | E9: 5.291 | F9: 233 | H9: Epigenomics | I9: 47 | J9: 1 | L9: =INDIRECT("D"&1+(ROW(D8)-1)*10+COLUMN(A8)-1) -> 4313.61 | M9: =INDIRECT("D"&1+(ROW(E8)-1)*10+COLUMN(B8)-1) -> 4313.61 | N9: =INDIRECT("D"&1+(ROW(F8)-1)*10+COLUMN(C8)-1) -> 4313.61 | O9: =INDIRECT("D"&1+(ROW(G8)-1)*10+COLUMN(D8)-1) -> 4318.488 | P9: =INDIRECT("D"&1+(ROW(H8)-1)*10+COLUMN(E8)-1) -> 4318.488 | Q9: =INDIRECT("D"&1+(ROW(I8)-1)*10+COLUMN(F8)-1) -> 4313.61 | R9: =INDIRECT("D"&1+(ROW(J8)-1)*10+COLUMN(G8)-1) -> 4313.61 | S9: =INDIRECT("D"&1+(ROW(K8)-1)*10+COLUMN(H8)-1) -> 4313.61 | ... U9: =INDIRECT("D"&1+(ROW(M8)-1)*10+COLUMN(J8)-1) -> 4313.61 | W9: =AVERAGE(L9:U9) -> 4314.5856 | Y9: =Total!E9 -> 4313.61 | AB9: =(L9-$Y9)/$Y9 -> 0 | AC9: =(M9-$Y9)/$Y9 -> 0 | AD9: =(N9-$Y9)/$Y9 -> 0 | AE9: =(O9-$Y9)/$Y9 -> 0.0011308394 | AF9: =(P9-$Y9)/$Y9 -> 0.0011308394 | AG9: =(Q9-$Y9)/$Y9 -> 0 | AH9: =(R9-$Y9)/$Y9 -> 0 | AI9: =(S9-$Y9)/$Y9 -> 0 | ... AK9: =(U9-$Y9)/$Y9 -> 0 | AM9: =SUM(AB9:AK9) -> 0.0022616787
A10: Montage | B10: 25 | C10: 1 | D10: 28.592 | E10: 5.278 | F10: 284 | H10: Epigenomics | I10: 100 | J10: 1 | L10: =INDIRECT("D"&1+(ROW(D9)-1)*10+COLUMN(A9)-1) -> 35272.827 | M10: =INDIRECT("D"&1+(ROW(E9)-1)*10+COLUMN(B9)-1) -> 35272.953 | N10: =INDIRECT("D"&1+(ROW(F9)-1)*10+COLUMN(C9)-1) -> 35217.664 | O10: =INDIRECT("D"&1+(ROW(G9)-1)*10+COLUMN(D9)-1) -> 35224.895 | P10: =INDIRECT("D"&1+(ROW(H9)-1)*10+COLUMN(E9)-1) -> 35210.383 | Q10: =INDIRECT("D"&1+(ROW(I9)-1)*10+COLUMN(F9)-1) -> 35272.953 | R10: =INDIRECT("D"&1+(ROW(J9)-1)*10+COLUMN(G9)-1) -> 35272.953 | S10: =INDIRECT("D"&1+(ROW(K9)-1)*10+COLUMN(H9)-1) -> 35246.271 | ... U10: =INDIRECT("D"&1+(ROW(M9)-1)*10+COLUMN(J9)-1) -> 35272.953 | W10: =AVERAGE(L10:U10) -> 35249.931 | Y10: =Total!E10 -> 35210.383 | AB10: =(L10-$Y10)/$Y10 -> 0.0017734542 | AC10: =(M10-$Y10)/$Y10 -> 0.0017770326 | AD10: =(N10-$Y10)/$Y10 -> 0.0002067856 | AE10: =(O10-$Y10)/$Y10 -> 0.00041215115 | AF10: =(P10-$Y10)/$Y10 -> 0 | AG10: =(Q10-$Y10)/$Y10 -> 0.0017770326 | AH10: =(R10-$Y10)/$Y10 -> 0.0017770326 | AI10: =(S10-$Y10)/$Y10 -> 0.0010192448 | ... AK10: =(U10-$Y10)/$Y10 -> 0.0017770326 | AM10: =SUM(AB10:AK10) -> 0.011232028
A11: Montage | B11: 50 | C11: 1 | D11: 53.367 | E11: 19.578 | F11: 366 | H11: Ligo | I11: 30 | J11: 1 | L11: =INDIRECT("D"&1+(ROW(D10)-1)*10+COLUMN(A10)-1) -> 658.233 | M11: =INDIRECT("D"&1+(ROW(E10)-1)*10+COLUMN(B10)-1) -> 658.233 | N11: =INDIRECT("D"&1+(ROW(F10)-1)*10+COLUMN(C10)-1) -> 658.233 | O11: =INDIRECT("D"&1+(ROW(G10)-1)*10+COLUMN(D10)-1) -> 658.233 | P11: =INDIRECT("D"&1+(ROW(H10)-1)*10+COLUMN(E10)-1) -> 658.233 | Q11: =INDIRECT("D"&1+(ROW(I10)-1)*10+COLUMN(F10)-1) -> 658.233 | R11: =INDIRECT("D"&1+(ROW(J10)-1)*10+COLUMN(G10)-1) -> 657.356 | S11: =INDIRECT("D"&1+(ROW(K10)-1)*10+COLUMN(H10)-1) -> 657.356 | ... U11: =INDIRECT("D"&1+(ROW(M10)-1)*10+COLUMN(J10)-1) -> 658.233 | W11: =AVERAGE(L11:U11) -> 658.0576 | Y11: =Total!E11 -> 655.465 | AB11: =(L11-$Y11)/$Y11 -> 0.0042229562 | AC11: =(M11-$Y11)/$Y11 -> 0.0042229562 | AD11: =(N11-$Y11)/$Y11 -> 0.0042229562 | AE11: =(O11-$Y11)/$Y11 -> 0.0042229562 | AF11: =(P11-$Y11)/$Y11 -> 0.0042229562 | AG11: =(Q11-$Y11)/$Y11 -> 0.0042229562 | AH11: =(R11-$Y11)/$Y11 -> 0.0028849748 | AI11: =(S11-$Y11)/$Y11 -> 0.0028849748 | ... AK11: =(U11-$Y11)/$Y11 -> 0.0042229562 | AM11: =SUM(AB11:AK11) -> 0.039553599
A12: Montage | B12: 50 | C12: 1 | D12: 52.958 | E12: 19.553 | F12: 371 | H12: Ligo | I12: 50 | J12: 1 | L12: =INDIRECT("D"&1+(ROW(D11)-1)*10+COLUMN(A11)-1) -> 996.566 | M12: =INDIRECT("D"&1+(ROW(E11)-1)*10+COLUMN(B11)-1) -> 994.471 | N12: =INDIRECT("D"&1+(ROW(F11)-1)*10+COLUMN(C11)-1) -> 990.792 | O12: =INDIRECT("D"&1+(ROW(G11)-1)*10+COLUMN(D11)-1) -> 996.14 | P12: =INDIRECT("D"&1+(ROW(H11)-1)*10+COLUMN(E11)-1) -> 996.253 | Q12: =INDIRECT("D"&1+(ROW(I11)-1)*10+COLUMN(F11)-1) -> 995.471 | R12: =INDIRECT("D"&1+(ROW(J11)-1)*10+COLUMN(G11)-1) -> 992.182 | S12: =INDIRECT("D"&1+(ROW(K11)-1)*10+COLUMN(H11)-1) -> 993.008 | ... U12: =INDIRECT("D"&1+(ROW(M11)-1)*10+COLUMN(J11)-1) -> 992.125 | W12: =AVERAGE(L12:U12) -> 994.3873 | Y12: =Total!E12 -> 990.096 | AB12: =(L12-$Y12)/$Y12 -> 0.0065347199 | AC12: =(M12-$Y12)/$Y12 -> 0.0044187634 | AD12: =(N12-$Y12)/$Y12 -> 0.00070296214 | AE12: =(O12-$Y12)/$Y12 -> 0.0061044586 | AF12: =(P12-$Y12)/$Y12 -> 0.0062185889 | AG12: =(Q12-$Y12)/$Y12 -> 0.0054287665 | AH12: =(R12-$Y12)/$Y12 -> 0.0021068664 | AI12: =(S12-$Y12)/$Y12 -> 0.0029411289 | ... AK12: =(U12-$Y12)/$Y12 -> 0.0020492962 | AM12: =SUM(AB12:AK12) -> 0.043342262
A13: Montage | B13: 50 | C13: 1 | D13: 53.037 | E13: 19.588 | F13: 368 | H13: Ligo | I13: 100 | J13: 1 | L13: =INDIRECT("D"&1+(ROW(D12)-1)*10+COLUMN(A12)-1) -> 1756.92 | M13: =INDIRECT("D"&1+(ROW(E12)-1)*10+COLUMN(B12)-1) -> 1754.423 | N13: =INDIRECT("D"&1+(ROW(F12)-1)*10+COLUMN(C12)-1) -> 1755.087 | O13: =INDIRECT("D"&1+(ROW(G12)-1)*10+COLUMN(D12)-1) -> 1757.307 | P13: =INDIRECT("D"&1+(ROW(H12)-1)*10+COLUMN(E12)-1) -> 1758.03 | Q13: =INDIRECT("D"&1+(ROW(I12)-1)*10+COLUMN(F12)-1) -> 1755.888 | R13: =INDIRECT("D"&1+(ROW(J12)-1)*10+COLUMN(G12)-1) -> 1758.687 | S13: =INDIRECT("D"&1+(ROW(K12)-1)*10+COLUMN(H12)-1) -> 1755.209 | ... U13: =INDIRECT("D"&1+(ROW(M12)-1)*10+COLUMN(J12)-1) -> 1755.253 | W13: =AVERAGE(L13:U13) -> 1756.2487 | Y13: =Total!E13 -> 1753.79 | AB13: =(L13-$Y13)/$Y13 -> 0.0017847063 | AC13: =(M13-$Y13)/$Y13 -> 0.00036093261 | AD13: =(N13-$Y13)/$Y13 -> 0.00073954122 | AE13: =(O13-$Y13)/$Y13 -> 0.0020053712 | AF13: =(P13-$Y13)/$Y13 -> 0.0024176213 | AG13: =(Q13-$Y13)/$Y13 -> 0.0011962664 | AH13: =(R13-$Y13)/$Y13 -> 0.0027922385 | AI13: =(S13-$Y13)/$Y13 -> 0.00080910485 | ... AK13: =(U13-$Y13)/$Y13 -> 0.00083419338 | AM13: =SUM(AB13:AK13) -> 0.014019352
... A19: Montage | B19: 50 | C19: 1 | D19: 53.117 | E19: 19.563 | F19: 360 | H19: fft | I19: 224 | J19: 1 | L19: =INDIRECT("D"&1+(ROW(D18)-1)*10+COLUMN(A18)-1) -> 71.975 | M19: =INDIRECT("D"&1+(ROW(E18)-1)*10+COLUMN(B18)-1) -> 71.918 | N19: =INDIRECT("D"&1+(ROW(F18)-1)*10+COLUMN(C18)-1) -> 71.912 | O19: =INDIRECT("D"&1+(ROW(G18)-1)*10+COLUMN(D18)-1) -> 71.984 | P19: =INDIRECT("D"&1+(ROW(H18)-1)*10+COLUMN(E18)-1) -> 72.009 | Q19: =INDIRECT("D"&1+(ROW(I18)-1)*10+COLUMN(F18)-1) -> 71.919 | R19: =INDIRECT("D"&1+(ROW(J18)-1)*10+COLUMN(G18)-1) -> 71.936 | S19: =INDIRECT("D"&1+(ROW(K18)-1)*10+COLUMN(H18)-1) -> 71.92 | ... U19: =INDIRECT("D"&1+(ROW(M18)-1)*10+COLUMN(J18)-1) -> 71.933 | W19: =AVERAGE(L19:U19) -> 71.9483 | Y19: =Total!E19 -> 71.908 | AB19: =(L19-$Y19)/$Y19 -> 0.00093174612 | AC19: =(M19-$Y19)/$Y19 -> 0.00013906659 | AD19: =(N19-$Y19)/$Y19 -> 5.5626634e-05 | AE19: =(O19-$Y19)/$Y19 -> 0.001056906 | AF19: =(P19-$Y19)/$Y19 -> 0.0014045725 | AG19: =(Q19-$Y19)/$Y19 -> 0.00015297324 | AH19: =(R19-$Y19)/$Y19 -> 0.00038938644 | AI19: =(S19-$Y19)/$Y19 -> 0.0001668799 | ... AK19: =(U19-$Y19)/$Y19 -> 0.00034766646 | AM19: =SUM(AB19:AK19) -> 0.0056043834
A20: Montage | B20: 50 | C20: 1 | D20: 53.017 | E20: 19.568 | F20: 366
A21: Montage | B21: 100 | C21: 1 | D21: 103.302 | E21: 102.016 | F21: 638
A22: Montage | B22: 100 | C22: 1 | D22: 103.291 | E22: 102.008 | F22: 589
A23: Montage | B23: 100 | C23: 1 | D23: 103.266 | E23: 102 | F23: 625
A24: Montage | B24: 100 | C24: 1 | D24: 103.272 | E24: 102.006 | F24: 588
A25: Montage | B25: 100 | C25: 1 | D25: 103.259 | E25: 102.154 | F25: 626
A26: Montage | B26: 100 | C26: 1 | D26: 103.237 | E26: 102.078 | F26: 621
A27: Montage | B27: 100 | C27: 1 | D27: 103.285 | E27: 102.004 | F27: 585
A28: Montage | B28: 100 | C28: 1 | D28: 103.154 | E28: 102.082 | F28: 623
A29: Montage | B29: 100 | C29: 1 | D29: 103.248 | E29: 102.056 | F29: 571
A30: Montage | B30: 100 | C30: 1 | D30: 103.299 | E30: 102.118 | F30: 648
A31: CyberShake | B31: 30 | C31: 1 | D31: 156.127 | E31: 8.031 | F31: 275
... A180: fft | B180: 224 | C180: 1 | D180: 71.933 | E180: 255.938 | F180: 336

Sheet 3
A1: Montage | B1: 25 | C1: 1 | D1: 28.504 | E1: 5.291 | F1: 267 | H1: ty | I1: sz | J1: ra | L1: 1 | M1: 2 | N1: 3 | O1: 4 | P1: 5 | Q1: 6 | R1: 7 | S1: 8 | T1: 9 | U1: 10 | W1: average | Y1: Min | AM1: sum
A2: Montage | B2: 25 | C2: 1 | D2: 28.504 | E2: 5.288 | F2: 264 | H2: Montage | I2: 25 | J2: 1 | L2: =INDIRECT("D"&1+(ROW(D1)-1)*10+COLUMN(A1)-1) -> 28.504 | M2: =INDIRECT("D"&1+(ROW(E1)-1)*10+COLUMN(B1)-1) -> 28.504 | N2: =INDIRECT("D"&1+(ROW(F1)-1)*10+COLUMN(C1)-1) -> 28.546 | O2: =INDIRECT("D"&1+(ROW(G1)-1)*10+COLUMN(D1)-1) -> 28.546 | P2: =INDIRECT("D"&1+(ROW(H1)-1)*10+COLUMN(E1)-1) -> 28.504 | Q2: =INDIRECT("D"&1+(ROW(I1)-1)*10+COLUMN(F1)-1) -> 28.504 | R2: =INDIRECT("D"&1+(ROW(J1)-1)*10+COLUMN(G1)-1) -> 28.592 | S2: =INDIRECT("D"&1+(ROW(K1)-1)*10+COLUMN(H1)-1) -> 28.504 | ... U2: =INDIRECT("D"&1+(ROW(M1)-1)*10+COLUMN(J1)-1) -> 28.546 | W2: =AVERAGE(L2:U2) -> 28.5296 | Y2: =Total!E2 -> 28.504 | AB2: =(L2-$Y2)/$Y2 -> 0 | AC2: =(M2-$Y2)/$Y2 -> 0 | AD2: =(N2-$Y2)/$Y2 -> 0.0014734774 | AE2: =(O2-$Y2)/$Y2 -> 0.0014734774 | AF2: =(P2-$Y2)/$Y2 -> 0 | AG2: =(Q2-$Y2)/$Y2 -> 0 | AH2: =(R2-$Y2)/$Y2 -> 0.003087286 | AI2: =(S2-$Y2)/$Y2 -> 0 | ... AK2: =(U2-$Y2)/$Y2 -> 0.0014734774 | AM2: =SUM(AB2:AK2) -> 0.0089811956
A3: Montage | B3: 25 | C3: 1 | D3: 28.546 | E3: 5.285 | F3: 283 | H3: Montage | I3: 50 | J3: 1 | L3: =INDIRECT("D"&1+(ROW(D2)-1)*10+COLUMN(A2)-1) -> 53.148 | M3: =INDIRECT("D"&1+(ROW(E2)-1)*10+COLUMN(B2)-1) -> 53.187 | N3: =INDIRECT("D"&1+(ROW(F2)-1)*10+COLUMN(C2)-1) -> 52.958 | O3: =INDIRECT("D"&1+(ROW(G2)-1)*10+COLUMN(D2)-1) -> 53.058 | P3: =INDIRECT("D"&1+(ROW(H2)-1)*10+COLUMN(E2)-1) -> 52.987 | Q3: =INDIRECT("D"&1+(ROW(I2)-1)*10+COLUMN(F2)-1) -> 53.096 | R3: =INDIRECT("D"&1+(ROW(J2)-1)*10+COLUMN(G2)-1) -> 53.048 | S3: =INDIRECT("D"&1+(ROW(K2)-1)*10+COLUMN(H2)-1) -> 52.958 | ... U3: =INDIRECT("D"&1+(ROW(M2)-1)*10+COLUMN(J2)-1) -> 53.067 | W3: =AVERAGE(L3:U3) -> 53.0621 | Y3: =Total!E3 -> 52.927 | AB3: =(L3-$Y3)/$Y3 -> 0.0041755626 | AC3: =(M3-$Y3)/$Y3 -> 0.0049124265 | AD3: =(N3-$Y3)/$Y3 -> 0.0005857124 | AE3: =(O3-$Y3)/$Y3 -> 0.0024751072 | AF3: =(P3-$Y3)/$Y3 -> 0.0011336369 | AG3: =(Q3-$Y3)/$Y3 -> 0.0031930773 | AH3: =(R3-$Y3)/$Y3 -> 0.0022861677 | AI3: =(S3-$Y3)/$Y3 -> 0.0005857124 | ... AK3: =(U3-$Y3)/$Y3 -> 0.0026451528 | AM3: =SUM(AB3:AK3) -> 0.025525724
A4: Montage | B4: 25 | C4: 1 | D4: 28.546 | E4: 5.283 | F4: 333 | H4: Montage | I4: 100 | J4: 1 | L4: =INDIRECT("D"&1+(ROW(D3)-1)*10+COLUMN(A3)-1) -> 103.303 | M4: =INDIRECT("D"&1+(ROW(E3)-1)*10+COLUMN(B3)-1) -> 103.348 | N4: =INDIRECT("D"&1+(ROW(F3)-1)*10+COLUMN(C3)-1) -> 103.276 | O4: =INDIRECT("D"&1+(ROW(G3)-1)*10+COLUMN(D3)-1) -> 103.342 | P4: =INDIRECT("D"&1+(ROW(H3)-1)*10+COLUMN(E3)-1) -> 103.302 | Q4: =INDIRECT("D"&1+(ROW(I3)-1)*10+COLUMN(F3)-1) -> 103.282 | R4: =INDIRECT("D"&1+(ROW(J3)-1)*10+COLUMN(G3)-1) -> 103.245 | S4: =INDIRECT("D"&1+(ROW(K3)-1)*10+COLUMN(H3)-1) -> 103.588 | ... U4: =INDIRECT("D"&1+(ROW(M3)-1)*10+COLUMN(J3)-1) -> 103.242 | W4: =AVERAGE(L4:U4) -> 103.3474 | Y4: =Total!E4 -> 102.802 | AB4: =(L4-$Y4)/$Y4 -> 0.004873446 | AC4: =(M4-$Y4)/$Y4 -> 0.0053111807 | AD4: =(N4-$Y4)/$Y4 -> 0.0046108052 | AE4: =(O4-$Y4)/$Y4 -> 0.0052528161 | AF4: =(P4-$Y4)/$Y4 -> 0.0048637186 | AG4: =(Q4-$Y4)/$Y4 -> 0.0046691699 | AH4: =(R4-$Y4)/$Y4 -> 0.0043092547 | AI4: =(S4-$Y4)/$Y4 -> 0.0076457656 | ... AK4: =(U4-$Y4)/$Y4 -> 0.0042800724 | AM4: =SUM(AB4:AK4) -> 0.053053443
A5: Montage | B5: 25 | C5: 1 | D5: 28.504 | E5: 5.28 | F5: 276 | H5: CyberShake | I5: 30 | J5: 1 | L5: =INDIRECT("D"&1+(ROW(D4)-1)*10+COLUMN(A4)-1) -> 156.127 | M5: =INDIRECT("D"&1+(ROW(E4)-1)*10+COLUMN(B4)-1) -> 156.127 | N5: =INDIRECT("D"&1+(ROW(F4)-1)*10+COLUMN(C4)-1) -> 156.127 | O5: =INDIRECT("D"&1+(ROW(G4)-1)*10+COLUMN(D4)-1) -> 156.127 | P5: =INDIRECT("D"&1+(ROW(H4)-1)*10+COLUMN(E4)-1) -> 156.127 | Q5: =INDIRECT("D"&1+(ROW(I4)-1)*10+COLUMN(F4)-1) -> 156.127 | R5: =INDIRECT("D"&1+(ROW(J4)-1)*10+COLUMN(G4)-1) -> 156.127 | S5: =INDIRECT("D"&1+(ROW(K4)-1)*10+COLUMN(H4)-1) -> 156.127 | ... U5: =INDIRECT("D"&1+(ROW(M4)-1)*10+COLUMN(J4)-1) -> 156.127 | W5: =AVERAGE(L5:U5) -> 156.127 | Y5: =Total!E5 -> 156.127 | AB5: =(L5-$Y5)/$Y5 -> 0 | AC5: =(M5-$Y5)/$Y5 -> 0 | AD5: =(N5-$Y5)/$Y5 -> 0 | AE5: =(O5-$Y5)/$Y5 -> 0 | AF5: =(P5-$Y5)/$Y5 -> 0 | AG5: =(Q5-$Y5)/$Y5 -> 0 | AH5: =(R5-$Y5)/$Y5 -> 0 | AI5: =(S5-$Y5)/$Y5 -> 0 | ... AK5: =(U5-$Y5)/$Y5 -> 0 | AM5: =SUM(AB5:AK5) -> 0
A6: Montage | B6: 25 | C6: 1 | D6: 28.504 | E6: 5.294 | F6: 303 | H6: CyberShake | I6: 50 | J6: 1 | L6: =INDIRECT("D"&1+(ROW(D5)-1)*10+COLUMN(A5)-1) -> 179.938 | M6: =INDIRECT("D"&1+(ROW(E5)-1)*10+COLUMN(B5)-1) -> 179.953 | N6: =INDIRECT("D"&1+(ROW(F5)-1)*10+COLUMN(C5)-1) -> 180.053 | O6: =INDIRECT("D"&1+(ROW(G5)-1)*10+COLUMN(D5)-1) -> 179.938 | P6: =INDIRECT("D"&1+(ROW(H5)-1)*10+COLUMN(E5)-1) -> 181.408 | Q6: =INDIRECT("D"&1+(ROW(I5)-1)*10+COLUMN(F5)-1) -> 180.871 | R6: =INDIRECT("D"&1+(ROW(J5)-1)*10+COLUMN(G5)-1) -> 179.938 | S6: =INDIRECT("D"&1+(ROW(K5)-1)*10+COLUMN(H5)-1) -> 182.077 | ... U6: =INDIRECT("D"&1+(ROW(M5)-1)*10+COLUMN(J5)-1) -> 179.938 | W6: =AVERAGE(L6:U6) -> 180.4052 | Y6: =Total!E6 -> 179.673 | AB6: =(L6-$Y6)/$Y6 -> 0.0014749016 | AC6: =(M6-$Y6)/$Y6 -> 0.0015583866 | AD6: =(N6-$Y6)/$Y6 -> 0.0021149533 | AE6: =(O6-$Y6)/$Y6 -> 0.0014749016 | AF6: =(P6-$Y6)/$Y6 -> 0.0096564314 | AG6: =(Q6-$Y6)/$Y6 -> 0.0066676685 | AH6: =(R6-$Y6)/$Y6 -> 0.0014749016 | AI6: =(S6-$Y6)/$Y6 -> 0.013379862 | ... AK6: =(U6-$Y6)/$Y6 -> 0.0014749016 | AM6: =SUM(AB6:AK6) -> 0.04075181
